<?xml version="1.0" encoding="utf-8"?>
<!-- This URDF was automatically created by SolidWorks to URDF Exporter! Originally created by Stephen Brawner (brawner@gmail.com) 
     Commit Version: 1.6.0-4-g7f85cfe  Build Version: 1.6.7995.38578
     For more information, please see http://wiki.ros.org/sw_urdf_exporter -->
<robot
        name="GRMini1T1">
    <link
            name="base_link">
        <inertial>
            <origin
                    xyz="-0.00058375 -1.4517E-06 -0.063447"
                    rpy="0 0 0"/>
            <mass
                    value="3.1357"/>
            <inertia
                    ixx="0.0095393"
                    ixy="-2.156E-05"
                    ixz="-8E-08"
                    iyy="0.013549"
                    iyz="-3.997E-05"
                    izz="0.010053"/>
        </inertial>
        <visual>
            <origin
                    xyz="0 0 0"
                    rpy="0 0 0"/>
            <geometry>
                <mesh
                        filename="../meshes/base_link.STL"/>
            </geometry>
            <material
                    name="">
                <color
                        rgba="0.75294 0.75294 0.75294 1"/>
            </material>
        </visual>
        <!--        <collision>-->
        <!--            <origin-->
        <!--                    xyz="0 0 0"-->
        <!--                    rpy="0 0 0"/>-->
        <!--            <geometry>-->
        <!--                <mesh-->
        <!--                        filename="../meshes/base_link.STL"/>-->
        <!--            </geometry>-->
        <!--        </collision>-->
    </link>
    <link
            name="waist_yaw_link">
        <inertial>
            <origin
                    xyz="-0.0022054 0.00010046 0.025305"
                    rpy="0 0 0"/>
            <mass
                    value="0.92522"/>
            <inertia
                    ixx="0.001509"
                    ixy="-2.322E-05"
                    ixz="9.2E-07"
                    iyy="0.0012082"
                    iyz="2.75E-06"
                    izz="0.001278"/>
        </inertial>
        <visual>
            <origin
                    xyz="0 0 0"
                    rpy="0 0 0"/>
            <geometry>
                <mesh
                        filename="../meshes/waist_yaw_link.STL"/>
            </geometry>
            <material
                    name="">
                <color
                        rgba="0.75294 0.75294 0.75294 1"/>
            </material>
        </visual>
        <!--        <collision>-->
        <!--            <origin-->
        <!--                    xyz="0 0 0"-->
        <!--                    rpy="0 0 0"/>-->
        <!--            <geometry>-->
        <!--                <mesh-->
        <!--                        filename="../meshes/waist_yaw_link.STL"/>-->
        <!--            </geometry>-->
        <!--        </collision>-->
    </link>
    <joint
            name="waist_yaw_joint"
            type="revolute">
        <origin
                xyz="0 0 0.015"
                rpy="0 0 0"/>
        <parent
                link="base_link"/>
        <child
                link="waist_yaw_link"/>
        <axis
                xyz="0 0 1"/>
        <limit
                lower="-2.618"
                upper="2.618"
                effort="59.8"
                velocity="12.252"/>
    </joint>
    <link
            name="torso_link">
        <inertial>
            <origin
                    xyz="0.0041208 0.0024646 -0.051503"
                    rpy="0 0 0"/>
            <mass
                    value="7.84667176"/>
            <inertia
                    ixx="0.03712429"
                    ixy="-0.00061932"
                    ixz="0.00101372"
                    iyy="0.08563448"
                    iyz="-0.00036419"
                    izz="0.07498642"/>
        </inertial>
        <visual>
            <origin
                    xyz="0 0 0"
                    rpy="0 0 0"/>
            <geometry>
                <mesh
                        filename="../meshes/torso_link.STL"/>
            </geometry>
            <material
                    name="">
                <color
                        rgba="0.75294 0.75294 0.75294 1"/>
            </material>
        </visual>
        <collision>
            <origin
                    rpy="0 0 0"
                    xyz="0 0 -0.05"/>
            <geometry>
                <cylinder
                        length="0.2"
                        radius="0.1"/>
            </geometry>
        </collision>
        <!--        <collision>-->
        <!--            <origin-->
        <!--                    xyz="0 0 0"-->
        <!--                    rpy="0 0 0"/>-->
        <!--            <geometry>-->
        <!--                <mesh-->
        <!--                        filename="../meshes/torso_link.STL"/>-->
        <!--            </geometry>-->
        <!--        </collision>-->
    </link>
    <joint
            name="torso_joint"
            type="fixed">
        <origin
                xyz="0 0 0.2604"
                rpy="0 0 0"/>
        <parent
                link="waist_yaw_link"/>
        <child
                link="torso_link"/>
        <axis
                xyz="0 0 0"/>
    </joint>
    <link
            name="imu_link">
        <inertial>
            <origin
                    xyz="5.3169E-08 -0.0070317 0.0021507"
                    rpy="0 0 0"/>
            <mass
                    value="0.0417145"/>
            <inertia
                    ixx="2.651E-05"
                    ixy="0"
                    ixz="-2.8E-07"
                    iyy="2.209E-05"
                    iyz="0"
                    izz="1.049E-05"/>
        </inertial>
        <visual>
            <origin
                    xyz="0 0 0"
                    rpy="0 0 0"/>
            <geometry>
                <mesh
                        filename="../meshes/imu_link.STL"/>
            </geometry>
            <material
                    name="">
                <color
                        rgba="0.75294 0.75294 0.75294 1"/>
            </material>
        </visual>
        <collision>
            <origin
                    rpy="0 0 0"
                    xyz="0 0 0"/>
            <geometry>
                <cylinder
                        length="0.02"
                        radius="0.02"/>
            </geometry>
        </collision>
        <!--        <collision>-->
        <!--            <origin-->
        <!--                    xyz="0 0 0"-->
        <!--                    rpy="0 0 0"/>-->
        <!--            <geometry>-->
        <!--                <mesh-->
        <!--                        filename="../meshes/imu_link.STL"/>-->
        <!--            </geometry>-->
        <!--        </collision>-->
    </link>
    <joint
            name="imu_joint"
            type="fixed">
        <origin
                xyz="0.07875 0 -0.2068"
                rpy="0 0 0"/>
        <parent
                link="torso_link"/>
        <child
                link="imu_link"/>
        <axis
                xyz="0 0 0"/>
    </joint>
    <link
            name="camera_link">
        <inertial>
            <origin
                    xyz="0.0099227 0.0014966 8.1692E-05"
                    rpy="0 0 0"/>
            <mass
                    value="0.0985531"/>
            <inertia
                    ixx="5.333E-05"
                    ixy="1.41E-06"
                    ixz="2.37E-05"
                    iyy="6.584E-05"
                    iyz="6.7E-07"
                    izz="2.601E-05"/>
        </inertial>
        <visual>
            <origin
                    xyz="0 0 0"
                    rpy="0 0 0"/>
            <geometry>
                <mesh
                        filename="../meshes/camera_link.STL"/>
            </geometry>
            <material
                    name="">
                <color
                        rgba="0.75294 0.75294 0.75294 1"/>
            </material>
        </visual>
        <collision>
            <origin
                    rpy="0 0 0"
                    xyz="0 0 0"/>
            <geometry>
                <cylinder
                        length="0.02"
                        radius="0.02"/>
            </geometry>
        </collision>
        <!--        <collision>-->
        <!--            <origin-->
        <!--                    xyz="0 0 0"-->
        <!--                    rpy="0 0 0"/>-->
        <!--            <geometry>-->
        <!--                <mesh-->
        <!--                        filename="../meshes/camera_link.STL"/>-->
        <!--            </geometry>-->
        <!--        </collision>-->
    </link>
    <joint
            name="camera_joint"
            type="fixed">
        <origin
                xyz="0.071504 0 0.1798"
                rpy="0 0.5236 0"/>
        <parent
                link="torso_link"/>
        <child
                link="camera_link"/>
        <axis
                xyz="0 0 0"/>
    </joint>
    <link
            name="left_upper_arm_pitch_link">
        <inertial>
            <origin
                    xyz="0.0004349 0.07265 6.9487E-06"
                    rpy="0 0 0"/>
            <mass
                    value="0.88423"/>
            <inertia
                    ixx="0.0018303"
                    ixy="-1E-07"
                    ixz="1.154E-05"
                    iyy="0.0018418"
                    iyz="-6.2E-07"
                    izz="0.00062558"/>
        </inertial>
        <visual>
            <origin
                    xyz="0 0 0"
                    rpy="0 0 0"/>
            <geometry>
                <mesh
                        filename="../meshes/left_upper_arm_pitch_link.STL"/>
            </geometry>
            <material
                    name="">
                <color
                        rgba="0.75294 0.75294 0.75294 1"/>
            </material>
        </visual>
        <!--        <collision>-->
        <!--            <origin-->
        <!--                    xyz="0 0 0"-->
        <!--                    rpy="0 0 0"/>-->
        <!--            <geometry>-->
        <!--                <mesh-->
        <!--                        filename="../meshes/left_upper_arm_pitch_link.STL"/>-->
        <!--            </geometry>-->
        <!--        </collision>-->
    </link>
    <joint
            name="left_shoulder_pitch_joint"
            type="revolute">
        <origin
                xyz="0 0.09365 0"
                rpy="0 0 0"/>
        <parent
                link="torso_link"/>
        <child
                link="left_upper_arm_pitch_link"/>
        <axis
                xyz="0 1 0"/>
        <limit
                lower="-2.967"
                upper="2.967"
                effort="59.8"
                velocity="12.252"/>
    </joint>
    <link
            name="left_upper_arm_roll_link">
        <inertial>
            <origin
                    xyz="0.0071999 0.00095188 -0.031174"
                    rpy="0 0 0"/>
            <mass
                    value="0.71516"/>
            <inertia
                    ixx="0.001714"
                    ixy="-0.00014319"
                    ixz="5E-07"
                    iyy="0.00041667"
                    iyz="-4.08E-06"
                    izz="0.0018111"/>
        </inertial>
        <visual>
            <origin
                    xyz="0 0 0"
                    rpy="0 0 0"/>
            <geometry>
                <mesh
                        filename="../meshes/left_upper_arm_roll_link.STL"/>
            </geometry>
            <material
                    name="">
                <color
                        rgba="0.75294 0.75294 0.75294 1"/>
            </material>
        </visual>
        <collision>
            <origin
                    rpy="0 0 0"
                    xyz="0 0 -0.04"/>
            <geometry>
                <cylinder
                        length="0.15"
                        radius="0.04"/>
            </geometry>
        </collision>
        <!--        <collision>-->
        <!--            <origin-->
        <!--                    xyz="0 0 0"-->
        <!--                    rpy="0 0 0"/>-->
        <!--            <geometry>-->
        <!--                <mesh-->
        <!--                        filename="../meshes/left_upper_arm_roll_link.STL"/>-->
        <!--            </geometry>-->
        <!--        </collision>-->
    </link>
    <joint
            name="left_shoulder_roll_joint"
            type="revolute">
        <origin
                xyz="0 0.082 0"
                rpy="0 0 0"/>
        <parent
                link="left_upper_arm_pitch_link"/>
        <child
                link="left_upper_arm_roll_link"/>
        <axis
                xyz="1 0 0"/>
        <limit
                lower="-0.175"
                upper="2.792"
                effort="29.3"
                velocity="13.927"/>
    </joint>
    <link
            name="left_upper_arm_yaw_link">
        <inertial>
            <origin
                    xyz="-0.00024227 -6.5025E-05 -0.055988"
                    rpy="0 0 0"/>
            <mass
                    value="0.91461"/>
            <inertia
                    ixx="0.0030946"
                    ixy="4.01E-06"
                    ixz="2.64E-06"
                    iyy="0.00073776"
                    iyz="-1.877E-05"
                    izz="0.0030869"/>
        </inertial>
        <visual>
            <origin
                    xyz="0 0 0"
                    rpy="0 0 0"/>
            <geometry>
                <mesh
                        filename="../meshes/left_upper_arm_yaw_link.STL"/>
            </geometry>
            <material
                    name="">
                <color
                        rgba="0.75294 0.75294 0.75294 1"/>
            </material>
        </visual>
        <!--        <collision>-->
        <!--            <origin-->
        <!--                    xyz="0 0 0"-->
        <!--                    rpy="0 0 0"/>-->
        <!--            <geometry>-->
        <!--                <mesh-->
        <!--                        filename="../meshes/left_upper_arm_yaw_link.STL"/>-->
        <!--            </geometry>-->
        <!--        </collision>-->
    </link>
    <joint
            name="left_shoulder_yaw_joint"
            type="revolute">
        <origin
                xyz="0 0 -0.105"
                rpy="0 0 0"/>
        <parent
                link="left_upper_arm_roll_link"/>
        <child
                link="left_upper_arm_yaw_link"/>
        <axis
                xyz="0 0 1"/>
        <limit
                lower="-1.833"
                upper="1.833"
                effort="29.3"
                velocity="13.927"/>
    </joint>
    <link
            name="left_lower_arm_pitch_link">
        <inertial>
            <origin
                    xyz="0.031249 0.0068387 -0.00086783"
                    rpy="0 0 0"/>
            <mass
                    value="0.71626"/>
            <inertia
                    ixx="0.00041877"
                    ixy="-5E-06"
                    ixz="0.00014466"
                    iyy="0.0018113"
                    iyz="-8.1E-07"
                    izz="0.0017159"/>
        </inertial>
        <visual>
            <origin
                    xyz="0 0 0"
                    rpy="0 0 0"/>
            <geometry>
                <mesh
                        filename="../meshes/left_lower_arm_pitch_link.STL"/>
            </geometry>
            <material
                    name="">
                <color
                        rgba="0.75294 0.75294 0.75294 1"/>
            </material>
        </visual>
        <collision>
            <origin
                    rpy="0 1.5708 0"
                    xyz="0.04 0 0"/>
            <geometry>
                <cylinder
                        length="0.15"
                        radius="0.04"/>
            </geometry>
        </collision>
        <!--        <collision>-->
        <!--            <origin-->
        <!--                    xyz="0 0 0"-->
        <!--                    rpy="0 0 0"/>-->
        <!--            <geometry>-->
        <!--                <mesh-->
        <!--                        filename="../meshes/left_lower_arm_pitch_link.STL"/>-->
        <!--            </geometry>-->
        <!--        </collision>-->
    </link>
    <joint
            name="left_elbow_pitch_joint"
            type="revolute">
        <origin
                xyz="0 0 -0.105"
                rpy="0 0 0"/>
        <parent
                link="left_upper_arm_yaw_link"/>
        <child
                link="left_lower_arm_pitch_link"/>
        <axis
                xyz="0 1 0"/>
        <limit
                lower="-0.314"
                upper="1.658"
                effort="29.3"
                velocity="13.927"/>
    </joint>
    <link
            name="left_hand_yaw_link">
        <inertial>
            <origin
                    xyz="0.010273 0.00011318 -0.00011362"
                    rpy="0 0 0"/>
            <mass
                    value="0.47586"/>
            <inertia
                    ixx="0.00036505"
                    ixy="-2.04E-06"
                    ixz="1.4E-07"
                    iyy="0.00051905"
                    iyz="-1.34E-06"
                    izz="0.0005199"/>
        </inertial>
        <visual>
            <origin
                    xyz="0 0 0"
                    rpy="0 0 0"/>
            <geometry>
                <mesh
                        filename="../meshes/left_hand_yaw_link.STL"/>
            </geometry>
            <material
                    name="">
                <color
                        rgba="0.75294 0.75294 0.75294 1"/>
            </material>
        </visual>
        <!--        <collision>-->
        <!--            <origin-->
        <!--                    xyz="0 0 0"-->
        <!--                    rpy="0 0 0"/>-->
        <!--            <geometry>-->
        <!--                <mesh-->
        <!--                        filename="../meshes/left_hand_yaw_link.STL"/>-->
        <!--            </geometry>-->
        <!--        </collision>-->
    </link>
    <joint
            name="left_wrist_yaw_joint"
            type="revolute">
        <origin
                xyz="0.105 0 0"
                rpy="0 0 0"/>
        <parent
                link="left_lower_arm_pitch_link"/>
        <child
                link="left_hand_yaw_link"/>
        <axis
                xyz="1 0 0"/>
        <limit
                lower="-1.833"
                upper="1.833"
                effort="29.3"
                velocity="13.927"/>
    </joint>
    <link
            name="left_end_effector_link">
        <inertial>
            <origin
                    xyz="0.022489 -2.5699E-12 3.3307E-16"
                    rpy="0 0 0"/>
            <mass
                    value="0.10135"/>
            <inertia
                    ixx="4.693E-05"
                    ixy="0"
                    ixz="0"
                    iyy="3.946E-05"
                    iyz="0"
                    izz="3.946E-05"/>
        </inertial>
        <visual>
            <origin
                    xyz="0 0 0"
                    rpy="0 0 0"/>
            <geometry>
                <mesh
                        filename="../meshes/left_end_effector_link.STL"/>
            </geometry>
            <material
                    name="">
                <color
                        rgba="0.75294 0.75294 0.75294 1"/>
            </material>
        </visual>
        <collision>
            <origin
                    rpy="0 0 0"
                    xyz="0.02 0 0"/>
            <geometry>
                <sphere
                        radius="0.03"/>
            </geometry>
        </collision>
        <!--        <collision>-->
        <!--            <origin-->
        <!--                    xyz="0 0 0"-->
        <!--                    rpy="0 0 0"/>-->
        <!--            <geometry>-->
        <!--                <mesh-->
        <!--                        filename="../meshes/left_end_effector_link.STL"/>-->
        <!--            </geometry>-->
        <!--        </collision>-->
    </link>
    <joint
            name="left_end_effector_joint"
            type="fixed">
        <origin
                xyz="0.08 0 0"
                rpy="0 0 0"/>
        <parent
                link="left_hand_yaw_link"/>
        <child
                link="left_end_effector_link"/>
        <axis
                xyz="0 0 0"/>
    </joint>
    <link
            name="right_upper_arm_pitch_link">
        <inertial>
            <origin
                    xyz="0.00043469 -0.072654 -9.14E-06"
                    rpy="0 0 0"/>
            <mass
                    value="0.88423"/>
            <inertia
                    ixx="0.00183029"
                    ixy="-3.7E-07"
                    ixz="-1.164E-05"
                    iyy="0.00184169"
                    iyz="1.11E-06"
                    izz="0.00062587"/>
        </inertial>
        <visual>
            <origin
                    xyz="0 0 0"
                    rpy="0 0 0"/>
            <geometry>
                <mesh
                        filename="../meshes/right_upper_arm_pitch_link.STL"/>
            </geometry>
            <material
                    name="">
                <color
                        rgba="0.75294 0.75294 0.75294 1"/>
            </material>
        </visual>
        <!--        <collision>-->
        <!--            <origin-->
        <!--                    xyz="0 0 0"-->
        <!--                    rpy="0 0 0"/>-->
        <!--            <geometry>-->
        <!--                <mesh-->
        <!--                        filename="../meshes/right_upper_arm_pitch_link.STL"/>-->
        <!--            </geometry>-->
        <!--        </collision>-->
    </link>
    <joint
            name="right_shoulder_pitch_joint"
            type="revolute">
        <origin
                xyz="0 -0.09365 0"
                rpy="0 0 0"/>
        <parent
                link="torso_link"/>
        <child
                link="right_upper_arm_pitch_link"/>
        <axis
                xyz="0 1 0"/>
        <limit
                lower="-2.967"
                upper="2.967"
                effort="59.8"
                velocity="12.252"/>
    </joint>
    <link
            name="right_upper_arm_roll_link">
        <inertial>
            <origin
                    xyz="0.0070543 -0.0010248 -0.031296"
                    rpy="0 0 0"/>
            <mass
                    value="0.71516"/>
            <inertia
                    ixx="0.0017137"
                    ixy="-0.00014381"
                    ixz="-6.9E-07"
                    iyy="0.00041734"
                    iyz="3.34E-06"
                    izz="0.00181137"/>
        </inertial>
        <visual>
            <origin
                    xyz="0 0 0"
                    rpy="0 0 0"/>
            <geometry>
                <mesh
                        filename="../meshes/right_upper_arm_roll_link.STL"/>
            </geometry>
            <material
                    name="">
                <color
                        rgba="0.75294 0.75294 0.75294 1"/>
            </material>
        </visual>
        <collision>
            <origin
                    rpy="0 0 0"
                    xyz="0 0 -0.04"/>
            <geometry>
                <cylinder
                        length="0.15"
                        radius="0.04"/>
            </geometry>
        </collision>
        <!--        <collision>-->
        <!--            <origin-->
        <!--                    xyz="0 0 0"-->
        <!--                    rpy="0 0 0"/>-->
        <!--            <geometry>-->
        <!--                <mesh-->
        <!--                        filename="../meshes/right_upper_arm_roll_link.STL"/>-->
        <!--            </geometry>-->
        <!--        </collision>-->
    </link>
    <joint
            name="right_shoulder_roll_joint"
            type="revolute">
        <origin
                xyz="0 -0.082 0"
                rpy="0 0 0"/>
        <parent
                link="right_upper_arm_pitch_link"/>
        <child
                link="right_upper_arm_roll_link"/>
        <axis
                xyz="1 0 0"/>
        <limit
                lower="-2.792"
                upper="0.175"
                effort="29.3"
                velocity="13.927"/>
    </joint>
    <link
            name="right_upper_arm_yaw_link">
        <inertial>
            <origin
                    xyz="-0.00021358 0.0014607 -0.06011"
                    rpy="0 0 0"/>
            <mass
                    value="0.91461"/>
            <inertia
                    ixx="0.0030941"
                    ixy="3.11E-06"
                    ixz="-2.19E-06"
                    iyy="0.00073751"
                    iyz="1.915E-05"
                    izz="0.0030871"/>
        </inertial>
        <visual>
            <origin
                    xyz="0 0 0"
                    rpy="0 0 0"/>
            <geometry>
                <mesh
                        filename="../meshes/right_upper_arm_yaw_link.STL"/>
            </geometry>
            <material
                    name="">
                <color
                        rgba="0.75294 0.75294 0.75294 1"/>
            </material>
        </visual>
        <!--        <collision>-->
        <!--            <origin-->
        <!--                    xyz="0 0 0"-->
        <!--                    rpy="0 0 0"/>-->
        <!--            <geometry>-->
        <!--                <mesh-->
        <!--                        filename="../meshes/right_upper_arm_yaw_link.STL"/>-->
        <!--            </geometry>-->
        <!--        </collision>-->
    </link>
    <joint
            name="right_shoulder_yaw_joint"
            type="revolute">
        <origin
                xyz="0 0 -0.105"
                rpy="0 0 0"/>
        <parent
                link="right_upper_arm_roll_link"/>
        <child
                link="right_upper_arm_yaw_link"/>
        <axis
                xyz="0 0 1"/>
        <limit
                lower="-1.833"
                upper="1.833"
                effort="29.3"
                velocity="13.927"/>
    </joint>
    <link
            name="right_lower_arm_pitch_link">
        <inertial>
            <origin
                    xyz="0.031259 -0.0068423 -0.00084165"
                    rpy="0 0 0"/>
            <mass
                    value="0.71626"/>
            <inertia
                    ixx="0.00041415"
                    ixy="-4.12E-06"
                    ixz="-0.00014499"
                    iyy="0.00181012"
                    iyz="2.8E-07"
                    izz="0.00171129"/>
        </inertial>
        <visual>
            <origin
                    xyz="0 0 0"
                    rpy="0 0 0"/>
            <geometry>
                <mesh
                        filename="../meshes/right_lower_arm_pitch_link.STL"/>
            </geometry>
            <material
                    name="">
                <color
                        rgba="0.75294 0.75294 0.75294 1"/>
            </material>
        </visual>
        <collision>
            <origin
                    rpy="0 1.5708 0"
                    xyz="0.04 0 0"/>
            <geometry>
                <cylinder
                        length="0.15"
                        radius="0.04"/>
            </geometry>
        </collision>
        <!--        <collision>-->
        <!--            <origin-->
        <!--                    xyz="0 0 0"-->
        <!--                    rpy="0 0 0"/>-->
        <!--            <geometry>-->
        <!--                <mesh-->
        <!--                        filename="../meshes/right_lower_arm_pitch_link.STL"/>-->
        <!--            </geometry>-->
        <!--        </collision>-->
    </link>
    <joint
            name="right_elbow_pitch_joint"
            type="revolute">
        <origin
                xyz="0 0 -0.105"
                rpy="0 0 0"/>
        <parent
                link="right_upper_arm_yaw_link"/>
        <child
                link="right_lower_arm_pitch_link"/>
        <axis
                xyz="0 1 0"/>
        <limit
                lower="-0.314"
                upper="1.658"
                effort="29.3"
                velocity="13.927"/>
    </joint>
    <link
            name="right_hand_yaw_link">
        <inertial>
            <origin
                    xyz="0.010273 0.00011164 -0.00011513"
                    rpy="0 0 0"/>
            <mass
                    value="0.47586"/>
            <inertia
                    ixx="0.00036505"
                    ixy="-2.04E-06"
                    ixz="1.2E-07"
                    iyy="0.00051909"
                    iyz="-1.35E-06"
                    izz="0.00051986"/>
        </inertial>
        <visual>
            <origin
                    xyz="0 0 0"
                    rpy="0 0 0"/>
            <geometry>
                <mesh
                        filename="../meshes/right_hand_yaw_link.STL"/>
            </geometry>
            <material
                    name="">
                <color
                        rgba="0.75294 0.75294 0.75294 1"/>
            </material>
        </visual>
        <!--        <collision>-->
        <!--            <origin-->
        <!--                    xyz="0 0 0"-->
        <!--                    rpy="0 0 0"/>-->
        <!--            <geometry>-->
        <!--                <mesh-->
        <!--                        filename="../meshes/right_hand_yaw_link.STL"/>-->
        <!--            </geometry>-->
        <!--        </collision>-->
    </link>
    <joint
            name="right_wrist_yaw_joint"
            type="revolute">
        <origin
                xyz="0.105 0 0"
                rpy="0 0 0"/>
        <parent
                link="right_lower_arm_pitch_link"/>
        <child
                link="right_hand_yaw_link"/>
        <axis
                xyz="1 0 0"/>
        <limit
                lower="-1.833"
                upper="1.833"
                effort="29.3"
                velocity="13.927"/>
    </joint>
    <link
            name="right_end_effector_link">
        <inertial>
            <origin
                    xyz="0.02257 -7.952E-14 -6.3018E-13"
                    rpy="0 0 0"/>
            <mass
                    value="0.10135"/>
            <inertia
                    ixx="4.686E-05"
                    ixy="0"
                    ixz="0"
                    iyy="3.928E-05"
                    iyz="0"
                    izz="3.928E-05"/>
        </inertial>
        <visual>
            <origin
                    xyz="0 0 0"
                    rpy="0 0 0"/>
            <geometry>
                <mesh
                        filename="../meshes/right_end_effector_link.STL"/>
            </geometry>
            <material
                    name="">
                <color
                        rgba="0.75294 0.75294 0.75294 1"/>
            </material>
        </visual>
        <collision>
            <origin
                    rpy="0 0 0"
                    xyz="0.02 0 0"/>
            <geometry>
                <sphere
                        radius="0.03"/>
            </geometry>
        </collision>
        <!--        <collision>-->
        <!--            <origin-->
        <!--                    xyz="0 0 0"-->
        <!--                    rpy="0 0 0"/>-->
        <!--            <geometry>-->
        <!--                <mesh-->
        <!--                        filename="../meshes/right_end_effector_link.STL"/>-->
        <!--            </geometry>-->
        <!--        </collision>-->
    </link>
    <joint
            name="right_end_effector_joint"
            type="fixed">
        <origin
                xyz="0.08 0 0"
                rpy="0 0 0"/>
        <parent
                link="right_hand_yaw_link"/>
        <child
                link="right_end_effector_link"/>
        <axis
                xyz="0 0 0"/>
    </joint>
    <link
            name="left_thigh_pitch_link">
        <inertial>
            <origin
                    xyz="0.0019432 0.048293 0.00082926"
                    rpy="0 0 0"/>
            <mass
                    value="1.3008"/>
            <inertia
                    ixx="0.0023186"
                    ixy="4.62E-06"
                    ixz="0.00024593"
                    iyy="0.0020661"
                    iyz="-0.00010476"
                    izz="0.0013865"/>
        </inertial>
        <visual>
            <origin
                    xyz="0 0 0"
                    rpy="0 0 0"/>
            <geometry>
                <mesh
                        filename="../meshes/left_thigh_pitch_link.STL"/>
            </geometry>
            <material
                    name="">
                <color
                        rgba="0.75294 0.75294 0.75294 1"/>
            </material>
        </visual>
        <!--        <collision>-->
        <!--            <origin-->
        <!--                    xyz="0 0 0"-->
        <!--                    rpy="0 0 0"/>-->
        <!--            <geometry>-->
        <!--                <mesh-->
        <!--                        filename="../meshes/left_thigh_pitch_link.STL"/>-->
        <!--            </geometry>-->
        <!--        </collision>-->
    </link>
    <joint
            name="left_hip_pitch_joint"
            type="revolute">
        <origin
                xyz="0 0.048521 -0.076847"
                rpy="-0.2618 0 0"/>
        <parent
                link="base_link"/>
        <child
                link="left_thigh_pitch_link"/>
        <axis
                xyz="0 1 0"/>
        <limit
                lower="-2.618"
                upper="2.618"
                effort="96.7"
                velocity="10.891"/>
    </joint>
    <link
            name="left_thigh_roll_link">
        <inertial>
            <origin
                    xyz="-0.0037546 -2.1988E-05 -0.022317"
                    rpy="0 0 0"/>
            <mass
                    value="1.359"/>
            <inertia
                    ixx="0.0012551"
                    ixy="-7.925E-05"
                    ixz="1.4E-07"
                    iyy="0.0030174"
                    iyz="-2.62E-06"
                    izz="0.0028871"/>
        </inertial>
        <visual>
            <origin
                    xyz="0 0 0"
                    rpy="0 0 0"/>
            <geometry>
                <mesh
                        filename="../meshes/left_thigh_roll_link.STL"/>
            </geometry>
            <material
                    name="">
                <color
                        rgba="0.75294 0.75294 0.75294 1"/>
            </material>
        </visual>
        <!--        <collision>-->
        <!--            <origin-->
        <!--                    xyz="0 0 0"-->
        <!--                    rpy="0 0 0"/>-->
        <!--            <geometry>-->
        <!--                <mesh-->
        <!--                        filename="../meshes/left_thigh_roll_link.STL"/>-->
        <!--            </geometry>-->
        <!--        </collision>-->
    </link>
    <joint
            name="left_hip_roll_joint"
            type="revolute">
        <origin
                xyz="0 0.074 0"
                rpy="0.2618 0 0"/>
        <parent
                link="left_thigh_pitch_link"/>
        <child
                link="left_thigh_roll_link"/>
        <axis
                xyz="1 0 0"/>
        <limit
                lower="-0.262"
                upper="1.571"
                effort="59.8"
                velocity="12.252"/>
    </joint>
    <link
            name="left_thigh_yaw_link">
        <inertial>
            <origin
                    xyz="0.0043807 -0.0044838 -0.09162"
                    rpy="0 0 0"/>
            <mass
                    value="3.4519"/>
            <inertia
                    ixx="0.015956"
                    ixy="-0.00056889"
                    ixz="-7.21E-05"
                    iyy="0.0054953"
                    iyz="0.00067596"
                    izz="0.016255"/>
        </inertial>
        <visual>
            <origin
                    xyz="0 0 0"
                    rpy="0 0 0"/>
            <geometry>
                <mesh
                        filename="../meshes/left_thigh_yaw_link.STL"/>
            </geometry>
            <material
                    name="">
                <color
                        rgba="0.75294 0.75294 0.75294 1"/>
            </material>
        </visual>
        <collision>
            <origin
                    rpy="0 0 0"
                    xyz="0 0 0"/>
            <geometry>
                <cylinder
                        length="0.2"
                        radius="0.04"/>
            </geometry>
        </collision>
        <!--        <collision>-->
        <!--            <origin-->
        <!--                    xyz="0 0 0"-->
        <!--                    rpy="0 0 0"/>-->
        <!--            <geometry>-->
        <!--                <mesh-->
        <!--                        filename="../meshes/left_thigh_yaw_link.STL"/>-->
        <!--            </geometry>-->
        <!--        </collision>-->
    </link>
    <joint
            name="left_hip_yaw_joint"
            type="revolute">
        <origin
                xyz="0 0 -0.0875"
                rpy="0 0 0"/>
        <parent
                link="left_thigh_roll_link"/>
        <child
                link="left_thigh_yaw_link"/>
        <axis
                xyz="0 0 1"/>
        <limit
                lower="-1.571"
                upper="1.571"
                effort="59.8"
                velocity="12.252"/>
    </joint>
    <link
            name="left_shank_pitch_link">
        <inertial>
            <origin
                    xyz="0.0040504 0.0024929 -0.11735"
                    rpy="0 0 0"/>
            <mass
                    value="2.3355"/>
            <inertia
                    ixx="0.013759"
                    ixy="0.00020374"
                    ixz="3.74E-05"
                    iyy="0.0017735"
                    iyz="0.00027894"
                    izz="0.013757"/>
        </inertial>
        <visual>
            <origin
                    xyz="0 0 0"
                    rpy="0 0 0"/>
            <geometry>
                <mesh
                        filename="../meshes/left_shank_pitch_link.STL"/>
            </geometry>
            <material
                    name="">
                <color
                        rgba="0.75294 0.75294 0.75294 1"/>
            </material>
        </visual>
        <collision>
            <origin
                    rpy="0 0 0"
                    xyz="0 0 -0.1"/>
            <geometry>
                <cylinder
                        length="0.2"
                        radius="0.04"/>
            </geometry>
        </collision>
        <!--        <collision>-->
        <!--            <origin-->
        <!--                    xyz="0 0 0"-->
        <!--                    rpy="0 0 0"/>-->
        <!--            <geometry>-->
        <!--                <mesh-->
        <!--                        filename="../meshes/left_shank_pitch_link.STL"/>-->
        <!--            </geometry>-->
        <!--        </collision>-->
    </link>
    <joint
            name="left_knee_pitch_joint"
            type="revolute">
        <origin
                xyz="0 0 -0.2031"
                rpy="0 0 0"/>
        <parent
                link="left_thigh_yaw_link"/>
        <child
                link="left_shank_pitch_link"/>
        <axis
                xyz="0 1 0"/>
        <limit
                lower="-0.087"
                upper="2.356"
                effort="96.7"
                velocity="10.891"/>
    </joint>
    <link
            name="left_foot_roll_link">
        <inertial>
            <origin
                    xyz="6.6608E-09 0.001805 -5.856E-07"
                    rpy="0 0 0"/>
            <mass
                    value="0.11173"/>
            <inertia
                    ixx="2.445E-05"
                    ixy="0"
                    ixz="0"
                    iyy="2.876E-05"
                    iyz="0"
                    izz="1.162E-05"/>
        </inertial>
        <visual>
            <origin
                    xyz="0 0 0"
                    rpy="0 0 0"/>
            <geometry>
                <mesh
                        filename="../meshes/left_foot_roll_link.STL"/>
            </geometry>
            <material
                    name="">
                <color
                        rgba="0.75294 0.75294 0.75294 1"/>
            </material>
        </visual>
        <!--        <collision>-->
        <!--            <origin-->
        <!--                    xyz="0 0 0"-->
        <!--                    rpy="0 0 0"/>-->
        <!--            <geometry>-->
        <!--                <mesh-->
        <!--                        filename="../meshes/left_foot_roll_link.STL"/>-->
        <!--            </geometry>-->
        <!--        </collision>-->
    </link>
    <joint
            name="left_ankle_roll_joint"
            type="revolute">
        <origin
                xyz="0 0 -0.28"
                rpy="0 0 0"/>
        <parent
                link="left_shank_pitch_link"/>
        <child
                link="left_foot_roll_link"/>
        <axis
                xyz="1 0 0"/>
        <limit
                lower="-0.436"
                upper="0.436"
                effort="29.3"
                velocity="13.927"/>
    </joint>
    <link
            name="left_foot_pitch_link">
        <inertial>
            <origin
                    xyz="0.023432 -0.0001521 -0.030678"
                    rpy="0 0 0"/>
            <mass
                    value="0.39067"/>
            <inertia
                    ixx="0.00014047"
                    ixy="3.02E-06"
                    ixz="4.13E-06"
                    iyy="0.00089535"
                    iyz="4.9E-07"
                    izz="0.00083373"/>
        </inertial>
        <visual>
            <origin
                    xyz="0 0 0"
                    rpy="0 0 0"/>
            <geometry>
                <mesh
                        filename="../meshes/left_foot_pitch_link.STL"/>
            </geometry>
            <material
                    name="">
                <color
                        rgba="0.75294 0.75294 0.75294 1"/>
            </material>
        </visual>
        <collision>
            <origin
                    rpy="0 1.5708 0"
                    xyz="0.025 -0.015 -0.025"/>
            <geometry>
                <cylinder
                        length="0.15"
                        radius="0.015"/>
            </geometry>
        </collision>
        <collision>
            <origin
                    rpy="0 1.5708 0"
                    xyz="0.025 0.015 -0.025"/>
            <geometry>
                <cylinder
                        length="0.15"
                        radius="0.015"/>
            </geometry>
        </collision>
        <!--        <collision>-->
        <!--            <origin-->
        <!--                    xyz="0 0 0"-->
        <!--                    rpy="0 0 0"/>-->
        <!--            <geometry>-->
        <!--                <mesh-->
        <!--                        filename="../meshes/left_foot_pitch_link.STL"/>-->
        <!--            </geometry>-->
        <!--        </collision>-->
    </link>
    <joint
            name="left_ankle_pitch_joint"
            type="revolute">
        <origin
                xyz="0 0 0"
                rpy="0 0 0"/>
        <parent
                link="left_foot_roll_link"/>
        <child
                link="left_foot_pitch_link"/>
        <axis
                xyz="0 1 0"/>
        <limit
                lower="-0.96"
                upper="0.838"
                effort="29.3"
                velocity="13.927"/>
    </joint>
    <link
            name="right_thigh_pitch_link">
        <inertial>
            <origin
                    xyz="0.001947 -0.048292 0.00082948"
                    rpy="0 0 0"/>
            <mass
                    value="1.3008"/>
            <inertia
                    ixx="0.0023186"
                    ixy="4.64E-06"
                    ixz="-0.00024594"
                    iyy="0.0020661"
                    iyz="0.00010474"
                    izz="0.0013865"/>
        </inertial>
        <visual>
            <origin
                    xyz="0 0 0"
                    rpy="0 0 0"/>
            <geometry>
                <mesh
                        filename="../meshes/right_thigh_pitch_link.STL"/>
            </geometry>
            <material
                    name="">
                <color
                        rgba="0.75294 0.75294 0.75294 1"/>
            </material>
        </visual>
        <!--        <collision>-->
        <!--            <origin-->
        <!--                    xyz="0 0 0"-->
        <!--                    rpy="0 0 0"/>-->
        <!--            <geometry>-->
        <!--                <mesh-->
        <!--                        filename="../meshes/right_thigh_pitch_link.STL"/>-->
        <!--            </geometry>-->
        <!--        </collision>-->
    </link>
    <joint
            name="right_hip_pitch_joint"
            type="revolute">
        <origin
                xyz="0 -0.048521 -0.076847"
                rpy="0.2618 0 0"/>
        <parent
                link="base_link"/>
        <child
                link="right_thigh_pitch_link"/>
        <axis
                xyz="0 1 0"/>
        <limit
                lower="-2.618"
                upper="2.618"
                effort="96.7"
                velocity="10.891"/>
    </joint>
    <link
            name="right_thigh_roll_link">
        <inertial>
            <origin
                    xyz="-0.003738 -2.2055E-05 -0.022317"
                    rpy="0 0 0"/>
            <mass
                    value="1.359"/>
            <inertia
                    ixx="0.00125504"
                    ixy="-7.906E-05"
                    ixz="1.3E-07"
                    iyy="0.00301739"
                    iyz="-2.62E-06"
                    izz="0.0028871"/>
        </inertial>
        <visual>
            <origin
                    xyz="0 0 0"
                    rpy="0 0 0"/>
            <geometry>
                <mesh
                        filename="../meshes/right_thigh_roll_link.STL"/>
            </geometry>
            <material
                    name="">
                <color
                        rgba="0.75294 0.75294 0.75294 1"/>
            </material>
        </visual>
        <!--        <collision>-->
        <!--            <origin-->
        <!--                    xyz="0 0 0"-->
        <!--                    rpy="0 0 0"/>-->
        <!--            <geometry>-->
        <!--                <mesh-->
        <!--                        filename="../meshes/right_thigh_roll_link.STL"/>-->
        <!--            </geometry>-->
        <!--        </collision>-->
    </link>
    <joint
            name="right_hip_roll_joint"
            type="revolute">
        <origin
                xyz="0 -0.074 0"
                rpy="-0.2618 0 0"/>
        <parent
                link="right_thigh_pitch_link"/>
        <child
                link="right_thigh_roll_link"/>
        <axis
                xyz="1 0 0"/>
        <limit
                lower="-1.571"
                upper="0.262"
                effort="59.8"
                velocity="12.252"/>
    </joint>
    <link
            name="right_thigh_yaw_link">
        <inertial>
            <origin
                    xyz="0.0042717 0.0044788 -0.09162"
                    rpy="0 0 0"/>
            <mass
                    value="3.4519"/>
            <inertia
                    ixx="0.01595641"
                    ixy="-0.00057571"
                    ixz="8.994E-05"
                    iyy="0.00549538"
                    iyz="-0.00067874"
                    izz="0.0162559"/>
        </inertial>
        <visual>
            <origin
                    xyz="0 0 0"
                    rpy="0 0 0"/>
            <geometry>
                <mesh
                        filename="../meshes/right_thigh_yaw_link.STL"/>
            </geometry>
            <material
                    name="">
                <color
                        rgba="0.75294 0.75294 0.75294 1"/>
            </material>
        </visual>
        <collision>
            <origin
                    rpy="0 0 0"
                    xyz="0 0 0"/>
            <geometry>
                <cylinder
                        length="0.2"
                        radius="0.04"/>
            </geometry>
        </collision>
        <!--        <collision>-->
        <!--            <origin-->
        <!--                    xyz="0 0 0"-->
        <!--                    rpy="0 0 0"/>-->
        <!--            <geometry>-->
        <!--                <mesh-->
        <!--                        filename="../meshes/right_thigh_yaw_link.STL"/>-->
        <!--            </geometry>-->
        <!--        </collision>-->
    </link>
    <joint
            name="right_hip_yaw_joint"
            type="revolute">
        <origin
                xyz="0 0 -0.0875"
                rpy="0 0 0"/>
        <parent
                link="right_thigh_roll_link"/>
        <child
                link="right_thigh_yaw_link"/>
        <axis
                xyz="0 0 1"/>
        <limit
                lower="-1.571"
                upper="1.571"
                effort="59.8"
                velocity="12.252"/>
    </joint>
    <link
            name="right_shank_pitch_link">
        <inertial>
            <origin
                    xyz="0.0040923 -0.002519 -0.1174"
                    rpy="0 0 0"/>
            <mass
                    value="2.3355"/>
            <inertia
                    ixx="0.013762"
                    ixy="0.00020219"
                    ixz="-3.75E-05"
                    iyy="0.0017789"
                    iyz="-0.00028062"
                    izz="0.013763"/>
        </inertial>
        <visual>
            <origin
                    xyz="0 0 0"
                    rpy="0 0 0"/>
            <geometry>
                <mesh
                        filename="../meshes/right_shank_pitch_link.STL"/>
            </geometry>
            <material
                    name="">
                <color
                        rgba="0.75294 0.75294 0.75294 1"/>
            </material>
        </visual>
        <collision>
            <origin
                    rpy="0 0 0"
                    xyz="0 0 -0.1"/>
            <geometry>
                <cylinder
                        length="0.2"
                        radius="0.04"/>
            </geometry>
        </collision>
        <!--        <collision>-->
        <!--            <origin-->
        <!--                    xyz="0 0 0"-->
        <!--                    rpy="0 0 0"/>-->
        <!--            <geometry>-->
        <!--                <mesh-->
        <!--                        filename="../meshes/right_shank_pitch_link.STL"/>-->
        <!--            </geometry>-->
        <!--        </collision>-->
    </link>
    <joint
            name="right_knee_pitch_joint"
            type="revolute">
        <origin
                xyz="0 0 -0.2031"
                rpy="0 0 0"/>
        <parent
                link="right_thigh_yaw_link"/>
        <child
                link="right_shank_pitch_link"/>
        <axis
                xyz="0 1 0"/>
        <limit
                lower="-0.087"
                upper="2.356"
                effort="96.7"
                velocity="10.891"/>
    </joint>
    <link
            name="right_foot_roll_link">
        <inertial>
            <origin
                    xyz="6.881E-09 -0.0018059 -1.0471E-12"
                    rpy="0 0 0"/>
            <mass
                    value="0.11173"/>
            <inertia
                    ixx="2.445E-05"
                    ixy="0"
                    ixz="0"
                    iyy="2.876E-05"
                    iyz="0"
                    izz="1.162E-05"/>
        </inertial>
        <visual>
            <origin
                    xyz="0 0 0"
                    rpy="0 0 0"/>
            <geometry>
                <mesh
                        filename="../meshes/right_foot_roll_link.STL"/>
            </geometry>
            <material
                    name="">
                <color
                        rgba="0.75294 0.75294 0.75294 1"/>
            </material>
        </visual>
        <!--        <collision>-->
        <!--            <origin-->
        <!--                    xyz="0 0 0"-->
        <!--                    rpy="0 0 0"/>-->
        <!--            <geometry>-->
        <!--                <mesh-->
        <!--                        filename="../meshes/right_foot_roll_link.STL"/>-->
        <!--            </geometry>-->
        <!--        </collision>-->
    </link>
    <joint
            name="right_ankle_roll_joint"
            type="revolute">
        <origin
                xyz="0 0 -0.28"
                rpy="0 0 0"/>
        <parent
                link="right_shank_pitch_link"/>
        <child
                link="right_foot_roll_link"/>
        <axis
                xyz="1 0 0"/>
        <limit
                lower="-0.436"
                upper="0.436"
                effort="29.3"
                velocity="13.927"/>
    </joint>
    <link
            name="right_foot_pitch_link">
        <inertial>
            <origin
                    xyz="0.023908 0.00023123 -0.0302"
                    rpy="0 0 0"/>
            <mass
                    value="0.39067"/>
            <inertia
                    ixx="0.00014601"
                    ixy="7.67E-06"
                    ixz="-4.92E-06"
                    iyy="0.00090087"
                    iyz="3.3E-07"
                    izz="0.00084381"/>
        </inertial>
        <visual>
            <origin
                    xyz="0 0 0"
                    rpy="0 0 0"/>
            <geometry>
                <mesh
                        filename="../meshes/right_foot_pitch_link.STL"/>
            </geometry>
            <material
                    name="">
                <color
                        rgba="0.75294 0.75294 0.75294 1"/>
            </material>
        </visual>
        <collision>
            <origin
                    rpy="0 1.5708 0"
                    xyz="0.025 -0.015 -0.025"/>
            <geometry>
                <cylinder
                        length="0.15"
                        radius="0.015"/>
            </geometry>
        </collision>
        <collision>
            <origin
                    rpy="0 1.5708 0"
                    xyz="0.025 0.015 -0.025"/>
            <geometry>
                <cylinder
                        length="0.15"
                        radius="0.015"/>
            </geometry>
        </collision>
        <!--        <collision>-->
        <!--            <origin-->
        <!--                    xyz="0 0 0"-->
        <!--                    rpy="0 0 0"/>-->
        <!--            <geometry>-->
        <!--                <mesh-->
        <!--                        filename="../meshes/right_foot_pitch_link.STL"/>-->
        <!--            </geometry>-->
        <!--        </collision>-->
    </link>
    <joint
            name="right_ankle_pitch_joint"
            type="revolute">
        <origin
                xyz="0 0 0"
                rpy="0 0 0"/>
        <parent
                link="right_foot_roll_link"/>
        <child
                link="right_foot_pitch_link"/>
        <axis
                xyz="0 1 0"/>
        <limit
                lower="-0.96"
                upper="0.838"
                effort="29.3"
                velocity="13.927"/>
    </joint>
</robot>