<?xml version='1.0' encoding='ASCII'?>
<robot name="GR2">
    <link name="base_link">
        <inertial>
            <origin xyz="-0.0030357 6.968e-05 -0.087284" rpy="0.0 -0.0 0.0"/>
            <mass value="6.6598"/>
            <inertia ixx="0.048356" ixy="-1.314e-05" ixz="0.00041517" iyy="0.030781" iyz="-3.242e-05" izz="0.041191"/>
        </inertial>
        <visual>
            <geometry>
                <mesh filename="../meshes/base_link.STL"/>
            </geometry>
            <origin xyz="0.0 0.0 0.0" rpy="0.0 -0.0 0.0"/>
            <material name="">
                <color rgba="1.0 1.0 1.0 1.0"/>
            </material>
        </visual>
        <collision>
            <origin
                    xyz="-0.03 0 -0.08"
                    rpy="1.57 0 0"/>
            <geometry>
                <cylinder radius="0.1" length="0.1"/>
            </geometry>
        </collision>
    </link>
    <link name="waist_yaw_link">
        <inertial>
            <origin xyz="-2.017e-05 8.88e-05 0.024104" rpy="0.0 -0.0 0.0"/>
            <mass value="0.67252"/>
            <inertia ixx="0.6066425" ixy="9e-08" ixz="-4.3e-07" iyy="0.6066427" iyz="3.7e-07" izz="0.6061712899999999"/>
        </inertial>
        <visual>
            <geometry>
                <mesh filename="../meshes/waist_yaw_link.STL"/>
            </geometry>
            <origin xyz="0.0 0.0 0.0" rpy="0.0 -0.0 0.0"/>
            <material name="">
                <color rgba="1.0 1.0 1.0 1.0"/>
            </material>
        </visual>
    </link>
    <link name="torso_link">
        <inertial>
            <origin xyz="-0.0054214 0.0010624 -0.12326" rpy="0.0 -0.0 0.0"/>
            <mass value="14.058"/>
            <inertia ixx="0.2545" ixy="0.0001127" ixz="-0.0023" iyy="0.21565" iyz="0.00034939" izz="0.1107"/>
        </inertial>
        <visual>
            <geometry>
                <mesh filename="../meshes/torso_link.STL"/>
            </geometry>
            <origin xyz="0.0 0.0 0.0" rpy="0.0 -0.0 0.0"/>
            <material name="">
                <color rgba="1.0 1.0 1.0 1.0"/>
            </material>
        </visual>
        <collision>
            <origin
                    xyz="0 0 -0.13"
                    rpy="0 0 0"/>
            <geometry>
                <cylinder radius="0.13" length="0.13"/>
            </geometry>
        </collision>
    </link>
    <link name="head_yaw_link">
        <inertial>
            <origin xyz="0.0 0.0099543 0.0065646" rpy="0.0 -0.0 0.0"/>
            <mass value="0.1402"/>
            <inertia ixx="0.11084944" ixy="0.0" ixz="0.0" iyy="0.11082676" iyz="-3.991e-05" izz="0.11076821"/>
        </inertial>
        <visual>
            <geometry>
                <mesh filename="../meshes/head_yaw_link.STL"/>
            </geometry>
            <origin xyz="0.0 0.0 0.0" rpy="0.0 -0.0 0.0"/>
            <material name="">
                <color rgba="1.0 1.0 1.0 1.0"/>
            </material>
        </visual>
    </link>
    <link name="head_pitch_link">
        <inertial>
            <origin xyz="0.031582 0.0012059 0.072239" rpy="0.0 -0.0 0.0"/>
            <mass value="1.6096"/>
            <inertia ixx="0.1184457" ixy="-1.346e-05" ixz="-0.00055988" iyy="0.121144" iyz="0.00010711" izz="0.1167999"/>
        </inertial>
        <visual>
            <geometry>
                <mesh filename="../meshes/head_pitch_link.STL"/>
            </geometry>
            <origin xyz="0.0 0.0 0.0" rpy="0.0 -0.0 0.0"/>
            <material name="">
                <color rgba="1.0 1.0 1.0 1.0"/>
            </material>
        </visual>
        <collision>
            <origin
                    xyz="0.02 0 0.07"
                    rpy="0 0 0"/>
            <geometry>
                <sphere radius="0.09"/>
            </geometry>
        </collision>
    </link>
    <link name="camera_link">
        <inertial>
            <origin xyz="0.0 0.0 0.0" rpy="0.0 -0.0 0.0"/>
            <mass value="0.0"/>
            <inertia ixx="0.0" ixy="0.0" ixz="0.0" iyy="0.0" iyz="0.0" izz="0.0"/>
        </inertial>
    </link>
    <link name="left_upper_arm_pitch_link">
        <inertial>
            <origin xyz="0.0022312 0.040265 3.797e-05" rpy="0.0 -0.0 0.0"/>
            <mass value="1.3432"/>
            <inertia ixx="0.6087614" ixy="-7.306e-05" ixz="-1.5e-07" iyy="0.6068363999999999" iyz="9e-08" izz="0.6086245"/>
        </inertial>
        <visual>
            <geometry>
                <mesh filename="../meshes/left_upper_arm_pitch_link.STL"/>
            </geometry>
            <origin xyz="0.0 0.0 0.0" rpy="0.0 -0.0 0.0"/>
            <material name="">
                <color rgba="1.0 1.0 1.0 1.0"/>
            </material>
        </visual>
    </link>
    <link name="left_upper_arm_roll_link">
        <inertial>
            <origin xyz="0.0087432 0.0022878 -0.038787" rpy="0.0 -0.0 0.0"/>
            <mass value="0.96142"/>
            <inertia ixx="0.6081913999999999" ixy="1.105e-05" ixz="-0.00033468" iyy="0.608382" iyz="2.91e-06" izz="0.60649221"/>
        </inertial>
        <visual>
            <geometry>
                <mesh filename="../meshes/left_upper_arm_roll_link.STL"/>
            </geometry>
            <origin xyz="0.0 0.0 0.0" rpy="0.0 -0.0 0.0"/>
            <material name="">
                <color rgba="1.0 1.0 1.0 1.0"/>
            </material>
        </visual>
    </link>
    <link name="left_upper_arm_yaw_link">
        <inertial>
            <origin xyz="-0.00056161 0.0012137 -0.091108" rpy="0.0 -0.0 0.0"/>
            <mass value="1.3181"/>
            <inertia ixx="0.2292415" ixy="3.2e-07" ixz="-5.12e-06" iyy="0.2292571" iyz="9.238e-05" izz="0.2235365"/>
        </inertial>
        <visual>
            <geometry>
                <mesh filename="../meshes/left_upper_arm_yaw_link.STL"/>
            </geometry>
            <origin xyz="0.0 0.0 0.0" rpy="0.0 -0.0 0.0"/>
            <material name="">
                <color rgba="1.0 1.0 1.0 1.0"/>
            </material>
        </visual>
        <collision>
            <origin
                    xyz="0 0 0"
                    rpy="0 0 0"/>
            <geometry>
                <cylinder radius="0.04" length="0.10"/>
            </geometry>
        </collision>
    </link>
    <link name="left_lower_arm_pitch_link">
        <inertial>
            <origin xyz="-0.0014862 0.006973 -0.021097" rpy="0.0 -0.0 0.0"/>
            <mass value="0.45807"/>
            <inertia ixx="0.22314093999999998" ixy="-3.65e-06" ixz="-2.99e-06" iyy="0.22302583999999998" iyz="-6.575e-05" izz="0.22284016999999998"/>
        </inertial>
        <visual>
            <geometry>
                <mesh filename="../meshes/left_lower_arm_pitch_link.STL"/>
            </geometry>
            <origin xyz="0.0 0.0 0.0" rpy="0.0 -0.0 0.0"/>
            <material name="">
                <color rgba="1.0 1.0 1.0 1.0"/>
            </material>
        </visual>
    </link>
    <link name="left_hand_yaw_link">
        <inertial>
            <origin xyz="0.00027991 0.0038031 -0.062955" rpy="0.0 -0.0 0.0"/>
            <mass value="1.0855"/>
            <inertia ixx="0.1130798" ixy="-9.31e-06" ixz="2.063e-05" iyy="0.112954" iyz="0.00013994" izz="0.11160838"/>
        </inertial>
        <visual>
            <geometry>
                <mesh filename="../meshes/left_hand_yaw_link.STL"/>
            </geometry>
            <origin xyz="0.0 0.0 0.0" rpy="0.0 -0.0 0.0"/>
            <material name="">
                <color rgba="1.0 1.0 1.0 1.0"/>
            </material>
        </visual>
        <collision>
            <origin
                    xyz="0 0 -0.05"
                    rpy="0 0 0"/>
            <geometry>
                <cylinder radius="0.045" length="0.115"/>
            </geometry>
        </collision>
    </link>
    <link name="left_hand_pitch_link">
        <inertial>
            <origin xyz="0.0045911 2.426e-05 1.61e-06" rpy="0.0 -0.0 0.0"/>
            <mass value="0.51916"/>
            <inertia ixx="0.11093986" ixy="-3.7e-07" ixz="-1e-07" iyy="0.11096897" iyz="-2.1e-07" izz="0.11097566"/>
        </inertial>
        <visual>
            <geometry>
                <mesh filename="../meshes/left_hand_pitch_link.STL"/>
            </geometry>
            <origin xyz="0.0 0.0 0.0" rpy="0.0 -0.0 0.0"/>
            <material name="">
                <color rgba="1.0 1.0 1.0 1.0"/>
            </material>
        </visual>
    </link>
    <link name="left_hand_roll_link">
        <inertial>
            <origin xyz="0.0081828 -4.116e-05 -0.022647" rpy="0.0 -0.0 0.0"/>
            <mass value="0.14059"/>
            <inertia ixx="0.11080243" ixy="-1e-08" ixz="-2.27e-05" iyy="0.11087239" iyz="-2e-08" izz="0.11084817"/>
        </inertial>
        <visual>
            <geometry>
                <mesh filename="../meshes/left_hand_roll_link.STL"/>
            </geometry>
            <origin xyz="0.0 0.0 0.0" rpy="0.0 -0.0 0.0"/>
            <material name="">
                <color rgba="1.0 1.0 1.0 1.0"/>
            </material>
        </visual>
    </link>
    <link name="left_end_effector_link">
        <inertial>
            <origin xyz="0.0 0.0 0.0" rpy="0.0 -0.0 0.0"/>
            <mass value="0.0"/>
            <inertia ixx="0.0" ixy="0.0" ixz="0.0" iyy="0.0" iyz="0.0" izz="0.0"/>
        </inertial>
    </link>
    <link name="right_upper_arm_pitch_link">
        <inertial>
            <origin xyz="0.0022312 -0.040265 3.797e-05" rpy="0.0 -0.0 0.0"/>
            <mass value="1.3432"/>
            <inertia ixx="0.6087614" ixy="7.306e-05" ixz="-1.5e-07" iyy="0.6068363999999999" iyz="-9e-08" izz="0.6086245"/>
        </inertial>
        <visual>
            <geometry>
                <mesh filename="../meshes/right_upper_arm_pitch_link.STL"/>
            </geometry>
            <origin xyz="0.0 0.0 0.0" rpy="0.0 -0.0 0.0"/>
            <material name="">
                <color rgba="1.0 1.0 1.0 1.0"/>
            </material>
        </visual>
    </link>
    <link name="right_upper_arm_roll_link">
        <inertial>
            <origin xyz="0.0087432 -0.0022878 -0.038787" rpy="0.0 -0.0 0.0"/>
            <mass value="0.96142"/>
            <inertia ixx="0.6081913999999999" ixy="-1.105e-05" ixz="-0.00033468" iyy="0.608382" iyz="-2.91e-06" izz="0.60649221"/>
        </inertial>
        <visual>
            <geometry>
                <mesh filename="../meshes/right_upper_arm_roll_link.STL"/>
            </geometry>
            <origin xyz="0.0 0.0 0.0" rpy="0.0 -0.0 0.0"/>
            <material name="">
                <color rgba="1.0 1.0 1.0 1.0"/>
            </material>
        </visual>
    </link>
    <link name="right_upper_arm_yaw_link">
        <inertial>
            <origin xyz="-0.00056161 -0.0012137 -0.091108" rpy="0.0 -0.0 0.0"/>
            <mass value="1.3181"/>
            <inertia ixx="0.2292415" ixy="-3.2e-07" ixz="-5.12e-06" iyy="0.2292571" iyz="-9.238e-05" izz="0.2235365"/>
        </inertial>
        <visual>
            <geometry>
                <mesh filename="../meshes/right_upper_arm_yaw_link.STL"/>
            </geometry>
            <origin xyz="0.0 0.0 0.0" rpy="0.0 -0.0 0.0"/>
            <material name="">
                <color rgba="1.0 1.0 1.0 1.0"/>
            </material>
        </visual>
        <collision>
            <origin
                    xyz="0 0 0"
                    rpy="0 0 0"/>
            <geometry>
                <cylinder radius="0.040" length="0.1"/>
            </geometry>
        </collision>
    </link>
    <link name="right_lower_arm_pitch_link">
        <inertial>
            <origin xyz="-0.0014862 -0.006973 -0.021097" rpy="0.0 -0.0 0.0"/>
            <mass value="0.45807"/>
            <inertia ixx="0.22314093999999998" ixy="3.65e-06" ixz="-2.99e-06" iyy="0.22302583999999998" iyz="6.575e-05" izz="0.22284016999999998"/>
        </inertial>
        <visual>
            <geometry>
                <mesh filename="../meshes/right_lower_arm_pitch_link.STL"/>
            </geometry>
            <origin xyz="0.0 0.0 0.0" rpy="0.0 -0.0 0.0"/>
            <material name="">
                <color rgba="1.0 1.0 1.0 1.0"/>
            </material>
        </visual>
    </link>
    <link name="right_hand_yaw_link">
        <inertial>
            <origin xyz="0.00027991 -0.0038031 -0.062955" rpy="0.0 -0.0 0.0"/>
            <mass value="1.0855"/>
            <inertia ixx="0.1130798" ixy="9.31e-06" ixz="2.063e-05" iyy="0.112954" iyz="-0.00013994" izz="0.11160838"/>
        </inertial>
        <visual>
            <geometry>
                <mesh filename="../meshes/right_hand_yaw_link.STL"/>
            </geometry>
            <origin xyz="0.0 0.0 0.0" rpy="0.0 -0.0 0.0"/>
            <material name="">
                <color rgba="1.0 1.0 1.0 1.0"/>
            </material>
        </visual>
        <collision>
            <origin
                    xyz="0 0 -0.05"
                    rpy="0 0 0"/>
            <geometry>
                <cylinder radius="0.045" length="0.1155"/>
            </geometry>
        </collision>
    </link>
    <link name="right_hand_pitch_link">
        <inertial>
            <origin xyz="0.0045911 -2.426e-05 1.61e-06" rpy="0.0 -0.0 0.0"/>
            <mass value="0.51916"/>
            <inertia ixx="0.11093986" ixy="3.7e-07" ixz="-1e-07" iyy="0.11096897" iyz="2.1e-07" izz="0.11097566"/>
        </inertial>
        <visual>
            <geometry>
                <mesh filename="../meshes/right_hand_pitch_link.STL"/>
            </geometry>
            <origin xyz="0.0 0.0 0.0" rpy="0.0 -0.0 0.0"/>
            <material name="">
                <color rgba="1.0 1.0 1.0 1.0"/>
            </material>
        </visual>
    </link>
    <link name="right_hand_roll_link">
        <inertial>
            <origin xyz="0.0081828 4.116e-05 -0.022647" rpy="0.0 -0.0 0.0"/>
            <mass value="0.14059"/>
            <inertia ixx="0.11080243" ixy="1e-08" ixz="-2.27e-05" iyy="0.11087239" iyz="2e-08" izz="0.11084817"/>
        </inertial>
        <visual>
            <geometry>
                <mesh filename="../meshes/right_hand_roll_link.STL"/>
            </geometry>
            <origin xyz="0.0 0.0 0.0" rpy="0.0 -0.0 0.0"/>
            <material name="">
                <color rgba="1.0 1.0 1.0 1.0"/>
            </material>
        </visual>
    </link>
    <link name="right_end_effector_link">
        <inertial>
            <origin xyz="0.0 0.0 0.0" rpy="0.0 -0.0 0.0"/>
            <mass value="0.0"/>
            <inertia ixx="0.0" ixy="0.0" ixz="0.0" iyy="0.0" iyz="0.0" izz="0.0"/>
        </inertial>
    </link>
    <link name="left_thigh_pitch_link">
        <inertial>
            <origin xyz="-0.035065 0.036467 0.0020083" rpy="0.0 -0.0 0.0"/>
            <mass value="2.61"/>
            <inertia ixx="0.9385802" ixy="0.0031974" ixz="-8.035e-05" iyy="0.9395807" iyz="-9.448e-05" izz="0.942703"/>
        </inertial>
        <visual>
            <geometry>
                <mesh filename="../meshes/left_thigh_pitch_link.STL"/>
            </geometry>
            <origin xyz="0.0 0.0 0.0" rpy="0.0 -0.0 0.0"/>
            <material name="">
                <color rgba="1.0 1.0 1.0 1.0"/>
            </material>
        </visual>
    </link>
    <link name="left_thigh_roll_link">
        <inertial>
            <origin xyz="0.027776 -0.00010848 -0.0074687" rpy="0.0 -0.0 0.0"/>
            <mass value="1.3487"/>
            <inertia ixx="0.12227924" ixy="-5.3e-06" ixz="0.00034163" iyy="0.12373514" iyz="-3.01e-06" izz="0.12386334"/>
        </inertial>
        <visual>
            <geometry>
                <mesh filename="../meshes/left_thigh_roll_link.STL"/>
            </geometry>
            <origin xyz="0.0 0.0 0.0" rpy="0.0 -0.0 0.0"/>
            <material name="">
                <color rgba="1.0 1.0 1.0 1.0"/>
            </material>
        </visual>
    </link>
    <link name="left_thigh_yaw_link">
        <inertial>
            <origin xyz="0.0010147 -0.012758 -0.14387" rpy="0.0 -0.0 0.0"/>
            <mass value="5.1152"/>
            <inertia ixx="0.209888009139308" ixy="-8.538e-05" ixz="0.00038855" iyy="0.210775009139308" iyz="0.00098874" izz="0.177511809139308"/>
        </inertial>
        <visual>
            <geometry>
                <mesh filename="../meshes/left_thigh_yaw_link.STL"/>
            </geometry>
            <origin xyz="0.0 0.0 0.0" rpy="0.0 -0.0 0.0"/>
            <material name="">
                <color rgba="1.0 1.0 1.0 1.0"/>
            </material>
        </visual>
        <collision>
            <origin
                    xyz="0 0 -0.2"
                    rpy="0 0 0"/>
            <geometry>
                <cylinder radius="0.06" length="0.2"/>
            </geometry>
        </collision>
    </link>
    <link name="left_shank_pitch_link">
        <inertial>
            <origin xyz="0.004743 -0.0014414 -0.1756" rpy="0.0 -0.0 0.0"/>
            <mass value="3.5932"/>
            <inertia ixx="0.9658680000000001" ixy="-1.912e-05" ixz="-6.005e-05" iyy="0.966353" iyz="0.0010678" izz="0.9353132"/>
        </inertial>
        <visual>
            <geometry>
                <mesh filename="../meshes/left_shank_pitch_link.STL"/>
            </geometry>
            <origin xyz="0.0 0.0 0.0" rpy="0.0 -0.0 0.0"/>
            <material name="">
                <color rgba="1.0 1.0 1.0 1.0"/>
            </material>
        </visual>
        <collision>
            <origin
                    xyz="0 0 -0.2"
                    rpy="0 0 0"/>
            <geometry>
                <cylinder radius="0.05" length="0.2"/>
            </geometry>
        </collision>
    </link>
    <link name="left_foot_pitch_link">
        <inertial>
            <origin xyz="0.026267 1.226e-05 0.0010987" rpy="0.0 -0.0 0.0"/>
            <mass value="0.17877"/>
            <inertia ixx="0.167604619139308" ixy="-9e-08" ixz="5.14e-06" iyy="0.167811149139308" iyz="-1.8e-07" izz="0.167812119139308"/>
        </inertial>
        <visual>
            <geometry>
                <mesh filename="../meshes/left_foot_pitch_link.STL"/>
            </geometry>
            <origin xyz="0.0 0.0 0.0" rpy="0.0 -0.0 0.0"/>
            <material name="">
                <color rgba="1.0 1.0 1.0 1.0"/>
            </material>
        </visual>
    </link>
    <link name="left_foot_roll_link">
        <inertial>
            <origin xyz="0.050086 0.006159 -0.032795" rpy="0.0 -0.0 0.0"/>
            <mass value="1.1232"/>
            <inertia ixx="0.0325434" ixy="0.00033767" ixz="0.00043059" iyy="0.037989600000000005" iyz="-0.00019341" izz="0.0384948"/>
        </inertial>
        <visual>
            <geometry>
                <mesh filename="../meshes/left_foot_roll_link.STL"/>
            </geometry>
            <origin xyz="0.0 0.0 0.0" rpy="0.0 -0.0 0.0"/>
            <material name="">
                <color rgba="1.0 1.0 1.0 1.0"/>
            </material>
        </visual>
        <collision>
            <origin
                    rpy="0 1.5707 0"
                    xyz="0.055 0.026 -0.045"/>
            <geometry>
                <cylinder
                        length="0.225"
                        radius="0.013"/>
            </geometry>
        </collision>
        <collision>
            <origin
                    rpy="0 0 0"
                    xyz="0.055 0 -0.045"/>
            <geometry>
                <box size="0.225 0.052 0.026"/>
            </geometry>
        </collision>
        <collision>
            <origin
                    rpy="0 1.5707 0"
                    xyz="0.055 -0.026 -0.045"/>
            <geometry>
                <cylinder
                        length="0.225"
                        radius="0.013"/>
            </geometry>
        </collision>
    </link>
    <link name="right_thigh_pitch_link">
        <inertial>
            <origin xyz="-0.035065 -0.036467 0.0020083" rpy="0.0 -0.0 0.0"/>
            <mass value="2.61"/>
            <inertia ixx="0.9385802" ixy="-0.0031974" ixz="-8.035e-05" iyy="0.9395807" iyz="9.448e-05" izz="0.942703"/>
        </inertial>
        <visual>
            <geometry>
                <mesh filename="../meshes/right_thigh_pitch_link.STL"/>
            </geometry>
            <origin xyz="0.0 0.0 0.0" rpy="0.0 -0.0 0.0"/>
            <material name="">
                <color rgba="1.0 1.0 1.0 1.0"/>
            </material>
        </visual>
    </link>
    <link name="right_thigh_roll_link">
        <inertial>
            <origin xyz="0.027776 0.00010848 -0.0074687" rpy="0.0 -0.0 0.0"/>
            <mass value="1.3487"/>
            <inertia ixx="0.12227924" ixy="5.3e-06" ixz="0.00034163" iyy="0.12373514" iyz="3.01e-06" izz="0.12386334"/>
        </inertial>
        <visual>
            <geometry>
                <mesh filename="../meshes/right_thigh_roll_link.STL"/>
            </geometry>
            <origin xyz="0.0 0.0 0.0" rpy="0.0 -0.0 0.0"/>
            <material name="">
                <color rgba="1.0 1.0 1.0 1.0"/>
            </material>
        </visual>
    </link>
    <link name="right_thigh_yaw_link">
        <inertial>
            <origin xyz="0.0010147 0.012758 -0.14387" rpy="0.0 -0.0 0.0"/>
            <mass value="5.1152"/>
            <inertia ixx="0.209888009139308" ixy="8.538e-05" ixz="0.00038855" iyy="0.210775009139308" iyz="-0.00098874" izz="0.177511809139308"/>
        </inertial>
        <visual>
            <geometry>
                <mesh filename="../meshes/right_thigh_yaw_link.STL"/>
            </geometry>
            <origin xyz="0.0 0.0 0.0" rpy="0.0 -0.0 0.0"/>
            <material name="">
                <color rgba="1.0 1.0 1.0 1.0"/>
            </material>
        </visual>
        <collision>
            <origin
                    xyz="0 0 -0.2"
                    rpy="0 0 0"/>
            <geometry>
                <cylinder radius="0.06" length="0.2"/>
            </geometry>
        </collision>
    </link>
    <link name="right_shank_pitch_link">
        <inertial>
            <origin xyz="0.004743 0.0014414 -0.1756" rpy="0.0 -0.0 0.0"/>
            <mass value="3.5932"/>
            <inertia ixx="0.9658680000000001" ixy="1.912e-05" ixz="-6.005e-05" iyy="0.966353" iyz="-0.0010678" izz="0.9353132"/>
        </inertial>
        <visual>
            <geometry>
                <mesh filename="../meshes/right_shank_pitch_link.STL"/>
            </geometry>
            <origin xyz="0.0 0.0 0.0" rpy="0.0 -0.0 0.0"/>
            <material name="">
                <color rgba="1.0 1.0 1.0 1.0"/>
            </material>
        </visual>
        <collision>
            <origin
                    xyz="0 0 -0.2"
                    rpy="0 0 0"/>
            <geometry>
                <cylinder radius="0.05" length="0.2"/>
            </geometry>
        </collision>
    </link>
    <link name="right_foot_pitch_link">
        <inertial>
            <origin xyz="0.026267 -1.226e-05 0.0010987" rpy="0.0 -0.0 0.0"/>
            <mass value="0.17877"/>
            <inertia ixx="0.167604619139308" ixy="9e-08" ixz="5.14e-06" iyy="0.167811149139308" iyz="1.8e-07" izz="0.167812119139308"/>
        </inertial>
        <visual>
            <geometry>
                <mesh filename="../meshes/right_foot_pitch_link.STL"/>
            </geometry>
            <origin xyz="0.0 0.0 0.0" rpy="0.0 -0.0 0.0"/>
            <material name="">
                <color rgba="1.0 1.0 1.0 1.0"/>
            </material>
        </visual>
    </link>
    <link name="right_foot_roll_link">
        <inertial>
            <origin xyz="0.050086 -0.006159 -0.032795" rpy="0.0 -0.0 0.0"/>
            <mass value="1.1232"/>
            <inertia ixx="0.0325434" ixy="-0.00033767" ixz="0.00043059" iyy="0.037989600000000005" iyz="0.00019341" izz="0.0384948"/>
        </inertial>
        <visual>
            <geometry>
                <mesh filename="../meshes/right_foot_roll_link.STL"/>
            </geometry>
            <origin xyz="0.0 0.0 0.0" rpy="0.0 -0.0 0.0"/>
            <material name="">
                <color rgba="1.0 1.0 1.0 1.0"/>
            </material>
        </visual>
        <collision>
            <origin
                    rpy="0 1.5707 0"
                    xyz="0.055 0.026 -0.045"/>
            <geometry>
                <cylinder
                        length="0.225"
                        radius="0.013"/>
            </geometry>
        </collision>
        <collision>
            <origin
                    rpy="0 0 0"
                    xyz="0.055 0 -0.045"/>
            <geometry>
                <box size="0.225 0.052 0.026"/>
            </geometry>
        </collision>
        <collision>
            <origin
                    rpy="0 1.5707 0"
                    xyz="0.055 -0.026 -0.045"/>
            <geometry>
                <cylinder
                        length="0.225"
                        radius="0.013"/>
            </geometry>
        </collision>
    </link>
    <link name="imu_link">
        <inertial>
            <origin xyz="0.0 0.0 0.0" rpy="0.0 -0.0 0.0"/>
            <mass value="0.0"/>
            <inertia ixx="0.0" ixy="0.0" ixz="0.0" iyy="0.0" iyz="0.0" izz="0.0"/>
        </inertial>
    </link>
    <joint name="waist_yaw_joint" type="revolute">
        <parent link="base_link"/>
        <child link="waist_yaw_link"/>
        <origin xyz="0.0 0.0 -0.0159" rpy="0.0 -0.0 0.0"/>
        <axis xyz="0.0 0.0 1.0"/>
        <limit effort="74.45" velocity="7.7568" lower="-2.618" upper="2.618"/>
    </joint>
    <joint name="torso_joint" type="fixed">
        <parent link="waist_yaw_link"/>
        <child link="torso_link"/>
        <origin xyz="0.0 0.0 0.39681" rpy="0.0 -0.0 0.0"/>
        <axis xyz="0.0 0.0 0.0"/>
    </joint>
    <joint name="head_yaw_joint" type="revolute">
        <parent link="torso_link"/>
        <child link="head_yaw_link"/>
        <origin xyz="0.001 0.0 0.11061" rpy="0.0 -0.0 0.0"/>
        <axis xyz="0.0 0.0 1.0"/>
        <limit effort="17.325" velocity="9.1627" lower="-1.3963" upper="1.3963"/>
    </joint>
    <joint name="head_pitch_joint" type="revolute">
        <parent link="head_yaw_link"/>
        <child link="head_pitch_link"/>
        <origin xyz="0.0 0.0 0.044185" rpy="0.0 -0.0 0.0"/>
        <axis xyz="0.0 1.0 0.0"/>
        <limit effort="17.325" velocity="9.1627" lower="-0.5236" upper="0.5236"/>
    </joint>
    <joint name="camera_joint" type="fixed">
        <parent link="head_pitch_link"/>
        <child link="camera_link"/>
        <origin xyz="0.11296 0.0 0.09815" rpy="0.0 -0.0 0.0"/>
        <axis xyz="0.0 0.0 0.0"/>
    </joint>
    <joint name="left_shoulder_pitch_joint" type="revolute">
        <parent link="torso_link"/>
        <child link="left_upper_arm_pitch_link"/>
        <origin xyz="0.0 0.15115 0.0" rpy="0.0 -0.0 0.0"/>
        <axis xyz="0.0 1.0 0.0"/>
        <limit effort="74.45" velocity="7.7568" lower="-2.9671" upper="2.9671"/>
    </joint>
    <joint name="left_shoulder_roll_joint" type="revolute">
        <parent link="left_upper_arm_pitch_link"/>
        <child link="left_upper_arm_roll_link"/>
        <origin xyz="0.0 0.078848 0.0" rpy="0.0 -0.0 0.0"/>
        <axis xyz="1.0 0.0 0.0"/>
        <limit effort="74.45" velocity="7.7568" lower="-0.5236" upper="2.7925"/>
    </joint>
    <joint name="left_shoulder_yaw_joint" type="revolute">
        <parent link="left_upper_arm_roll_link"/>
        <child link="left_upper_arm_yaw_link"/>
        <origin xyz="0.0 0.0 -0.09438" rpy="0.0 -0.0 0.0"/>
        <axis xyz="0.0 0.0 1.0"/>
        <limit effort="42.75" velocity="6.283" lower="-1.8326" upper="1.8326"/>
    </joint>
    <joint name="left_elbow_pitch_joint" type="revolute">
        <parent link="left_upper_arm_yaw_link"/>
        <child link="left_lower_arm_pitch_link"/>
        <origin xyz="0.0 0.0 -0.16111" rpy="0.0 -0.3926 0.0"/>
        <axis xyz="0.0 1.0 0.0"/>
        <limit effort="42.75" velocity="6.283" lower="-1.5272" upper="0.47997"/>
    </joint>
    <joint name="left_wrist_yaw_joint" type="revolute">
        <parent link="left_lower_arm_pitch_link"/>
        <child link="left_hand_yaw_link"/>
        <origin xyz="0.0 0.0 -0.058525" rpy="0.0 -0.0 0.0"/>
        <axis xyz="0.0 0.0 1.0"/>
        <limit effort="17.325" velocity="9.1627" lower="-1.8326" upper="1.8326"/>
    </joint>
    <joint name="left_wrist_pitch_joint" type="revolute">
        <parent link="left_hand_yaw_link"/>
        <child link="left_hand_pitch_link"/>
        <origin xyz="0.0 0.0 -0.16102" rpy="0.0 -0.0 0.0"/>
        <axis xyz="0.0 1.0 0.0"/>
        <limit effort="17.325" velocity="9.1627" lower="-0.61087" upper="0.61087"/>
    </joint>
    <joint name="left_wrist_roll_joint" type="revolute">
        <parent link="left_hand_pitch_link"/>
        <child link="left_hand_roll_link"/>
        <origin xyz="0.0 0.0 0.0" rpy="0.0 -0.0 0.0"/>
        <axis xyz="1.0 0.0 0.0"/>
        <limit effort="17.325" velocity="9.1627" lower="-0.95993" upper="0.95993"/>
    </joint>
    <joint name="left_end_effector_joint" type="fixed">
        <parent link="left_hand_roll_link"/>
        <child link="left_end_effector_link"/>
        <origin xyz="0.0 0.0 -0.052" rpy="0.0 -0.0 0.0"/>
        <axis xyz="0.0 0.0 0.0"/>
    </joint>
    <joint name="right_shoulder_pitch_joint" type="revolute">
        <parent link="torso_link"/>
        <child link="right_upper_arm_pitch_link"/>
        <origin xyz="0.0 -0.1585 0.0" rpy="0.0 -0.0 0.0"/>
        <axis xyz="0.0 1.0 0.0"/>
        <limit effort="74.45" velocity="7.7568" lower="-2.9671" upper="2.9671"/>
    </joint>
    <joint name="right_shoulder_roll_joint" type="revolute">
        <parent link="right_upper_arm_pitch_link"/>
        <child link="right_upper_arm_roll_link"/>
        <origin xyz="0.0 -0.071498 0.0" rpy="0.0 -0.0 0.0"/>
        <axis xyz="1.0 0.0 0.0"/>
        <limit effort="74.45" velocity="7.7568" lower="-2.7925" upper="0.5236"/>
    </joint>
    <joint name="right_shoulder_yaw_joint" type="revolute">
        <parent link="right_upper_arm_roll_link"/>
        <child link="right_upper_arm_yaw_link"/>
        <origin xyz="0.0 0.0 -0.09438" rpy="0.0 -0.0 0.0"/>
        <axis xyz="0.0 0.0 1.0"/>
        <limit effort="42.75" velocity="6.283" lower="-1.8326" upper="1.8326"/>
    </joint>
    <joint name="right_elbow_pitch_joint" type="revolute">
        <parent link="right_upper_arm_yaw_link"/>
        <child link="right_lower_arm_pitch_link"/>
        <origin xyz="0.0 0.0 -0.16111" rpy="0.0 -0.39265 0.0"/>
        <axis xyz="0.0 1.0 0.0"/>
        <limit effort="42.75" velocity="6.283" lower="-1.5272" upper="0.47997"/>
    </joint>
    <joint name="right_wrist_yaw_joint" type="revolute">
        <parent link="right_lower_arm_pitch_link"/>
        <child link="right_hand_yaw_link"/>
        <origin xyz="0.0 0.0 -0.058525" rpy="0.0 -0.0 0.0"/>
        <axis xyz="0.0 0.0 1.0"/>
        <limit effort="17.325" velocity="9.1627" lower="-1.8326" upper="1.8326"/>
    </joint>
    <joint name="right_wrist_pitch_joint" type="revolute">
        <parent link="right_hand_yaw_link"/>
        <child link="right_hand_pitch_link"/>
        <origin xyz="0.0 0.0 -0.16102" rpy="0.0 -0.0 0.0"/>
        <axis xyz="0.0 1.0 0.0"/>
        <limit effort="17.325" velocity="9.1627" lower="-0.61087" upper="0.61087"/>
    </joint>
    <joint name="right_wrist_roll_joint" type="revolute">
        <parent link="right_hand_pitch_link"/>
        <child link="right_hand_roll_link"/>
        <origin xyz="0.0 0.0 0.0" rpy="0.0 -0.0 0.0"/>
        <axis xyz="1.0 0.0 0.0"/>
        <limit effort="17.325" velocity="9.1627" lower="-0.95993" upper="0.95993"/>
    </joint>
    <joint name="right_end_effector_joint" type="fixed">
        <parent link="right_hand_roll_link"/>
        <child link="right_end_effector_link"/>
        <origin xyz="0.0 0.0 -0.052" rpy="0.0 -0.0 0.0"/>
        <axis xyz="0.0 0.0 0.0"/>
    </joint>
    <joint name="left_hip_pitch_joint" type="revolute">
        <parent link="base_link"/>
        <child link="left_thigh_pitch_link"/>
        <origin xyz="0.0 0.076867 -0.12355" rpy="-0.5236 -0.0 0.0"/>
        <axis xyz="0.0 1.0 0.0"/>
        <limit effort="366.05" velocity="6.4997" lower="-2.618" upper="2.618"/>
    </joint>
    <joint name="left_hip_roll_joint" type="revolute">
        <parent link="left_thigh_pitch_link"/>
        <child link="left_thigh_roll_link"/>
        <origin xyz="-0.062 0.0729 0.0" rpy="0.5236 -0.0 0.0"/>
        <axis xyz="1.0 0.0 0.0"/>
        <limit effort="127.296" velocity="12.362" lower="-0.59341" upper="1.5708"/>
    </joint>
    <joint name="left_hip_yaw_joint" type="revolute">
        <parent link="left_thigh_roll_link"/>
        <child link="left_thigh_yaw_link"/>
        <origin xyz="0.062 0.0 -0.03495" rpy="0.0 -0.0 0.0"/>
        <axis xyz="0.0 0.0 1.0"/>
        <limit effort="94.2" velocity="14.745" lower="-0.69813" upper="1.5708"/>
    </joint>
    <joint name="left_knee_pitch_joint" type="revolute">
        <parent link="left_thigh_yaw_link"/>
        <child link="left_shank_pitch_link"/>
        <origin xyz="0.0 0.0 -0.34305" rpy="0.0 -0.0 0.0"/>
        <axis xyz="0.0 1.0 0.0"/>
        <limit effort="366.05" velocity="6.4997" lower="-0.087266" upper="2.3562"/>
    </joint>
    <joint name="left_ankle_pitch_joint" type="revolute">
        <parent link="left_shank_pitch_link"/>
        <child link="left_foot_pitch_link"/>
        <origin xyz="0.0 0.0 -0.406" rpy="0.0 -0.0 0.0"/>
        <axis xyz="0.0 1.0 0.0"/>
        <limit effort="94.2" velocity="14.745" lower="-0.7854" upper="0.7854"/>
    </joint>
    <joint name="left_ankle_roll_joint" type="revolute">
        <parent link="left_foot_pitch_link"/>
        <child link="left_foot_roll_link"/>
        <origin xyz="0.0 0.0 0.0" rpy="0.0 -0.0 0.0"/>
        <axis xyz="1.0 0.0 0.0"/>
        <limit effort="29.835" velocity="16.755" lower="-0.38397" upper="0.38397"/>
    </joint>
    <joint name="right_hip_pitch_joint" type="revolute">
        <parent link="base_link"/>
        <child link="right_thigh_pitch_link"/>
        <origin xyz="0.0 -0.076867 -0.12355" rpy="0.5236 -0.0 0.0"/>
        <axis xyz="0.0 1.0 0.0"/>
        <limit effort="366.05" velocity="6.4997" lower="-2.618" upper="2.618"/>
    </joint>
    <joint name="right_hip_roll_joint" type="revolute">
        <parent link="right_thigh_pitch_link"/>
        <child link="right_thigh_roll_link"/>
        <origin xyz="-0.062 -0.0729 0.0" rpy="-0.5236 -0.0 0.0"/>
        <axis xyz="1.0 0.0 0.0"/>
        <limit effort="127.296" velocity="12.362" lower="-1.5708" upper="0.59341"/>
    </joint>
    <joint name="right_hip_yaw_joint" type="revolute">
        <parent link="right_thigh_roll_link"/>
        <child link="right_thigh_yaw_link"/>
        <origin xyz="0.062 0.0 -0.03495" rpy="0.0 -0.0 0.0"/>
        <axis xyz="0.0 0.0 1.0"/>
        <limit effort="94.2" velocity="14.745" lower="-1.5708" upper="0.69813"/>
    </joint>
    <joint name="right_knee_pitch_joint" type="revolute">
        <parent link="right_thigh_yaw_link"/>
        <child link="right_shank_pitch_link"/>
        <origin xyz="0.0 0.0 -0.34305" rpy="0.0 -0.0 0.0"/>
        <axis xyz="0.0 1.0 0.0"/>
        <limit effort="366.05" velocity="6.4997" lower="-0.087266" upper="2.3562"/>
    </joint>
    <joint name="right_ankle_pitch_joint" type="revolute">
        <parent link="right_shank_pitch_link"/>
        <child link="right_foot_pitch_link"/>
        <origin xyz="0.0 0.0 -0.406" rpy="0.0 -0.0 0.0"/>
        <axis xyz="0.0 1.0 0.0"/>
        <limit effort="94.2" velocity="14.745" lower="-0.7854" upper="0.7854"/>
    </joint>
    <joint name="right_ankle_roll_joint" type="revolute">
        <parent link="right_foot_pitch_link"/>
        <child link="right_foot_roll_link"/>
        <origin xyz="0.0 0.0 0.0" rpy="0.0 -0.0 0.0"/>
        <axis xyz="1.0 0.0 0.0"/>
        <limit effort="29.835" velocity="16.755" lower="-0.38397" upper="0.38397"/>
    </joint>
    <joint name="imu_joint" type="fixed">
        <parent link="base_link"/>
        <child link="imu_link"/>
        <origin xyz="-0.059 0.0 -0.068" rpy="0.0 -0.0 0.0"/>
        <axis xyz="0.0 0.0 0.0"/>
    </joint>
</robot>
