<?xml version="1.0" encoding="utf-8"?>


<!-- 10082024-1 -->

<robot
  name="fourier_right_hand">  
  <link
    name="r_hand_base_link">
    <inertial>
      <origin
        xyz="-0.0004953 0.0050417 -0.044939"
        rpy="0 0 0" />
      <mass
        value="0.09995" />
      <inertia
        ixx="3.010578E-4"
        ixy="3.497E-7"
        ixz="-6.915E-7"
        iyy="4.067957E-4"
        iyz="-3.17E-7"
        izz="1.921802E-4" />
    </inertial>
    <visual>
      <origin
        xyz="0 0 0"
        rpy="0 0 0" />
      <geometry>
        <mesh
          filename="../meshes/fourier_hand/r_hand_base_link.STL" />
      </geometry>
      <material
        name="">
        <color
          rgba="0.86667 0.86667 0.8902 1" />
      </material>
    </visual>
    <collision>
      <origin
        xyz="0 0 0"
        rpy="0 0 0" />
      <geometry>
        <mesh
          filename="../meshes/fourier_hand/r_hand_base_link.STL" />
      </geometry>
    </collision>
  </link>
  <!-- <joint
    name="r_hand_base_joint"
    type="fixed">
    <origin
      xyz="-0.0014094 0 -0.021"
      rpy="-6.835E-05 -0.0029196 0" />
    <parent
      link="right_end_effector_link" />
    <child
      link="r_hand_base_link" />
    <axis
      xyz="0 0 0" />
  </joint> -->
  <link
    name="R_thumb_proximal_base">
    <inertial>
      <origin
        xyz="0.011023 -3.3272E-05 -0.00074447"
        rpy="0 0 0" />
      <mass
        value="0.0094822" />
      <inertia
        ixx="2.987E-7"
        ixy="0"
        ixz="-3.95E-8"
        iyy="9.492E-7"
        iyz="0"
        izz="9.692E-7" />
    </inertial>
    <visual>
      <origin
        xyz="0 0 0"
        rpy="0 0 0" />
      <geometry>
        <mesh
          filename="../meshes/fourier_hand/R_thumb_proximal_base.STL" />
      </geometry>
      <material
        name="">
        <color
          rgba="0.8902 0.8902 0.91373 1" />
      </material>
    </visual>
    <collision>
      <origin
        xyz="0 0 0"
        rpy="0 0 0" />
      <geometry>
        <mesh
          filename="../meshes/fourier_hand/R_thumb_proximal_base.STL" />
      </geometry>
    </collision>
  </link>
  <joint
    name="R_thumb_proximal_yaw_joint"
    type="revolute">
    <origin
      xyz="0.021922 0.015502 -0.025153"
      rpy="3.1416 0 0" />
    <parent
      link="r_hand_base_link" />
    <child
      link="R_thumb_proximal_base" />
    <axis
      xyz="0 0 1" />
    <limit
      lower="-1.74"
      upper="0"
      effort="10"
      velocity="0.8" />
  </joint>
  <link
    name="R_thumb_proximal">
    <inertial>
      <origin
        xyz="0.031771 0.0011474 -2.2445E-05"
        rpy="0 0 0" />
      <mass
        value="0.033824" />
      <inertia
        ixx="1.13213E-5"
        ixy="2.56E-8"
        ixz="2.361E-7"
        iyy="3.41895E-5"
        iyz="1.04E-8"
        izz="3.2277E-5" />
    </inertial>
    <visual>
      <origin
        xyz="0 0 0"
        rpy="0 0 0" />
      <geometry>
        <mesh
          filename="../meshes/fourier_hand/R_thumb_proximal.STL" />
      </geometry>
      <material
        name="">
        <color
          rgba="0.86667 0.86667 0.8902 1" />
      </material>
    </visual>
    <collision>
      <origin
        xyz="0 0 0"
        rpy="0 0 0" />
      <geometry>
        <mesh
          filename="../meshes/fourier_hand/R_thumb_proximal.STL" />
      </geometry>
    </collision>
  </link>
  <joint
    name="R_thumb_proximal_pitch_joint"
    type="revolute">
    <origin
      xyz="0.02175 -1.722E-05 6.35E-05"
      rpy="1.5709 -0.0029195 -0.00079174" />
    <parent
      link="R_thumb_proximal_base" />
    <child
      link="R_thumb_proximal" />
    <axis
      xyz="0 0 1" />
    <limit
      lower="0"
      upper="1.22"
      effort="10"
      velocity="0.8" />
  </joint>
  <link
    name="R_thumb_distal">
    <inertial>
      <origin
        xyz="0.013742 -0.0027343 -5.1674E-07"
        rpy="0 0 0" />
      <mass
        value="0.019744" />
      <inertia
        ixx="8.966E-7"
        ixy="0"
        ixz="9.15E-8"
        iyy="2.1908E-6"
        iyz="0"
        izz="2.3291E-6" />
    </inertial>
    <visual>
      <origin
        xyz="0 0 0"
        rpy="0 0 0" />
      <geometry>
        <mesh
          filename="../meshes/fourier_hand/R_thumb_distal.STL" />
      </geometry>
      <material
        name="">
        <color
          rgba="0.86667 0.86667 0.8902 1" />
      </material>
    </visual>
    <collision>
      <origin
        xyz="0 0 0"
        rpy="0 0 0" />
      <geometry>
        <mesh
          filename="../meshes/fourier_hand/R_thumb_distal.STL" />
      </geometry>
    </collision>
  </link>
  <joint
    name="R_thumb_distal_joint"
    type="revolute">
    <origin
      xyz="0.061444 0.0082822 0"
      rpy="0 0 -0.0029196" />
    <parent
      link="R_thumb_proximal" />
    <child
      link="R_thumb_distal" />
    <axis
      xyz="0 0 1" />
    <limit
      lower="0"
      upper="1.04"
      effort="10"
      velocity="0.8" />
    <mimic
      joint="R_thumb_proximal_pitch_joint"
      multiplier="0.974"
      offset="0" />
  </joint>


  <link name="R_thumb_tip">
    <visual>
      <origin
        xyz="0 0 0"
        rpy="0 0 0" />
      <geometry>
        <sphere radius="0.005" />
      </geometry>
      <material name="yellow">
        <color rgba="0.9 1 0 1" />
      </material>
    </visual>
  </link>
  <joint name="R_thumb_tip_joint" type="fixed">
    <parent link="R_thumb_distal" />
    <child link="R_thumb_tip" />
    <origin rpy="0 0 0" xyz="0.031 0 0" />
  </joint>
  


  <link
    name="R_index_proximal">
    <inertial>
      <origin
        xyz="0.0095995 0.00044318 2.9627E-06"
        rpy="0 0 0" />
      <mass
        value="0.019118" />
      <inertia
        ixx="3.8425E-6"
        ixy="0"
        ixz="1.462E-7"
        iyy="3.7145E-6"
        iyz="1.232E-7"
        izz="8.708E-7" />
    </inertial>
    <visual>
      <origin
        xyz="0 0 0"
        rpy="0 0 0" />
      <geometry>
        <mesh
          filename="../meshes/fourier_hand/R_index_proximal.STL" />
      </geometry>
      <material
        name="">
        <color
          rgba="0.8902 0.8902 0.91373 1" />
      </material>
    </visual>
    <collision>
      <origin
        xyz="0 0 0"
        rpy="0 0 0" />
      <geometry>
        <mesh
          filename="../meshes/fourier_hand/R_index_proximal.STL" />
      </geometry>
    </collision>
  </link>
  <joint
    name="R_index_proximal_joint"
    type="revolute">
    <origin
      xyz="0.026583 0.012307 -0.096064"
      rpy="-3.1402 1.5214 0.0013813" />
    <parent
      link="r_hand_base_link" />
    <child
      link="R_index_proximal" />
    <axis
      xyz="0 0 1" />
    <limit
      lower="-1.57"
      upper="0"
      effort="10"
      velocity="0.8" />
  </joint>
  <link
    name="R_index_intermediate">
    <inertial>
      <origin
        xyz="0.018004 0.0029995 -8.9222E-06"
        rpy="0 0 0" />
      <mass
        value="0.012927" />
      <inertia
        ixx="2.0343E-6"
        ixy="-1.25E-8"
        ixz="8.29E-8"
        iyy="2.0059E-6"
        iyz="2.518E-7"
        izz="3.763E-7" />
    </inertial>
    <visual>
      <origin
        xyz="0 0 0"
        rpy="0 0 0" />
      <geometry>
        <mesh
          filename="../meshes/fourier_hand/R_index_intermediate.STL" />
      </geometry>
      <material
        name="">
        <color
          rgba="0.79216 0.81961 0.93333 1" />
      </material>
    </visual>
    <collision>
      <origin
        xyz="0 0 0"
        rpy="0 0 0" />
      <geometry>
        <mesh
          filename="../meshes/fourier_hand/R_index_intermediate.STL" />
      </geometry>
    </collision>
  </link>
  <joint
    name="R_index_intermediate_joint"
    type="revolute">
    <origin
      xyz="0.031532 -0.0054551 0"
      rpy="0 0 0" />
    <parent
      link="R_index_proximal" />
    <child
      link="R_index_intermediate" />
    <axis
      xyz="0 0 1" />
    <limit
      lower="-1.74"
      upper="0"
      effort="10"
      velocity="0.8" />
    <mimic
      joint="R_index_proximal_joint"
      multiplier="1.128"
      offset="0" />
  </joint>



  <link name="R_index_tip">
    <visual>
      <origin
        xyz="0 0 0"
        rpy="0 0 0" />
      <geometry>
        <sphere radius="0.005" />
      </geometry>
      <material name="yellow">
        <color rgba="0.9 1 0 1" />
      </material>
    </visual>
  </link>
  <joint name="R_index_tip_joint" type="fixed">
    <parent link="R_index_intermediate" />
    <child link="R_index_tip" />
    <origin rpy="0 0 0" xyz="0.038 -0.0015 0" />
  </joint>



  <link
    name="R_middle_proximal">
    <inertial>
      <origin
        xyz="0.0095562 0.000719 3.0016E-06"
        rpy="0 0 0" />
      <mass
        value="0.019118" />
      <inertia
        ixx="3.8487E-6"
        ixy="0"
        ixz="0"
        iyy="3.7212E-6"
        iyz="6.11E-8"
        izz="8.56E-7" />
    </inertial>
    <visual>
      <origin
        xyz="0 0 0"
        rpy="0 0 0" />
      <geometry>
        <mesh
          filename="../meshes/fourier_hand/R_middle_proximal.STL" />
      </geometry>
      <material
        name="">
        <color
          rgba="0.8902 0.8902 0.91373 1" />
      </material>
    </visual>
    <collision>
      <origin
        xyz="0 0 0"
        rpy="0 0 0" />
      <geometry>
        <mesh
          filename="../meshes/fourier_hand/R_middle_proximal.STL" />
      </geometry>
    </collision>
  </link>
  <joint
    name="R_middle_proximal_joint"
    type="revolute">
    <origin
      xyz="0.0082089 0.012307 -0.098014"
      rpy="-0.023406 1.5679 3.1182" />
    <parent
      link="r_hand_base_link" />
    <child
      link="R_middle_proximal" />
    <axis
      xyz="0 0 1" />
    <limit
      lower="-1.57"
      upper="0"
      effort="10"
      velocity="0.8" />
  </joint>
  <link
    name="R_middle_intermediate">
    <inertial>
      <origin
        xyz="0.021282 0.0040829 -9.9882E-06"
        rpy="0 0 0" />
      <mass
        value="0.015352" />
      <inertia
        ixx="3.2904E-6"
        ixy="0"
        ixz="0"
        iyy="3.2834E-6"
        iyz="2.227E-7"
        izz="4.144E-7" />
    </inertial>
    <visual>
      <origin
        xyz="0 0 0"
        rpy="0 0 0" />
      <geometry>
        <mesh
          filename="../meshes/fourier_hand/R_middle_intermediate.STL" />
      </geometry>
      <material
        name="">
        <color
          rgba="0.86667 0.86667 0.8902 1" />
      </material>
    </visual>
    <collision>
      <origin
        xyz="0 0 0"
        rpy="0 0 0" />
      <geometry>
        <mesh
          filename="../meshes/fourier_hand/R_middle_intermediate.STL" />
      </geometry>
    </collision>
  </link>
  <joint
    name="R_middle_intermediate_joint"
    type="revolute">
    <origin
      xyz="0.031662 -0.0046408 0"
      rpy="0 0 0" />
    <parent
      link="R_middle_proximal" />
    <child
      link="R_middle_intermediate" />
    <axis
      xyz="0 0 1" />
    <limit
      lower="-1.74"
      upper="0"
      effort="10"
      velocity="0.8" />
    <mimic
      joint="R_middle_proximal_joint"
      multiplier="1.131"
      offset="0" />
  </joint>


  <link name="R_middle_tip">
    <visual>
      <origin
        xyz="0 0 0"
        rpy="0 0 0" />
      <geometry>
        <sphere radius="0.005" />
      </geometry>
      <material name="yellow">
        <color rgba="0.9 1 0 1" />
      </material>
    </visual>
  </link>
  <joint name="R_middle_tip_joint" type="fixed">
    <parent link="R_middle_intermediate" />
    <child link="R_middle_tip" />
    <origin rpy="0 0 0" xyz="0.045 0.0005 0" />
  </joint>



  <link
    name="R_ring_proximal">
    <inertial>
      <origin
        xyz="0.0095993 0.00044271 2.9621E-06"
        rpy="0 0 0" />
      <mass
        value="0.019117" />
      <inertia
        ixx="3.8404E-6"
        ixy="0"
        ixz="-1.659E-7"
        iyy="3.7145E-6"
        iyz="1.232E-7"
        izz="8.729E-7" />
    </inertial>
    <visual>
      <origin
        xyz="0 0 0"
        rpy="0 0 0" />
      <geometry>
        <mesh
          filename="../meshes/fourier_hand/R_ring_proximal.STL" />
      </geometry>
      <material
        name="">
        <color
          rgba="0.8902 0.8902 0.91373 1" />
      </material>
    </visual>
    <collision>
      <origin
        xyz="0 0 0"
        rpy="0 0 0" />
      <geometry>
        <mesh
          filename="../meshes/fourier_hand/R_ring_proximal.STL" />
      </geometry>
    </collision>
  </link>
  <joint
    name="R_ring_proximal_joint"
    type="revolute">
    <origin
      xyz="-0.010252 0.012307 -0.097905"
      rpy="0 1.5155 3.1416" />
    <parent
      link="r_hand_base_link" />
    <child
      link="R_ring_proximal" />
    <axis
      xyz="0 0 1" />
    <limit
      lower="-1.57"
      upper="0"
      effort="10"
      velocity="0.8" />
  </joint>
  <link
    name="R_ring_intermediate">
    <inertial>
      <origin
        xyz="0.018005 0.0029979 -9.3052E-06"
        rpy="0 0 0" />
      <mass
        value="0.012925" />
      <inertia
        ixx="2.0334E-6"
        ixy="1.39E-8"
        ixz="-9.13E-8"
        iyy="2.0059E-6"
        iyz="2.517E-7"
        izz="3.772E-7" />
    </inertial>
    <visual>
      <origin
        xyz="0 0 0"
        rpy="0 0 0" />
      <geometry>
        <mesh
          filename="../meshes/fourier_hand/R_ring_intermediate.STL" />
      </geometry>
      <material
        name="">
        <color
          rgba="0.29804 0.29804 0.29804 1" />
      </material>
    </visual>
    <collision>
      <origin
        xyz="0 0 0"
        rpy="0 0 0" />
      <geometry>
        <mesh
          filename="../meshes/fourier_hand/R_ring_intermediate.STL" />
      </geometry>
    </collision>
  </link>
  <joint
    name="R_ring_intermediate_joint"
    type="revolute">
    <origin
      xyz="0.031531 -0.0054572 0"
      rpy="0 0 0" />
    <parent
      link="R_ring_proximal" />
    <child
      link="R_ring_intermediate" />
    <axis
      xyz="0 0 1" />
    <limit
      lower="-1.74"
      upper="0"
      effort="10"
      velocity="0.8" />
    <mimic
      joint="R_ring_proximal_joint"
      multiplier="1.143"
      offset="0" />
  </joint>


  <link name="R_ring_tip">
    <visual>
      <origin
        xyz="0 0 0"
        rpy="0 0 0" />
      <geometry>
        <sphere radius="0.005" />
      </geometry>
      <material name="green">
        <color rgba="0.9 1 0 1" />
      </material>
    </visual>
  </link>
  <joint name="R_ring_tip_joint" type="fixed">
    <parent link="R_ring_intermediate" />
    <child link="R_ring_tip" />
    <origin rpy="0 0 0" xyz="0.038 -0.0015 0" />
  </joint>



  <link
    name="R_pinky_proximal">
    <inertial>
      <origin
        xyz="0.0096436 9.4084E-05 2.9778E-06"
        rpy="0 0 0" />
      <mass
        value="0.019117" />
      <inertia
        ixx="3.816E-6"
        ixy="2.13E-8"
        ixz="-3.187E-7"
        iyy="3.7016E-6"
        iyz="2.002E-7"
        izz="9.119E-7" />
    </inertial>
    <visual>
      <origin
        xyz="0 0 0"
        rpy="0 0 0" />
      <geometry>
        <mesh
          filename="../meshes/fourier_hand/R_pinky_proximal.STL" />
      </geometry>
      <material
        name="">
        <color
          rgba="0.8902 0.8902 0.91373 1" />
      </material>
    </visual>
    <collision>
      <origin
        xyz="0 0 0"
        rpy="0 0 0" />
      <geometry>
        <mesh
          filename="../meshes/fourier_hand/R_pinky_proximal.STL" />
      </geometry>
    </collision>
  </link>
  <joint
    name="R_pinky_proximal_joint"
    type="revolute">
    <origin
      xyz="-0.028513 0.012307 -0.095926"
      rpy="-0.00063622 1.4632 3.141" />
    <parent
      link="r_hand_base_link" />
    <child
      link="R_pinky_proximal" />
    <axis
      xyz="0 0 1" />
    <limit
      lower="-1.57"
      upper="0"
      effort="10"
      velocity="0.8" />
  </joint>
  <link
    name="R_pinky_intermediate">
    <inertial>
      <origin
        xyz="0.016096 0.001186 -8.5372E-06"
        rpy="0 0 0" />
      <mass
        value="0.0056869" />
      <inertia
        ixx="6.595E-7"
        ixy="1.42E-8"
        ixz="-5.24E-8"
        iyy="6.243E-7"
        iyz="1.313E-7"
        izz="1.785E-7" />
    </inertial>
    <visual>
      <origin
        xyz="0 0 0"
        rpy="0 0 0" />
      <geometry>
        <mesh
          filename="../meshes/fourier_hand/R_pinky_intermediate.STL" />
      </geometry>
      <material
        name="">
        <color
          rgba="0.79216 0.81961 0.93333 1" />
      </material>
    </visual>
    <collision>
      <origin
        xyz="0 0 0"
        rpy="0 0 0" />
      <geometry>
        <mesh
          filename="../meshes/fourier_hand/R_pinky_intermediate.STL" />
      </geometry>
    </collision>
  </link>
  <joint
    name="R_pinky_intermediate_joint"
    type="revolute">
    <origin
      xyz="0.031338 -0.0064763 0"
      rpy="0 0 6.7954E-05" />
    <parent
      link="R_pinky_proximal" />
    <child
      link="R_pinky_intermediate" />
    <axis
      xyz="0 0 1" />
    <limit
      lower="-1.74"
      upper="0"
      effort="10"
      velocity="0.8" />
    <mimic
      joint="R_pinky_proximal_joint"
      multiplier="1.129"
      offset="0" />
  </joint>


  <link name="R_pinky_tip">
    <visual>
      <origin
        xyz="0 0 0"
        rpy="0 0 0" />
      <geometry>
        <sphere radius="0.005" />
      </geometry>
      <material name="yellow">
        <color rgba="0.9 1 0 1" />
      </material>
    </visual>
  </link>
  <joint name="R_pinky_tip_joint" type="fixed">
    <parent link="R_pinky_intermediate" />
    <child link="R_pinky_tip" />
    <origin rpy="0 0 0" xyz="0.031 -0.004 0" />
  </joint>



</robot>