<?xml version="1.0" encoding="utf-8"?>


<!-- 10082024-1 -->

<robot
  name="fourier_hand">  
  <link
    name="l_hand_base_link">
    <inertial>
      <origin
        xyz="-0.00034718 -0.0050378 -0.044954"
        rpy="0 0 0" />
      <mass
        value="0.09995" />
      <inertia
        ixx="3.011304E-4"
        ixy="-3.603E-7"
        ixz="-2.435E-7"
        iyy="4.068824E-4"
        iyz="3.694E-7"
        izz="1.921823E-4" />
    </inertial>
    <visual>
      <origin
        xyz="0 0 0"
        rpy="0 0 0" />
      <geometry>
        <mesh
          filename="../meshes/fourier_hand/l_hand_base_link.STL" />
      </geometry>
      <material
        name="">
        <color
          rgba="0.86667 0.86667 0.8902 1" />
      </material>
    </visual>
    <collision>
      <origin
        xyz="0 0 0"
        rpy="0 0 0" />
      <geometry>
        <mesh
          filename="../meshes/fourier_hand/l_hand_base_link.STL" />
      </geometry>
    </collision>
  </link>
  <!-- <joint
    name="l_hand_base_joint"
    type="fixed">
    <origin
      xyz="-0.0014375 -5.9402E-05 -0.021"
      rpy="0 0 0" />
    <parent
      link="left_end_effector_link" />
    <child
      link="l_hand_base_link" />
    <axis
      xyz="0 0 0" />
  </joint> -->
  <link
    name="L_thumb_proximal_base">
    <inertial>
      <origin
        xyz="0.011017 -2.4767E-05 0.00077605"
        rpy="0 0 0" />
      <mass
        value="0.0094853" />
      <inertia
        ixx="2.99E-7"
        ixy="0"
        ixz="-4.15E-8"
        iyy="9.499E-7"
        iyz="0"
        izz="9.696E-7" />
    </inertial>
    <visual>
      <origin
        xyz="0 0 0"
        rpy="0 0 0" />
      <geometry>
        <mesh
          filename="../meshes/fourier_hand/L_thumb_proximal_base.STL" />
      </geometry>
      <material
        name="">
        <color
          rgba="0.8902 0.8902 0.91373 1" />
      </material>
    </visual>
    <collision>
      <origin
        xyz="0 0 0"
        rpy="0 0 0" />
      <geometry>
        <mesh
          filename="../meshes/fourier_hand/L_thumb_proximal_base.STL" />
      </geometry>
    </collision>
  </link>
  <joint
    name="L_thumb_proximal_yaw_joint"
    type="revolute">
    <origin
      xyz="0.022 -0.015498 -0.025093"
      rpy="0 -1.2211E-05 0" />
    <parent
      link="l_hand_base_link" />
    <child
      link="L_thumb_proximal_base" />
    <axis
      xyz="0 0 1" />
    <limit
      lower="-1.74"
      upper="0"
      effort="10"
      velocity="0.8" />
  </joint>
  <link
    name="L_thumb_proximal">
    <inertial>
      <origin
        xyz="0.031275 0.00074132 -2.2831E-05"
        rpy="0 0 0" />
      <mass
        value="0.033247" />
      <inertia
        ixx="1.13073E-5"
        ixy="4.41E-8"
        ixz="-1.016E-7"
        iyy="3.3755E-5"
        iyz="1.1E-8"
        izz="3.18346E-5" />
    </inertial>
    <visual>
      <origin
        xyz="0 0 0"
        rpy="0 0 0" />
      <geometry>
        <mesh
          filename="../meshes/fourier_hand/L_thumb_proximal.STL" />
      </geometry>
      <material
        name="">
        <color
          rgba="0.86667 0.86667 0.8902 1" />
      </material>
    </visual>
    <collision>
      <origin
        xyz="0 0 0"
        rpy="0 0 0" />
      <geometry>
        <mesh
          filename="../meshes/fourier_hand/L_thumb_proximal.STL" />
      </geometry>
    </collision>
  </link>
  <joint
    name="L_thumb_proximal_pitch_joint"
    type="revolute">
    <origin
      xyz="0.02175 0 0"
      rpy="-1.5707 0 0" />
    <parent
      link="L_thumb_proximal_base" />
    <child
      link="L_thumb_proximal" />
    <axis
      xyz="0 0 1" />
    <limit
      lower="0"
      upper="1.22"
      effort="10"
      velocity="0.8" />
  </joint>
  <link
    name="L_thumb_distal">
    <inertial>
      <origin
        xyz="0.013217 -0.0032618 -5.265E-07"
        rpy="0 0 0" />
      <mass
        value="0.020321" />
      <inertia
        ixx="9.159E-7"
        ixy="0"
        ixz="9.04E-8"
        iyy="2.3382E-6"
        iyz="0"
        izz="2.4793E-6" />
    </inertial>
    <visual>
      <origin
        xyz="0 0 0"
        rpy="0 0 0" />
      <geometry>
        <mesh
          filename="../meshes/fourier_hand/L_thumb_distal.STL" />
      </geometry>
      <material
        name="">
        <color
          rgba="0.79216 0.81961 0.93333 1" />
      </material>
    </visual>
    <collision>
      <origin
        xyz="0 0 0"
        rpy="0 0 0" />
      <geometry>
        <mesh
          filename="../meshes/fourier_hand/L_thumb_distal.STL" />
      </geometry>
    </collision>
  </link>
  <joint
    name="L_thumb_distal_joint"
    type="revolute">
    <origin
      xyz="0.061549 0.0074616 0"
      rpy="0 0 1.221E-05" />
    <parent
      link="L_thumb_proximal" />
    <child
      link="L_thumb_distal" />
    <axis
      xyz="0 0 1" />
    <limit
      lower="0"
      upper="1.04"
      effort="10"
      velocity="0.8" />
    <mimic
      joint="L_thumb_proximal_pitch_joint"
      multiplier="0.974"
      offset="0" />
  </joint>


  <link name="L_thumb_tip">
    <visual>
      <origin
        xyz="0 0 0"
        rpy="0 0 0" />
      <geometry>
        <sphere radius="0.005" />
      </geometry>
      <material name="yellow">
        <color rgba="0.9 1 0 1" />
      </material>
    </visual>
  </link>
  <joint name="L_thumb_tip_joint" type="fixed">
    <parent link="L_thumb_distal" />
    <child link="L_thumb_tip" />
    <origin rpy="0 0 0" xyz="0.031 0 0" />
  </joint>



  <link
    name="L_index_proximal">
    <inertial>
      <origin
        xyz="0.0095993 0.00044337 2.962E-06"
        rpy="0 0 0" />
      <mass
        value="0.019117" />
      <inertia
        ixx="3.8413E-6"
        ixy="0"
        ixz="1.572E-7"
        iyy="3.7145E-6"
        iyz="-1.228E-7"
        izz="8.719E-7" />
    </inertial>
    <visual>
      <origin
        xyz="0 0 0"
        rpy="0 0 0" />
      <geometry>
        <mesh
          filename="../meshes/fourier_hand/L_index_proximal.STL" />
      </geometry>
      <material
        name="">
        <color
          rgba="0.86667 0.86667 0.8902 1" />
      </material>
    </visual>
    <collision>
      <origin
        xyz="0 0 0"
        rpy="0 0 0" />
      <geometry>
        <mesh
          filename="../meshes/fourier_hand/L_index_proximal.STL" />
      </geometry>
    </collision>
  </link>
  <joint
    name="L_index_proximal_joint"
    type="revolute">
    <origin
      xyz="0.026869 -0.012293 -0.095989"
      rpy="0.0013057 1.5184 0.0013039" />
    <parent
      link="l_hand_base_link" />
    <child
      link="L_index_proximal" />
    <axis
      xyz="0 0 1" />
    <limit
      lower="-1.57"
      upper="0"
      effort="10"
      velocity="0.8" />
  </joint>
  <link
    name="L_index_intermediate">
    <inertial>
      <origin
        xyz="0.018004 0.0030004 -9.3048E-06"
        rpy="0 0 0" />
      <mass
        value="0.012925" />
      <inertia
        ixx="2.034E-6"
        ixy="1.31E-8"
        ixz="8.65E-8"
        iyy="2.006E-6"
        iyz="-2.515E-7"
        izz="3.766E-7" />
    </inertial>
    <visual>
      <origin
        xyz="0 0 0"
        rpy="0 0 0" />
      <geometry>
        <mesh
          filename="../meshes/fourier_hand/L_index_intermediate.STL" />
      </geometry>
      <material
        name="">
        <color
          rgba="0.79216 0.81961 0.93333 1" />
      </material>
    </visual>
    <collision>
      <origin
        xyz="0 0 0"
        rpy="0 0 0" />
      <geometry>
        <mesh
          filename="../meshes/fourier_hand/L_index_intermediate.STL" />
      </geometry>
    </collision>
  </link>
  <joint
    name="L_index_intermediate_joint"
    type="revolute">
    <origin
      xyz="0.031532 -0.0054551 0"
      rpy="0 0 -6.8255E-05" />
    <parent
      link="L_index_proximal" />
    <child
      link="L_index_intermediate" />
    <axis
      xyz="0 0 1" />
    <limit
      lower="-1.74"
      upper="0"
      effort="10"
      velocity="0.8" />
    <mimic
      joint="L_index_proximal_joint"
      multiplier="1.128"
      offset="0" />
  </joint>

  <link name="L_index_tip">
    <visual>
      <origin
        xyz="0 0 0"
        rpy="0 0 0" />
      <geometry>
        <sphere radius="0.005" />
      </geometry>
      <material name="yellow">
        <color rgba="0.9 1 0 1" />
      </material>
    </visual>
  </link>
  <joint name="L_index_tip_joint" type="fixed">
    <parent link="L_index_intermediate" />
    <child link="L_index_tip" />
    <origin rpy="0 0 0" xyz="0.038 -0.001 0" />
  </joint>


  <link
    name="L_middle_proximal">
    <inertial>
      <origin
        xyz="0.0095565 0.00071875 2.9504E-06"
        rpy="0 0 0" />
      <mass
        value="0.019118" />
      <inertia
        ixx="3.8487E-6"
        ixy="0"
        ixz="0"
        iyy="3.7212E-6"
        iyz="-6.07E-8"
        izz="8.559E-7" />
    </inertial>
    <visual>
      <origin
        xyz="0 0 0"
        rpy="0 0 0" />
      <geometry>
        <mesh
          filename="../meshes/fourier_hand/L_middle_proximal.STL" />
      </geometry>
      <material
        name="">
        <color
          rgba="0.8902 0.8902 0.91373 1" />
      </material>
    </visual>
    <collision>
      <origin
        xyz="0 0 0"
        rpy="0 0 0" />
      <geometry>
        <mesh
          filename="../meshes/fourier_hand/L_middle_proximal.STL" />
      </geometry>
    </collision>
  </link>
  <joint
    name="L_middle_proximal_joint"
    type="revolute">
    <origin
      xyz="0.0085012 -0.012293 -0.097993"
      rpy="1.394 1.5707 1.394" />
    <parent
      link="l_hand_base_link" />
    <child
      link="L_middle_proximal" />
    <axis
      xyz="0 0 1" />
    <limit
      lower="-1.57"
      upper="0"
      effort="10"
      velocity="0.8" />
  </joint>
  <link
    name="L_middle_intermediate">
    <inertial>
      <origin
        xyz="0.021282 0.0040844 -9.9839E-06"
        rpy="0 0 0" />
      <mass
        value="0.015352" />
      <inertia
        ixx="3.2904E-6"
        ixy="0"
        ixz="0"
        iyy="3.2835E-6"
        iyz="-2.223E-7"
        izz="4.143E-7" />
    </inertial>
    <visual>
      <origin
        xyz="0 0 0"
        rpy="0 0 0" />
      <geometry>
        <mesh
          filename="../meshes/fourier_hand/L_middle_intermediate.STL" />
      </geometry>
      <material
        name="">
        <color
          rgba="0.79216 0.81961 0.93333 1" />
      </material>
    </visual>
    <collision>
      <origin
        xyz="0 0 0"
        rpy="0 0 0" />
      <geometry>
        <mesh
          filename="../meshes/fourier_hand/L_middle_intermediate.STL" />
      </geometry>
    </collision>
  </link>
  <joint
    name="L_middle_intermediate_joint"
    type="revolute">
    <origin
      xyz="0.031662 -0.0046408 0"
      rpy="0 0 -6.8349E-05" />
    <parent
      link="L_middle_proximal" />
    <child
      link="L_middle_intermediate" />
    <axis
      xyz="0 0 1" />
    <limit
      lower="-1.74"
      upper="0"
      effort="10"
      velocity="0.8" />
    <mimic
      joint="L_middle_proximal_joint"
      multiplier="1.131"
      offset="0" />
  </joint>


  <link name="L_middle_tip">
    <visual>
      <origin
        xyz="0 0 0"
        rpy="0 0 0" />
      <geometry>
        <sphere radius="0.005" />
      </geometry>
      <material name="yellow">
        <color rgba="0.9 1 0 1" />
      </material>
    </visual>
  </link>
  <joint name="L_middle_tip_joint" type="fixed">
    <parent link="L_middle_intermediate" />
    <child link="L_middle_tip" />
    <origin rpy="0 0 0" xyz="0.045 0.0005 0" />
  </joint>


  <link
    name="L_ring_proximal">
    <inertial>
      <origin
        xyz="0.0095995 0.00044318 2.9626E-06"
        rpy="0 0 0" />
      <mass
        value="0.019118" />
      <inertia
        ixx="3.8416E-6"
        ixy="0"
        ixz="-1.549E-7"
        iyy="3.7145E-6"
        iyz="-1.228E-7"
        izz="8.716E-7" />
    </inertial>
    <visual>
      <origin
        xyz="0 0 0"
        rpy="0 0 0" />
      <geometry>
        <mesh
          filename="../meshes/fourier_hand/L_ring_proximal.STL" />
      </geometry>
      <material
        name="">
        <color
          rgba="0.8902 0.8902 0.91373 1" />
      </material>
    </visual>
    <collision>
      <origin
        xyz="0 0 0"
        rpy="0 0 0" />
      <geometry>
        <mesh
          filename="../meshes/fourier_hand/L_ring_proximal.STL" />
      </geometry>
    </collision>
  </link>
  <joint
    name="L_ring_proximal_joint"
    type="revolute">
    <origin
      xyz="-0.00996 -0.012293 -0.097938"
      rpy="3.1403 1.5184 3.1403" />
    <parent
      link="l_hand_base_link" />
    <child
      link="L_ring_proximal" />
    <axis
      xyz="0 0 1" />
    <limit
      lower="-1.57"
      upper="0"
      effort="10"
      velocity="0.8" />
  </joint>
  <link
    name="L_ring_intermediate">
    <inertial>
      <origin
        xyz="0.018004 0.0030008 -8.9222E-06"
        rpy="0 0 0" />
      <mass
        value="0.012927" />
      <inertia
        ixx="2.0338E-6"
        ixy="-1.32E-8"
        ixz="-8.77E-8"
        iyy="2.006E-6"
        iyz="-2.515E-7"
        izz="3.767E-7" />
    </inertial>
    <visual>
      <origin
        xyz="0 0 0"
        rpy="0 0 0" />
      <geometry>
        <mesh
          filename="../meshes/fourier_hand/L_ring_intermediate.STL" />
      </geometry>
      <material
        name="">
        <color
          rgba="0.79216 0.81961 0.93333 1" />
      </material>
    </visual>
    <collision>
      <origin
        xyz="0 0 0"
        rpy="0 0 0" />
      <geometry>
        <mesh
          filename="../meshes/fourier_hand/L_ring_intermediate.STL" />
      </geometry>
    </collision>
  </link>
  <joint
    name="L_ring_intermediate_joint"
    type="revolute">
    <origin
      xyz="0.031532 -0.0054551 0"
      rpy="0 0 -6.8255E-05" />
    <parent
      link="L_ring_proximal" />
    <child
      link="L_ring_intermediate" />
    <axis
      xyz="0 0 1" />
    <limit
      lower="-1.74"
      upper="0"
      effort="10"
      velocity="0.8" />
    <mimic
      joint="L_ring_proximal_joint"
      multiplier="1.143"
      offset="0" />
  </joint>


  <link name="L_ring_tip">
    <visual>
      <origin
        xyz="0 0 0"
        rpy="0 0 0" />
      <geometry>
        <sphere radius="0.005" />
      </geometry>
      <material name="green">
        <color rgba="0.9 1 0 1" />
      </material>
    </visual>
  </link>
  <joint name="L_ring_tip_joint" type="fixed">
    <parent link="L_ring_intermediate" />
    <child link="L_ring_tip" />
    <origin rpy="0 0 0" xyz="0.038 -0.002 0" />
  </joint>


  <link
    name="L_pinky_proximal">
    <inertial>
      <origin
        xyz="0.009644 9.3815E-05 3.001E-06"
        rpy="0 0 0" />
      <mass
        value="0.019118" />
      <inertia
        ixx="3.8183E-6"
        ixy="-2.13E-8"
        ixz="-3.079E-7"
        iyy="3.7017E-6"
        iyz="-1.998E-7"
        izz="9.096E-7" />
    </inertial>
    <visual>
      <origin
        xyz="0 0 0"
        rpy="0 0 0" />
      <geometry>
        <mesh
          filename="../meshes/fourier_hand/L_pinky_proximal.STL" />
      </geometry>
      <material
        name="">
        <color
          rgba="0.8902 0.8902 0.91373 1" />
      </material>
    </visual>
    <collision>
      <origin
        xyz="0 0 0"
        rpy="0 0 0" />
      <geometry>
        <mesh
          filename="../meshes/fourier_hand/L_pinky_proximal.STL" />
      </geometry>
    </collision>
  </link>
  <joint
    name="L_pinky_proximal_joint"
    type="revolute">
    <origin
      xyz="-0.028227 -0.012293 -0.096013"
      rpy="3.1409 1.4661 3.1409" />
    <parent
      link="l_hand_base_link" />
    <child
      link="L_pinky_proximal" />
    <axis
      xyz="0 0 1" />
    <limit
      lower="-1.57"
      upper="0"
      effort="10"
      velocity="0.8" />
  </joint>
  <link
    name="L_pinky_intermediate">
    <inertial>
      <origin
        xyz="0.016096 0.0011882 -8.4063E-06"
        rpy="0 0 0" />
      <mass
        value="0.0056869" />
      <inertia
        ixx="6.597E-7"
        ixy="-1.38E-8"
        ixz="-5.14E-8"
        iyy="6.243E-7"
        iyz="-1.313E-7"
        izz="1.782E-7" />
    </inertial>
    <visual>
      <origin
        xyz="0 0 0"
        rpy="0 0 0" />
      <geometry>
        <mesh
          filename="../meshes/fourier_hand/L_pinky_intermediate.STL" />
      </geometry>
      <material
        name="">
        <color
          rgba="0.79216 0.81961 0.93333 1" />
      </material>
    </visual>
    <collision>
      <origin
        xyz="0 0 0"
        rpy="0 0 0" />
      <geometry>
        <mesh
          filename="../meshes/fourier_hand/L_pinky_intermediate.STL" />
      </geometry>
    </collision>
  </link>
  <joint
    name="L_pinky_intermediate_joint"
    type="revolute">
    <origin
      xyz="0.031338 -0.0064763 0"
      rpy="0 0 -6.7975E-05" />
    <parent
      link="L_pinky_proximal" />
    <child
      link="L_pinky_intermediate" />
    <axis
      xyz="0 0 1" />
    <limit
      lower="-1.74"
      upper="0"
      effort="10"
      velocity="0.8" />
    <mimic
      joint="L_pinky_proximal_joint"
      multiplier="1.129"
      offset="0" />
  </joint>


  <link name="L_pinky_tip">
    <visual>
      <origin
        xyz="0 0 0"
        rpy="0 0 0" />
      <geometry>
        <sphere radius="0.005" />
      </geometry>
      <material name="yellow">
        <color rgba="0.9 1 0 1" />
      </material>
    </visual>
  </link>
  <joint name="L_pinky_tip_joint" type="fixed">
    <parent link="L_pinky_intermediate" />
    <child link="L_pinky_tip" />
    <origin rpy="0 0 0" xyz="0.031 -0.0045 0" />
  </joint>







  <link
    name="r_hand_base_link">
    <inertial>
      <origin
        xyz="-0.0004953 0.0050417 -0.044939"
        rpy="0 0 0" />
      <mass
        value="0.09995" />
      <inertia
        ixx="3.010578E-4"
        ixy="3.497E-7"
        ixz="-6.915E-7"
        iyy="4.067957E-4"
        iyz="-3.17E-7"
        izz="1.921802E-4" />
    </inertial>
    <visual>
      <origin
        xyz="0 0 0"
        rpy="0 0 0" />
      <geometry>
        <mesh
          filename="../meshes/fourier_hand/r_hand_base_link.STL" />
      </geometry>
      <material
        name="">
        <color
          rgba="0.86667 0.86667 0.8902 1" />
      </material>
    </visual>
    <collision>
      <origin
        xyz="0 0 0"
        rpy="0 0 0" />
      <geometry>
        <mesh
          filename="../meshes/fourier_hand/r_hand_base_link.STL" />
      </geometry>
    </collision>
  </link>
  <!-- <joint
    name="r_hand_base_joint"
    type="fixed">
    <origin
      xyz="-0.0014094 0 -0.021"
      rpy="-6.835E-05 -0.0029196 0" />
    <parent
      link="right_end_effector_link" />
    <child
      link="r_hand_base_link" />
    <axis
      xyz="0 0 0" />
  </joint> -->
  <link
    name="R_thumb_proximal_base">
    <inertial>
      <origin
        xyz="0.011023 -3.3272E-05 -0.00074447"
        rpy="0 0 0" />
      <mass
        value="0.0094822" />
      <inertia
        ixx="2.987E-7"
        ixy="0"
        ixz="-3.95E-8"
        iyy="9.492E-7"
        iyz="0"
        izz="9.692E-7" />
    </inertial>
    <visual>
      <origin
        xyz="0 0 0"
        rpy="0 0 0" />
      <geometry>
        <mesh
          filename="../meshes/fourier_hand/R_thumb_proximal_base.STL" />
      </geometry>
      <material
        name="">
        <color
          rgba="0.8902 0.8902 0.91373 1" />
      </material>
    </visual>
    <collision>
      <origin
        xyz="0 0 0"
        rpy="0 0 0" />
      <geometry>
        <mesh
          filename="../meshes/fourier_hand/R_thumb_proximal_base.STL" />
      </geometry>
    </collision>
  </link>
  <joint
    name="R_thumb_proximal_yaw_joint"
    type="revolute">
    <origin
      xyz="0.021922 0.015502 -0.025153"
      rpy="3.1416 0 0" />
    <parent
      link="r_hand_base_link" />
    <child
      link="R_thumb_proximal_base" />
    <axis
      xyz="0 0 1" />
    <limit
      lower="-1.74"
      upper="0"
      effort="10"
      velocity="0.8" />
  </joint>
  <link
    name="R_thumb_proximal">
    <inertial>
      <origin
        xyz="0.031771 0.0011474 -2.2445E-05"
        rpy="0 0 0" />
      <mass
        value="0.033824" />
      <inertia
        ixx="1.13213E-5"
        ixy="2.56E-8"
        ixz="2.361E-7"
        iyy="3.41895E-5"
        iyz="1.04E-8"
        izz="3.2277E-5" />
    </inertial>
    <visual>
      <origin
        xyz="0 0 0"
        rpy="0 0 0" />
      <geometry>
        <mesh
          filename="../meshes/fourier_hand/R_thumb_proximal.STL" />
      </geometry>
      <material
        name="">
        <color
          rgba="0.86667 0.86667 0.8902 1" />
      </material>
    </visual>
    <collision>
      <origin
        xyz="0 0 0"
        rpy="0 0 0" />
      <geometry>
        <mesh
          filename="../meshes/fourier_hand/R_thumb_proximal.STL" />
      </geometry>
    </collision>
  </link>
  <joint
    name="R_thumb_proximal_pitch_joint"
    type="revolute">
    <origin
      xyz="0.02175 -1.722E-05 6.35E-05"
      rpy="1.5709 -0.0029195 -0.00079174" />
    <parent
      link="R_thumb_proximal_base" />
    <child
      link="R_thumb_proximal" />
    <axis
      xyz="0 0 1" />
    <limit
      lower="0"
      upper="1.22"
      effort="10"
      velocity="0.8" />
  </joint>
  <link
    name="R_thumb_distal">
    <inertial>
      <origin
        xyz="0.013742 -0.0027343 -5.1674E-07"
        rpy="0 0 0" />
      <mass
        value="0.019744" />
      <inertia
        ixx="8.966E-7"
        ixy="0"
        ixz="9.15E-8"
        iyy="2.1908E-6"
        iyz="0"
        izz="2.3291E-6" />
    </inertial>
    <visual>
      <origin
        xyz="0 0 0"
        rpy="0 0 0" />
      <geometry>
        <mesh
          filename="../meshes/fourier_hand/R_thumb_distal.STL" />
      </geometry>
      <material
        name="">
        <color
          rgba="0.86667 0.86667 0.8902 1" />
      </material>
    </visual>
    <collision>
      <origin
        xyz="0 0 0"
        rpy="0 0 0" />
      <geometry>
        <mesh
          filename="../meshes/fourier_hand/R_thumb_distal.STL" />
      </geometry>
    </collision>
  </link>
  <joint
    name="R_thumb_distal_joint"
    type="revolute">
    <origin
      xyz="0.061444 0.0082822 0"
      rpy="0 0 -0.0029196" />
    <parent
      link="R_thumb_proximal" />
    <child
      link="R_thumb_distal" />
    <axis
      xyz="0 0 1" />
    <limit
      lower="0"
      upper="1.04"
      effort="10"
      velocity="0.8" />
    <mimic
      joint="R_thumb_proximal_pitch_joint"
      multiplier="0.974"
      offset="0" />
  </joint>


  <link name="R_thumb_tip">
    <visual>
      <origin
        xyz="0 0 0"
        rpy="0 0 0" />
      <geometry>
        <sphere radius="0.005" />
      </geometry>
      <material name="yellow">
        <color rgba="0.9 1 0 1" />
      </material>
    </visual>
  </link>
  <joint name="R_thumb_tip_joint" type="fixed">
    <parent link="R_thumb_distal" />
    <child link="R_thumb_tip" />
    <origin rpy="0 0 0" xyz="0.031 0 0" />
  </joint>
  


  <link
    name="R_index_proximal">
    <inertial>
      <origin
        xyz="0.0095995 0.00044318 2.9627E-06"
        rpy="0 0 0" />
      <mass
        value="0.019118" />
      <inertia
        ixx="3.8425E-6"
        ixy="0"
        ixz="1.462E-7"
        iyy="3.7145E-6"
        iyz="1.232E-7"
        izz="8.708E-7" />
    </inertial>
    <visual>
      <origin
        xyz="0 0 0"
        rpy="0 0 0" />
      <geometry>
        <mesh
          filename="../meshes/fourier_hand/R_index_proximal.STL" />
      </geometry>
      <material
        name="">
        <color
          rgba="0.8902 0.8902 0.91373 1" />
      </material>
    </visual>
    <collision>
      <origin
        xyz="0 0 0"
        rpy="0 0 0" />
      <geometry>
        <mesh
          filename="../meshes/fourier_hand/R_index_proximal.STL" />
      </geometry>
    </collision>
  </link>
  <joint
    name="R_index_proximal_joint"
    type="revolute">
    <origin
      xyz="0.026583 0.012307 -0.096064"
      rpy="-3.1402 1.5214 0.0013813" />
    <parent
      link="r_hand_base_link" />
    <child
      link="R_index_proximal" />
    <axis
      xyz="0 0 1" />
    <limit
      lower="-1.57"
      upper="0"
      effort="10"
      velocity="0.8" />
  </joint>
  <link
    name="R_index_intermediate">
    <inertial>
      <origin
        xyz="0.018004 0.0029995 -8.9222E-06"
        rpy="0 0 0" />
      <mass
        value="0.012927" />
      <inertia
        ixx="2.0343E-6"
        ixy="-1.25E-8"
        ixz="8.29E-8"
        iyy="2.0059E-6"
        iyz="2.518E-7"
        izz="3.763E-7" />
    </inertial>
    <visual>
      <origin
        xyz="0 0 0"
        rpy="0 0 0" />
      <geometry>
        <mesh
          filename="../meshes/fourier_hand/R_index_intermediate.STL" />
      </geometry>
      <material
        name="">
        <color
          rgba="0.79216 0.81961 0.93333 1" />
      </material>
    </visual>
    <collision>
      <origin
        xyz="0 0 0"
        rpy="0 0 0" />
      <geometry>
        <mesh
          filename="../meshes/fourier_hand/R_index_intermediate.STL" />
      </geometry>
    </collision>
  </link>
  <joint
    name="R_index_intermediate_joint"
    type="revolute">
    <origin
      xyz="0.031532 -0.0054551 0"
      rpy="0 0 0" />
    <parent
      link="R_index_proximal" />
    <child
      link="R_index_intermediate" />
    <axis
      xyz="0 0 1" />
    <limit
      lower="-1.74"
      upper="0"
      effort="10"
      velocity="0.8" />
    <mimic
      joint="R_index_proximal_joint"
      multiplier="1.128"
      offset="0" />
  </joint>



  <link name="R_index_tip">
    <visual>
      <origin
        xyz="0 0 0"
        rpy="0 0 0" />
      <geometry>
        <sphere radius="0.005" />
      </geometry>
      <material name="yellow">
        <color rgba="0.9 1 0 1" />
      </material>
    </visual>
  </link>
  <joint name="R_index_tip_joint" type="fixed">
    <parent link="R_index_intermediate" />
    <child link="R_index_tip" />
    <origin rpy="0 0 0" xyz="0.038 -0.0015 0" />
  </joint>



  <link
    name="R_middle_proximal">
    <inertial>
      <origin
        xyz="0.0095562 0.000719 3.0016E-06"
        rpy="0 0 0" />
      <mass
        value="0.019118" />
      <inertia
        ixx="3.8487E-6"
        ixy="0"
        ixz="0"
        iyy="3.7212E-6"
        iyz="6.11E-8"
        izz="8.56E-7" />
    </inertial>
    <visual>
      <origin
        xyz="0 0 0"
        rpy="0 0 0" />
      <geometry>
        <mesh
          filename="../meshes/fourier_hand/R_middle_proximal.STL" />
      </geometry>
      <material
        name="">
        <color
          rgba="0.8902 0.8902 0.91373 1" />
      </material>
    </visual>
    <collision>
      <origin
        xyz="0 0 0"
        rpy="0 0 0" />
      <geometry>
        <mesh
          filename="../meshes/fourier_hand/R_middle_proximal.STL" />
      </geometry>
    </collision>
  </link>
  <joint
    name="R_middle_proximal_joint"
    type="revolute">
    <origin
      xyz="0.0082089 0.012307 -0.098014"
      rpy="-0.023406 1.5679 3.1182" />
    <parent
      link="r_hand_base_link" />
    <child
      link="R_middle_proximal" />
    <axis
      xyz="0 0 1" />
    <limit
      lower="-1.57"
      upper="0"
      effort="10"
      velocity="0.8" />
  </joint>
  <link
    name="R_middle_intermediate">
    <inertial>
      <origin
        xyz="0.021282 0.0040829 -9.9882E-06"
        rpy="0 0 0" />
      <mass
        value="0.015352" />
      <inertia
        ixx="3.2904E-6"
        ixy="0"
        ixz="0"
        iyy="3.2834E-6"
        iyz="2.227E-7"
        izz="4.144E-7" />
    </inertial>
    <visual>
      <origin
        xyz="0 0 0"
        rpy="0 0 0" />
      <geometry>
        <mesh
          filename="../meshes/fourier_hand/R_middle_intermediate.STL" />
      </geometry>
      <material
        name="">
        <color
          rgba="0.86667 0.86667 0.8902 1" />
      </material>
    </visual>
    <collision>
      <origin
        xyz="0 0 0"
        rpy="0 0 0" />
      <geometry>
        <mesh
          filename="../meshes/fourier_hand/R_middle_intermediate.STL" />
      </geometry>
    </collision>
  </link>
  <joint
    name="R_middle_intermediate_joint"
    type="revolute">
    <origin
      xyz="0.031662 -0.0046408 0"
      rpy="0 0 0" />
    <parent
      link="R_middle_proximal" />
    <child
      link="R_middle_intermediate" />
    <axis
      xyz="0 0 1" />
    <limit
      lower="-1.74"
      upper="0"
      effort="10"
      velocity="0.8" />
    <mimic
      joint="R_middle_proximal_joint"
      multiplier="1.131"
      offset="0" />
  </joint>


  <link name="R_middle_tip">
    <visual>
      <origin
        xyz="0 0 0"
        rpy="0 0 0" />
      <geometry>
        <sphere radius="0.005" />
      </geometry>
      <material name="yellow">
        <color rgba="0.9 1 0 1" />
      </material>
    </visual>
  </link>
  <joint name="R_middle_tip_joint" type="fixed">
    <parent link="R_middle_intermediate" />
    <child link="R_middle_tip" />
    <origin rpy="0 0 0" xyz="0.045 0.0005 0" />
  </joint>



  <link
    name="R_ring_proximal">
    <inertial>
      <origin
        xyz="0.0095993 0.00044271 2.9621E-06"
        rpy="0 0 0" />
      <mass
        value="0.019117" />
      <inertia
        ixx="3.8404E-6"
        ixy="0"
        ixz="-1.659E-7"
        iyy="3.7145E-6"
        iyz="1.232E-7"
        izz="8.729E-7" />
    </inertial>
    <visual>
      <origin
        xyz="0 0 0"
        rpy="0 0 0" />
      <geometry>
        <mesh
          filename="../meshes/fourier_hand/R_ring_proximal.STL" />
      </geometry>
      <material
        name="">
        <color
          rgba="0.8902 0.8902 0.91373 1" />
      </material>
    </visual>
    <collision>
      <origin
        xyz="0 0 0"
        rpy="0 0 0" />
      <geometry>
        <mesh
          filename="../meshes/fourier_hand/R_ring_proximal.STL" />
      </geometry>
    </collision>
  </link>
  <joint
    name="R_ring_proximal_joint"
    type="revolute">
    <origin
      xyz="-0.010252 0.012307 -0.097905"
      rpy="0 1.5155 3.1416" />
    <parent
      link="r_hand_base_link" />
    <child
      link="R_ring_proximal" />
    <axis
      xyz="0 0 1" />
    <limit
      lower="-1.57"
      upper="0"
      effort="10"
      velocity="0.8" />
  </joint>
  <link
    name="R_ring_intermediate">
    <inertial>
      <origin
        xyz="0.018005 0.0029979 -9.3052E-06"
        rpy="0 0 0" />
      <mass
        value="0.012925" />
      <inertia
        ixx="2.0334E-6"
        ixy="1.39E-8"
        ixz="-9.13E-8"
        iyy="2.0059E-6"
        iyz="2.517E-7"
        izz="3.772E-7" />
    </inertial>
    <visual>
      <origin
        xyz="0 0 0"
        rpy="0 0 0" />
      <geometry>
        <mesh
          filename="../meshes/fourier_hand/R_ring_intermediate.STL" />
      </geometry>
      <material
        name="">
        <color
          rgba="0.29804 0.29804 0.29804 1" />
      </material>
    </visual>
    <collision>
      <origin
        xyz="0 0 0"
        rpy="0 0 0" />
      <geometry>
        <mesh
          filename="../meshes/fourier_hand/R_ring_intermediate.STL" />
      </geometry>
    </collision>
  </link>
  <joint
    name="R_ring_intermediate_joint"
    type="revolute">
    <origin
      xyz="0.031531 -0.0054572 0"
      rpy="0 0 0" />
    <parent
      link="R_ring_proximal" />
    <child
      link="R_ring_intermediate" />
    <axis
      xyz="0 0 1" />
    <limit
      lower="-1.74"
      upper="0"
      effort="10"
      velocity="0.8" />
    <mimic
      joint="R_ring_proximal_joint"
      multiplier="1.143"
      offset="0" />
  </joint>


  <link name="R_ring_tip">
    <visual>
      <origin
        xyz="0 0 0"
        rpy="0 0 0" />
      <geometry>
        <sphere radius="0.005" />
      </geometry>
      <material name="green">
        <color rgba="0.9 1 0 1" />
      </material>
    </visual>
  </link>
  <joint name="R_ring_tip_joint" type="fixed">
    <parent link="R_ring_intermediate" />
    <child link="R_ring_tip" />
    <origin rpy="0 0 0" xyz="0.038 -0.0015 0" />
  </joint>



  <link
    name="R_pinky_proximal">
    <inertial>
      <origin
        xyz="0.0096436 9.4084E-05 2.9778E-06"
        rpy="0 0 0" />
      <mass
        value="0.019117" />
      <inertia
        ixx="3.816E-6"
        ixy="2.13E-8"
        ixz="-3.187E-7"
        iyy="3.7016E-6"
        iyz="2.002E-7"
        izz="9.119E-7" />
    </inertial>
    <visual>
      <origin
        xyz="0 0 0"
        rpy="0 0 0" />
      <geometry>
        <mesh
          filename="../meshes/fourier_hand/R_pinky_proximal.STL" />
      </geometry>
      <material
        name="">
        <color
          rgba="0.8902 0.8902 0.91373 1" />
      </material>
    </visual>
    <collision>
      <origin
        xyz="0 0 0"
        rpy="0 0 0" />
      <geometry>
        <mesh
          filename="../meshes/fourier_hand/R_pinky_proximal.STL" />
      </geometry>
    </collision>
  </link>
  <joint
    name="R_pinky_proximal_joint"
    type="revolute">
    <origin
      xyz="-0.028513 0.012307 -0.095926"
      rpy="-0.00063622 1.4632 3.141" />
    <parent
      link="r_hand_base_link" />
    <child
      link="R_pinky_proximal" />
    <axis
      xyz="0 0 1" />
    <limit
      lower="-1.57"
      upper="0"
      effort="10"
      velocity="0.8" />
  </joint>
  <link
    name="R_pinky_intermediate">
    <inertial>
      <origin
        xyz="0.016096 0.001186 -8.5372E-06"
        rpy="0 0 0" />
      <mass
        value="0.0056869" />
      <inertia
        ixx="6.595E-7"
        ixy="1.42E-8"
        ixz="-5.24E-8"
        iyy="6.243E-7"
        iyz="1.313E-7"
        izz="1.785E-7" />
    </inertial>
    <visual>
      <origin
        xyz="0 0 0"
        rpy="0 0 0" />
      <geometry>
        <mesh
          filename="../meshes/fourier_hand/R_pinky_intermediate.STL" />
      </geometry>
      <material
        name="">
        <color
          rgba="0.79216 0.81961 0.93333 1" />
      </material>
    </visual>
    <collision>
      <origin
        xyz="0 0 0"
        rpy="0 0 0" />
      <geometry>
        <mesh
          filename="../meshes/fourier_hand/R_pinky_intermediate.STL" />
      </geometry>
    </collision>
  </link>
  <joint
    name="R_pinky_intermediate_joint"
    type="revolute">
    <origin
      xyz="0.031338 -0.0064763 0"
      rpy="0 0 6.7954E-05" />
    <parent
      link="R_pinky_proximal" />
    <child
      link="R_pinky_intermediate" />
    <axis
      xyz="0 0 1" />
    <limit
      lower="-1.74"
      upper="0"
      effort="10"
      velocity="0.8" />
    <mimic
      joint="R_pinky_proximal_joint"
      multiplier="1.129"
      offset="0" />
  </joint>


  <link name="R_pinky_tip">
    <visual>
      <origin
        xyz="0 0 0"
        rpy="0 0 0" />
      <geometry>
        <sphere radius="0.005" />
      </geometry>
      <material name="yellow">
        <color rgba="0.9 1 0 1" />
      </material>
    </visual>
  </link>
  <joint name="R_pinky_tip_joint" type="fixed">
    <parent link="R_pinky_intermediate" />
    <child link="R_pinky_tip" />
    <origin rpy="0 0 0" xyz="0.031 -0.004 0" />
  </joint>


</robot>