<?xml version="1.0" encoding="utf-8"?>

<!-- 08272024ver1 -->

<robot
  name="GR1T1_fourier_hand">
  <link
    name="base_link">
    <inertial>
      <origin
        xyz="-0.0771772 -8.2E-5 -0.016535"
        rpy="0 0 0" />
      <mass
        value="4.5972" />
      <inertia
        ixx="0.041326"
        ixy="-7.5E-7"
        ixz="-0.002304"
        iyy="0.012878"
        iyz="-7.52E-6"
        izz="0.04563" />
    </inertial>
    <visual>
      <origin
        xyz="0 0 0"
        rpy="0 0 0" />
      <geometry>
        <mesh
          filename="../meshes/base_link.STL" />
      </geometry>
      <material
        name="">
        <color
          rgba="0.75294 0.75294 0.75294 1" />
      </material>
    </visual>
    <collision>
      <origin
        xyz="0 0 0"
        rpy="0 0 0" />
      <geometry>
        <mesh
          filename="../meshes/base_link.STL" />
      </geometry>
    </collision>
  </link>
  <link
    name="left_thigh_roll_link">
    <inertial>
      <origin
        xyz="0.0354 7.34E-5 0.00186"
        rpy="0 0 0" />
      <mass
        value="1.84" />
      <inertia
        ixx="0.001934"
        ixy="-1.16E-6"
        ixz="-8.95E-5"
        iyy="0.004144"
        iyz="-7.52E-6"
        izz="0.004220" />
    </inertial>
    <visual>
      <origin
        xyz="0 0 0"
        rpy="0 0 0" />
      <geometry>
        <mesh
          filename="../meshes/left_thigh_roll_link.STL" />
      </geometry>
      <material
        name="">
        <color
          rgba="0.752941176470588 0.752941176470588 0.752941176470588 1" />
      </material>
    </visual>
    <collision>
      <origin
        xyz="0 0 0"
        rpy="0 0 0" />
      <geometry>
        <mesh
          filename="../meshes/left_thigh_roll_link.STL" />
      </geometry>
    </collision>
  </link>
  <joint
    name="left_hip_roll_joint"
    type="revolute">
    <origin
      xyz="-0.0883 0.105 -0.027623"
      rpy="0 0 0" />
    <parent
      link="base_link" />
    <child
      link="left_thigh_roll_link" />
    <axis
      xyz="1 0 0" />
    <limit
      lower="-0.09"
      upper="0.79"
      effort="48"
      velocity="12.15" />
  </joint>
  <link
    name="left_thigh_yaw_link">
    <inertial>
      <origin
        xyz="-0.0007087 0.03910 -0.1181"
        rpy="0 0 0" />
      <mass
        value="3.71" />
      <inertia
        ixx="0.0176"
        ixy="-0.0001166"
        ixz="0.0001417"
        iyy="0.02054"
        iyz="0.003857"
        izz="0.0081" />
    </inertial>
    <visual>
      <origin
        xyz="0 0 0"
        rpy="0 0 0" />
      <geometry>
        <mesh
          filename="../meshes/left_thigh_yaw_link.STL" />
      </geometry>
      <material
        name="">
        <color
          rgba="0.752941176470588 0.752941176470588 0.752941176470588 1" />
      </material>
    </visual>
    <collision>
      <origin
        xyz="0 0 0"
        rpy="0 0 0" />
      <geometry>
        <mesh
          filename="../meshes/left_thigh_yaw_link.STL" />
      </geometry>
    </collision>
  </link>
  <joint
    name="left_hip_yaw_joint"
    type="revolute">
    <origin
      xyz="0.0858 0 0.0059233"
      rpy="0 0 0" />
    <parent
      link="left_thigh_roll_link" />
    <child
      link="left_thigh_yaw_link" />
    <axis
      xyz="0 0 1" />
    <limit
      lower="-0.7"
      upper="0.7"
      effort="66"
      velocity="16.76" />
  </joint>
  <link
    name="left_thigh_pitch_link">
    <inertial>
      <origin
        xyz="0.001183 -0.02922 -0.04822"
        rpy="0 0 0" />
      <mass
        value="9.63" />
      <inertia
        ixx="0.07708"
        ixy="-5.039E-5"
        ixz="0.001857"
        iyy="0.07633"
        iyz="-0.005547"
        izz="0.03356" />
    </inertial>
    <visual>
      <origin
        xyz="0 0 0"
        rpy="0 0 0" />
      <geometry>
        <mesh
          filename="../meshes/left_thigh_pitch_link.STL" />
      </geometry>
      <material
        name="">
        <color
          rgba="0.752941176470588 0.752941176470588 0.752941176470588 1" />
      </material>
    </visual>
    <collision>
      <origin
        xyz="0 0 0"
        rpy="0 0 0" />
      <geometry>
        <mesh
          filename="../meshes/left_thigh_pitch_link.STL" />
      </geometry>
    </collision>
  </link>
  <joint
    name="left_hip_pitch_joint"
    type="revolute">
    <origin
      xyz="0 0.0223 -0.1464"
      rpy="0 0 0" />
    <parent
      link="left_thigh_yaw_link" />
    <child
      link="left_thigh_pitch_link" />
    <axis
      xyz="0 1 0" />
    <limit
      lower="-1.75"
      upper="0.7"
      effort="225"
      velocity="37.38" />
  </joint>
  <link
    name="left_shank_pitch_link">
    <inertial>
      <origin
        xyz="0.001286 -2.255E-5 -0.1115"
        rpy="0 0 0" />
      <mass
        value="2.32" />
      <inertia
        ixx="0.01051"
        ixy="-2.38E-6"
        ixz="-1.788E-5"
        iyy="0.01051"
        iyz="-0.0003610"
        izz="0.001131" />
    </inertial>
    <visual>
      <origin
        xyz="0 0 0"
        rpy="0 0 0" />
      <geometry>
        <mesh
          filename="../meshes/left_shank_pitch_link.STL" />
      </geometry>
      <material
        name="">
        <color
          rgba="0.752941176470588 0.752941176470588 0.752941176470588 1" />
      </material>
    </visual>
    <collision>
      <origin
        xyz="0 0 0"
        rpy="0 0 0" />
      <geometry>
        <mesh
          filename="../meshes/left_shank_pitch_link.STL" />
      </geometry>
    </collision>
  </link>
  <joint
    name="left_knee_pitch_joint"
    type="revolute">
    <origin
      xyz="0 -0.0213 -0.36"
      rpy="0 0 0" />
    <parent
      link="left_thigh_pitch_link" />
    <child
      link="left_shank_pitch_link" />
    <axis
      xyz="0 1 0" />
    <limit
      lower="-0.09"
      upper="1.92"
      effort="225"
      velocity="37.38" />
  </joint>
  <link
    name="left_foot_pitch_link">
    <inertial>
      <origin
        xyz="0.0284 0.00121 -0.0293"
        rpy="0 0 0" />
      <mass
        value="0.538" />
      <inertia
        ixx="0.000394"
        ixy="-9.64E-6"
        ixz="0.000173"
        iyy="0.00232"
        iyz="4.36E-6"
        izz="0.002474" />
    </inertial>
    <visual>
      <origin
        xyz="0 0 0"
        rpy="0 0 0" />
      <geometry>
        <mesh
          filename="../meshes/left_foot_pitch_link.STL" />
      </geometry>
      <material
        name="">
        <color
          rgba="0.752941176470588 0.752941176470588 0.752941176470588 1" />
      </material>
    </visual>
    <collision>
      <origin
        xyz="0 0 0"
        rpy="0 0 0" />
      <geometry>
        <mesh
          filename="../meshes/left_foot_pitch_link.STL" />
      </geometry>
    </collision>
  </link>
  <joint
    name="left_ankle_pitch_joint"
    type="revolute">
    <origin
      xyz="0 0 -0.34"
      rpy="0 0 0" />
    <parent
      link="left_shank_pitch_link" />
    <child
      link="left_foot_pitch_link" />
    <axis
      xyz="0 1 0" />
    <limit
      lower="-1.05"
      upper="0.52"
      effort="15"
      velocity="20.32" />
  </joint>
  <link
    name="left_foot_roll_link">
    <inertial>
      <origin
        xyz="0.0284 0.00121 -0.0293"
        rpy="0 0 0" />
      <mass
        value="0.538" />
      <inertia
        ixx="0.000394"
        ixy="-9.64E-6"
        ixz="0.000173"
        iyy="0.00232"
        iyz="4.36E-6"
        izz="0.002474" />
    </inertial>
    <visual>
      <origin
        xyz="0 0 0"
        rpy="0 0 0" />
      <geometry>
        <mesh
          filename="../meshes/left_foot_roll_link.STL" />
      </geometry>
      <material
        name="">
        <color
          rgba="0.752941176470588 0.752941176470588 0.752941176470588 1" />
      </material>
    </visual>
    <collision>
      <origin
        xyz="0 0 0"
        rpy="0 0 0" />
      <geometry>
        <mesh
          filename="../meshes/left_foot_roll_link.STL" />
      </geometry>
    </collision>
  </link>
  <joint
    name="left_ankle_roll_joint"
    type="revolute">
    <origin
      xyz="0 0 0"
      rpy="0 0 0" />
    <parent
      link="left_foot_pitch_link" />
    <child
      link="left_foot_roll_link" />
    <axis
      xyz="1 0 0" />
    <limit
      lower="-0.44"
      upper="0.44"
      effort="30"
      velocity="20.32" />
  </joint>
  <link
    name="right_thigh_roll_link">
    <inertial>
      <origin
        xyz="0.0355 -6.91E-5 0.001854"
        rpy="0 0 0" />
      <mass
        value="1.84" />
      <inertia
        ixx="0.001935"
        ixy="1.098E-5"
        ixz="-9.038E-5"
        iyy="0.004171"
        iyz="7.53E-6"
        izz="0.004247" />
    </inertial>
    <visual>
      <origin
        xyz="0 0 0"
        rpy="0 0 0" />
      <geometry>
        <mesh
          filename="../meshes/right_thigh_roll_link.STL" />
      </geometry>
      <material
        name="">
        <color
          rgba="0.752941176470588 0.752941176470588 0.752941176470588 1" />
      </material>
    </visual>
    <collision>
      <origin
        xyz="0 0 0"
        rpy="0 0 0" />
      <geometry>
        <mesh
          filename="../meshes/right_thigh_roll_link.STL" />
      </geometry>
    </collision>
  </link>
  <joint
    name="right_hip_roll_joint"
    type="revolute">
    <origin
      xyz="-0.0883 -0.10499 -0.027622"
      rpy="0 0 0" />
    <parent
      link="base_link" />
    <child
      link="right_thigh_roll_link" />
    <axis
      xyz="1 0 0" />
    <limit
      lower="-0.79"
      upper="0.09"
      effort="48"
      velocity="12.15" />
  </joint>
  <link
    name="right_thigh_yaw_link">
    <inertial>
      <origin
        xyz="-0.0008125 -0.03909 -0.1181"
        rpy="0 0 0" />
      <mass
        value="3.71" />
      <inertia
        ixx="0.01760"
        ixy="0.0001017"
        ixz="0.0001380"
        iyy="0.02054"
        iyz="-0.003857"
        izz="0.008100" />
    </inertial>
    <visual>
      <origin
        xyz="0 0 0"
        rpy="0 0 0" />
      <geometry>
        <mesh
          filename="../meshes/right_thigh_yaw_link.STL" />
      </geometry>
      <material
        name="">
        <color
          rgba="0.752941176470588 0.752941176470588 0.752941176470588 1" />
      </material>
    </visual>
    <collision>
      <origin
        xyz="0 0 0"
        rpy="0 0 0" />
      <geometry>
        <mesh
          filename="../meshes/right_thigh_yaw_link.STL" />
      </geometry>
    </collision>
  </link>
  <joint
    name="right_hip_yaw_joint"
    type="revolute">
    <origin
      xyz="0.0858 0 0.0059216"
      rpy="0 0 0" />
    <parent
      link="right_thigh_roll_link" />
    <child
      link="right_thigh_yaw_link" />
    <axis
      xyz="0 0 1" />
    <limit
      lower="-0.7"
      upper="0.7"
      effort="66"
      velocity="16.76" />
  </joint>
  <link
    name="right_thigh_pitch_link">
    <inertial>
      <origin
        xyz="0.00123 0.02922 -0.04822"
        rpy="0 0 0" />
      <mass
        value="9.63" />
      <inertia
        ixx="0.07706"
        ixy="2.607E-5"
        ixz="0.001863"
        iyy="0.07632"
        iyz="0.005529"
        izz="0.03356" />
    </inertial>
    <visual>
      <origin
        xyz="0 0 0"
        rpy="0 0 0" />
      <geometry>
        <mesh
          filename="../meshes/right_thigh_pitch_link.STL" />
      </geometry>
      <material
        name="">
        <color
          rgba="0.752941176470588 0.752941176470588 0.752941176470588 1" />
      </material>
    </visual>
    <collision>
      <origin
        xyz="0 0 0"
        rpy="0 0 0" />
      <geometry>
        <mesh
          filename="../meshes/right_thigh_pitch_link.STL" />
      </geometry>
    </collision>
  </link>
  <joint
    name="right_hip_pitch_joint"
    type="revolute">
    <origin
      xyz="0 -0.0223 -0.1464"
      rpy="0 0 0" />
    <parent
      link="right_thigh_yaw_link" />
    <child
      link="right_thigh_pitch_link" />
    <axis
      xyz="0 1 0" />
    <limit
      lower="-1.75"
      upper="0.7"
      effort="225"
      velocity="37.38" />
  </joint>
  <link
    name="right_shank_pitch_link">
    <inertial>
      <origin
        xyz="0.001291 2.255E-5 -0.1115"
        rpy="0 0 0" />
      <mass
        value="2.32" />
      <inertia
        ixx="0.01051"
        ixy="2.42E-6"
        ixz="-1.788E-5"
        iyy="0.01051"
        iyz="0.0003610"
        izz="0.001131" />
    </inertial>
    <visual>
      <origin
        xyz="0 0 0"
        rpy="0 0 0" />
      <geometry>
        <mesh
          filename="../meshes/right_shank_pitch_link.STL" />
      </geometry>
      <material
        name="">
        <color
          rgba="0.752941176470588 0.752941176470588 0.752941176470588 1" />
      </material>
    </visual>
    <collision>
      <origin
        xyz="0 0 0"
        rpy="0 0 0" />
      <geometry>
        <mesh
          filename="../meshes/right_shank_pitch_link.STL" />
      </geometry>
    </collision>
  </link>
  <joint
    name="right_knee_pitch_joint"
    type="revolute">
    <origin
      xyz="0 0.0213 -0.36"
      rpy="0 0 0" />
    <parent
      link="right_thigh_pitch_link" />
    <child
      link="right_shank_pitch_link" />
    <axis
      xyz="0 1 0" />
    <limit
      lower="-0.09"
      upper="1.92"
      effort="225"
      velocity="37.38" />
  </joint>
  <link
    name="right_foot_pitch_link">
    <inertial>
      <origin
        xyz="0.0284 -0.00121 -0.0293"
        rpy="0 0 0" />
      <mass
        value="0.538" />
      <inertia
        ixx="0.000394"
        ixy="9.6E-6"
        ixz="0.000173"
        iyy="0.00232"
        iyz="-4.36E-6"
        izz="0.00247" />
    </inertial>
    <visual>
      <origin
        xyz="0 0 0"
        rpy="0 0 0" />
      <geometry>
        <mesh
          filename="../meshes/right_foot_pitch_link.STL" />
      </geometry>
      <material
        name="">
        <color
          rgba="0.752941176470588 0.752941176470588 0.752941176470588 1" />
      </material>
    </visual>
    <collision>
      <origin
        xyz="0 0 0"
        rpy="0 0 0" />
      <geometry>
        <mesh
          filename="../meshes/right_foot_pitch_link.STL" />
      </geometry>
    </collision>
  </link>
  <joint
    name="right_ankle_pitch_joint"
    type="revolute">
    <origin
      xyz="0 0 -0.34"
      rpy="0 0 0" />
    <parent
      link="right_shank_pitch_link" />
    <child
      link="right_foot_pitch_link" />
    <axis
      xyz="0 1 0" />
    <limit
      lower="-1.05"
      upper="0.52"
      effort="15"
      velocity="20.32" />
  </joint>
  <link
    name="right_foot_roll_link">
    <inertial>
      <origin
        xyz="0.0284 -0.00121 -0.0293"
        rpy="0 0 0" />
      <mass
        value="0.538" />
      <inertia
        ixx="0.000394"
        ixy="9.6E-6"
        ixz="0.000173"
        iyy="0.00232"
        iyz="-4.36E-6"
        izz="0.00247" />
    </inertial>
    <visual>
      <origin
        xyz="0 0 0"
        rpy="0 0 0" />
      <geometry>
        <mesh
          filename="../meshes/right_foot_roll_link.STL" />
      </geometry>
      <material
        name="">
        <color
          rgba="0.752941176470588 0.752941176470588 0.752941176470588 1" />
      </material>
    </visual>
    <collision>
      <origin
        xyz="0 0 0"
        rpy="0 0 0" />
      <geometry>
        <mesh
          filename="../meshes/right_foot_roll_link.STL" />
      </geometry>
    </collision>
  </link>
  <joint
    name="right_ankle_roll_joint"
    type="revolute">
    <origin
      xyz="0 0 0"
      rpy="0 0 0" />
    <parent
      link="right_foot_pitch_link" />
    <child
      link="right_foot_roll_link" />
    <axis
      xyz="1 0 0" />
    <limit
      lower="-0.44"
      upper="0.44"
      effort="30"
      velocity="20.32" />
  </joint>
  <link
    name="waist_yaw_link">
    <inertial>
      <origin
        xyz="-0.002641 -0.009332 0.050658"
        rpy="0 0 0" />
      <mass
        value="1.49" />
      <inertia
        ixx="0.00302"
        ixy="3.832E-5"
        ixz="1.016E-5"
        iyy="0.00271"
        iyz="0.0005105"
        izz="0.001679" />
    </inertial>
    <visual>
      <origin
        xyz="0 0 0"
        rpy="0 0 0" />
      <geometry>
        <mesh
          filename="../meshes/waist_yaw_link.STL" />
      </geometry>
      <material
        name="">
        <color
          rgba="0.752941176470588 0.752941176470588 0.752941176470588 1" />
      </material>
    </visual>
    <collision>
      <origin
        xyz="0 0 0"
        rpy="0 0 0" />
      <geometry>
        <mesh
          filename="../meshes/waist_yaw_link.STL" />
      </geometry>
    </collision>
  </link>
  <joint
    name="waist_yaw_joint"
    type="revolute">
    <origin
      xyz="0 0 0"
      rpy="0 0 0" />
    <parent
      link="base_link" />
    <child
      link="waist_yaw_link" />
    <axis
      xyz="0 0 1" />
    <limit
      lower="-1.05"
      upper="1.05"
      effort="66"
      velocity="16.76" />
  </joint>
  <link
    name="waist_pitch_link">
    <inertial>
      <origin
        xyz="0.00451 0.00086 0.0406"
        rpy="0 0 0" />
      <mass
        value="1.52" />
      <inertia
        ixx="0.004563"
        ixy="-2.99E-5"
        ixz="-0.000254"
        iyy="0.004563"
        iyz="-0.0002748"
        izz="0.001855" />
    </inertial>
    <visual>
      <origin
        xyz="0 0 0"
        rpy="0 0 0" />
      <geometry>
        <mesh
          filename="../meshes/waist_pitch_link.STL" />
      </geometry>
      <material
        name="">
        <color
          rgba="0.752941176470588 0.752941176470588 0.752941176470588 1" />
      </material>
    </visual>
    <collision>
      <origin
        xyz="0 0 0"
        rpy="0 0 0" />
      <geometry>
        <mesh
          filename="../meshes/waist_pitch_link.STL" />
      </geometry>
    </collision>
  </link>
  <joint
    name="waist_pitch_joint"
    type="revolute">
    <origin
      xyz="0 -0.00525 0.0873"
      rpy="0 0 0" />
    <parent
      link="waist_yaw_link" />
    <child
      link="waist_pitch_link" />
    <axis
      xyz="0 1 0" />
    <limit
      lower="-0.52"
      upper="1.22"
      effort="66"
      velocity="16.76" />
  </joint>
  <link
    name="waist_roll_link">
    <inertial>
      <origin
        xyz="0.00513 -1.48E-6 0.01311"
        rpy="0 0 0" />
      <mass
        value="0.906" />
      <inertia
        ixx="0.001"
        ixy="-1E-8"
        ixz="0.000151"
        iyy="0.001226"
        iyz="8E-8"
        izz="0.001087" />
    </inertial>
    <visual>
      <origin
        xyz="0 0 0"
        rpy="0 0 0" />
      <geometry>
        <mesh
          filename="../meshes/waist_roll_link.STL" />
      </geometry>
      <material
        name="">
        <color
          rgba="0.752941176470588 0.752941176470588 0.752941176470588 1" />
      </material>
    </visual>
    <collision>
      <origin
        xyz="0 0 0"
        rpy="0 0 0" />
      <geometry>
        <mesh
          filename="../meshes/waist_roll_link.STL" />
      </geometry>
    </collision>
  </link>
  <joint
    name="waist_roll_joint"
    type="revolute">
    <origin
      xyz="0.00525 0.00525 0.081"
      rpy="0 0 0" />
    <parent
      link="waist_pitch_link" />
    <child
      link="waist_roll_link" />
    <axis
      xyz="1 0 0" />
    <limit
      lower="-0.7"
      upper="0.7"
      effort="66"
      velocity="16.76" />
  </joint>
  <link
    name="torso_link">
    <inertial>
      <origin
        xyz="-0.0017 -3.871E-5 0.02154"
        rpy="0 0 0" />
      <mass
        value="2.92" />
      <inertia
        ixx="0.03163"
        ixy="-8.22E-6"
        ixz="-0.000265"
        iyy="0.02008"
        iyz="-3.53E-6"
        izz="0.01970" />
    </inertial>
    <visual>
      <origin
        xyz="0 0 0"
        rpy="0 0 0" />
      <geometry>
        <mesh
          filename="../meshes/torso_link.STL" />
      </geometry>
      <material
        name="">
        <color
          rgba="0.752941176470588 0.752941176470588 0.752941176470588 1" />
      </material>
    </visual>
    <collision>
      <origin
        xyz="0 0 0"
        rpy="0 0 0" />
      <geometry>
        <mesh
          filename="../meshes/torso_link.STL" />
      </geometry>
    </collision>
  </link>
  <joint
    name="torso_joint"
    type="fixed">
    <origin
      xyz="-0.00939 0 0.16071"
      rpy="0 0 0" />
    <parent
      link="waist_roll_link" />
    <child
      link="torso_link" />
    <axis
      xyz="0 0 0" />
  </joint>
  <link
    name="left_upper_arm_pitch_link">
    <inertial>
      <origin
        xyz="0.00323 0.05324 0.000192"
        rpy="0 0 0" />
      <mass
        value="0.81" />
      <inertia
        ixx="0.002024"
        ixy="-9.67E-5"
        ixz="-4.2E-7"
        iyy="0.0005"
        iyz="1.71E-6"
        izz="0.001957" />
    </inertial>
    <visual>
      <origin
        xyz="0 0 0"
        rpy="0 0 0" />
      <geometry>
        <mesh
          filename="../meshes/left_upper_arm_pitch_link.STL" />
      </geometry>
      <material
        name="">
        <color
          rgba="0.752941176470588 0.752941176470588 0.752941176470588 1" />
      </material>
    </visual>
    <collision>
      <origin
        xyz="0 0 0"
        rpy="0 0 0" />
      <geometry>
        <mesh
          filename="../meshes/left_upper_arm_pitch_link.STL" />
      </geometry>
    </collision>
  </link>
  <joint
    name="left_shoulder_pitch_joint"
    type="revolute">
    <origin
      xyz="0 0.10111 0.047149"
      rpy="0.43633 0 0" />
    <parent
      link="torso_link" />
    <child
      link="left_upper_arm_pitch_link" />
    <axis
      xyz="0 1 0" />
    <limit
      lower="-2.79"
      upper="1.92"
      effort="38"
      velocity="9.11" />
  </joint>
  <link
    name="left_upper_arm_roll_link">
    <inertial>
      <origin
        xyz="0.002576 0.01466 -0.02316"
        rpy="0 0 0" />
      <mass
        value="0.5" />
      <inertia
        ixx="0.0008749"
        ixy="-1.593E-5"
        ixz="2.96E-6"
        iyy="0.0006958"
        iyz="0.0002863"
        izz="0.0004119" />
  </inertial>
    <visual>
      <origin
        xyz="0 0 0"
        rpy="0 0 0" />
      <geometry>
        <mesh
          filename="../meshes/left_upper_arm_roll_link.STL" />
      </geometry>
      <material
        name="">
        <color
          rgba="0.752941176470588 0.752941176470588 0.752941176470588 1" />
      </material>
    </visual>
    <collision>
      <origin
        xyz="0 0 0"
        rpy="0 0 0" />
      <geometry>
        <mesh
          filename="../meshes/left_upper_arm_roll_link.STL" />
      </geometry>
    </collision>
  </link>
  <joint
    name="left_shoulder_roll_joint"
    type="revolute">
    <origin
      xyz="0.00085 0.09515 0"
      rpy="-0.43633 0 0" />
    <parent
      link="left_upper_arm_pitch_link" />
    <child
      link="left_upper_arm_roll_link" />
    <axis
      xyz="1 0 0" />
    <limit
      lower="-0.57"
      upper="3.27"
      effort="38"
      velocity="9.11" />
  </joint>
  <link
    name="left_upper_arm_yaw_link">
    <inertial>
      <origin
        xyz="5.47E-5 0.002013 -0.0852"
        rpy="0 0 0" />
      <mass
        value="0.55" />
      <inertia
        ixx="0.003544"
        ixy="-1.8E-7"
        ixz="-1.75E-6"
        iyy="0.003537"
        iyz="9.928E-5"
        izz="0.0002512" />
    </inertial>
    <visual>
      <origin
        xyz="0 0 0"
        rpy="0 0 0" />
      <geometry>
        <mesh
          filename="../meshes/left_upper_arm_yaw_link.STL" />
      </geometry>
      <material
        name="">
        <color
          rgba="0.752941176470588 0.752941176470588 0.752941176470588 1" />
      </material>
    </visual>
    <collision>
      <origin
        xyz="0 0 0"
        rpy="0 0 0" />
      <geometry>
        <mesh
          filename="../meshes/left_upper_arm_yaw_link.STL" />
      </geometry>
    </collision>
  </link>
  <joint
    name="left_shoulder_yaw_joint"
    type="revolute">
    <origin
      xyz="-0.00085 0.04 -0.07645"
      rpy="0 0 0" />
    <parent
      link="left_upper_arm_roll_link" />
    <child
      link="left_upper_arm_yaw_link" />
    <axis
      xyz="0 0 1" />
    <limit
      lower="-2.97"
      upper="2.97"
      effort="30"
      velocity="7.33" />
  </joint>
  <link
    name="left_lower_arm_pitch_link">
    <inertial>
      <origin
        xyz="3.31E-6 0.003746 -0.02549"
        rpy="0 0 0" />
      <mass
        value="0.32" />
      <inertia
        ixx="0.0002916"
        ixy="1E-8"
        ixz="-6E-8"
        iyy="0.0002848"
        iyz="-4.858E-5"
        izz="0.0001090" />
    </inertial>
    <visual>
      <origin
        xyz="0 0 0"
        rpy="0 0 0" />
      <geometry>
        <mesh
          filename="../meshes/left_lower_arm_pitch_link.STL" />
      </geometry>
      <material
        name="">
        <color
          rgba="0.752941176470588 0.752941176470588 0.752941176470588 1" />
      </material>
    </visual>
    <collision>
      <origin
        xyz="0 0 0"
        rpy="0 0 0" />
      <geometry>
        <mesh
          filename="../meshes/left_lower_arm_pitch_link.STL" />
      </geometry>
    </collision>
  </link>
  <joint
    name="left_elbow_pitch_joint"
    type="revolute">
    <origin
      xyz="0 0.0096 -0.1751"
      rpy="0 0 0" />
    <parent
      link="left_upper_arm_yaw_link" />
    <child
      link="left_lower_arm_pitch_link" />
    <axis
      xyz="0 1 0" />
    <limit
      lower="-2.27"
      upper="2.27"
      effort="30"
      velocity="7.33" />
  </joint>
  <link
    name="left_hand_yaw_link">
    <inertial>
      <origin
        xyz="-2.923E-5 0.002124 -0.06117"
        rpy="0 0 0" />
      <mass
        value="0.73" />
      <inertia
        ixx="0.001866"
        ixy="3.1E-7"
        ixz="1.064E-5"
        iyy="0.001862"
        iyz="1.649E-5"
        izz="0.0003211" />
    </inertial>
    <visual>
      <origin
        xyz="0 0 0"
        rpy="0 0 0" />
      <geometry>
        <mesh
          filename="../meshes/left_hand_yaw_link.STL" />
      </geometry>
      <material
        name="">
        <color
          rgba="0.752941176470588 0.752941176470588 0.752941176470588 1" />
      </material>
    </visual>
    <collision>
      <origin
        xyz="0 0 0"
        rpy="0 0 0" />
      <geometry>
        <mesh
          filename="../meshes/left_hand_yaw_link.STL" />
      </geometry>
    </collision>
  </link>
  <joint
    name="left_wrist_yaw_joint"
    type="revolute">
    <origin
      xyz="0 -0.0040497 -0.05945"
      rpy="0 0 0" />
    <parent
      link="left_lower_arm_pitch_link" />
    <child
      link="left_hand_yaw_link" />
    <axis
      xyz="0 0 1" />
    <limit
      lower="-2.97"
      upper="2.97"
      effort="10.2"
      velocity="24.4" />
  </joint>
  <link
    name="left_hand_roll_link">
    <inertial>
      <origin
        xyz="0 0.001292 -0.01174"
        rpy="0 0 0" />
      <mass
        value="0.0295" />
      <inertia
        ixx="5.38E-6"
        ixy="0"
        ixz="0"
        iyy="1E-5"
        iyz="-4.6E-7"
        izz="8.92E-6" />
    </inertial>
    <visual>
      <origin
        xyz="0 0 0"
        rpy="0 0 0" />
      <geometry>
        <mesh
          filename="../meshes/left_hand_roll_link.STL" />
      </geometry>
      <material
        name="">
        <color
          rgba="0.752941176470588 0.752941176470588 0.752941176470588 1" />
      </material>
    </visual>
    <collision>
      <origin
        xyz="0 0 0"
        rpy="0 0 0" />
      <geometry>
        <mesh
          filename="../meshes/left_hand_roll_link.STL" />
      </geometry>
    </collision>
  </link>
  <joint
    name="left_wrist_roll_link"
    type="revolute">
    <origin
      xyz="0 0 -0.18765"
      rpy="0 0 0" />
    <parent
      link="left_hand_yaw_link" />
    <child
      link="left_hand_roll_link" />
    <axis
      xyz="1 0 0" />
    <limit
      lower="-0.61"
      upper="0.61"
      effort="3.95"
      velocity="27.96" />
  </joint>
  <link
    name="left_hand_pitch_link">
    <inertial>
      <origin
        xyz="0 0.001292 -0.01174"
        rpy="0 0 0" />
      <mass
        value="0.0295" />
      <inertia
        ixx="5.38E-6"
        ixy="0"
        ixz="0"
        iyy="1E-5"
        iyz="-4.6E-7"
        izz="8.92E-6" />
    </inertial>
    <visual>
      <origin
        xyz="0 0 0"
        rpy="0 0 0" />
      <geometry>
        <mesh
          filename="../meshes/left_hand_pitch_link.STL" />
      </geometry>
      <material
        name="">
        <color
          rgba="0.752941176470588 0.752941176470588 0.752941176470588 1" />
      </material>
    </visual>
    <collision>
      <origin
        xyz="0 0 0"
        rpy="0 0 0" />
      <geometry>
        <mesh
          filename="../meshes/left_hand_pitch_link.STL" />
      </geometry>
    </collision>
  </link>
  <joint
    name="left_wrist_pitch_joint"
    type="revolute">
    <origin
      xyz="0 0 0"
      rpy="0 0 0" />
    <parent
      link="left_hand_roll_link" />
    <child
      link="left_hand_pitch_link" />
    <axis
      xyz="0 1 0" />
    <limit
      lower="-0.96"
      upper="0.87"
      effort="3.95"
      velocity="27.96" />
  </joint>


  <link
    name="left_end_effector_link">
  </link>
  <joint
    name="left_end_effector_joint"
    type="fixed">
    <origin
      xyz="0 0 0"
      rpy="0 0 0" />
    <parent
      link="left_hand_pitch_link" />
    <child
      link="left_end_effector_link" />
  </joint>



    <link
    name="l_hand_base_link">
    <inertial>
      <origin
        xyz="-0.000341219118062869 -0.00502824269426091 -0.0449280446308069"
        rpy="0 0 0" />
      <mass
        value="0.099947" />
      <inertia
        ixx="0.00030651"
        ixy="-2.324E-05"
        ixz="-3.2E-07"
        iyy="0.0004015"
        iyz="3.1E-07"
        izz="0.00019218" />
    </inertial>
    <visual>
      <origin
        xyz="0 0 0"
        rpy="0 0 0" />
      <geometry>
        <mesh
          filename="../meshes/l_hand_base_link.STL" />
      </geometry>
      <material
        name="">
        <color
          rgba="0.866666666666667 0.866666666666667 0.890196078431372 1" />
      </material>
    </visual>
    <collision>
      <origin
        xyz="0 0 0"
        rpy="0 0 0" />
      <geometry>
        <mesh
          filename="../meshes/l_hand_base_link.STL" />
      </geometry>
    </collision>
  </link>
  <joint
    name="l_hand_base_joint"
    type="fixed">
    <origin
      xyz="-0.00143750472419189 -5.94019892983799E-05 -0.0210000216633744"
      rpy="0 0 0" />
    <parent
      link="left_end_effector_link" />
    <child
      link="l_hand_base_link" />
    <axis
      xyz="0 0 0" />
  </joint>
  <link
    name="L_thumb_proximal_base">
    <inertial>
      <origin
        xyz="0.0110171865188146 -2.47672281110389E-05 0.000776047913919345"
        rpy="0 0 0" />
      <mass
        value="0.0094853" />
      <inertia
        ixx="3.2E-07"
        ixy="1.3E-07"
        ixz="-4E-08"
        iyy="9.2E-07"
        iyz="0"
        izz="9.7E-07" />
    </inertial>
    <visual>
      <origin
        xyz="0 0 0"
        rpy="0 0 0" />
      <geometry>
        <mesh
          filename="../meshes/L_thumb_proximal_base.STL" />
      </geometry>
      <material
        name="">
        <color
          rgba="0.890196078431372 0.890196078431372 0.913725490196078 1" />
      </material>
    </visual>
    <collision>
      <origin
        xyz="0 0 0"
        rpy="0 0 0" />
      <geometry>
        <mesh
          filename="../meshes/L_thumb_proximal_base.STL" />
      </geometry>
    </collision>
  </link>
  <joint
    name="L_thumb_proximal_yaw_joint"
    type="revolute">
    <origin
      xyz="0.0220003063830263 -0.0154982849769962 -0.0250926444440346"
      rpy="0 -1.22105233317497E-05 0" />
    <parent
      link="l_hand_base_link" />
    <child
      link="L_thumb_proximal_base" />
    <axis
      xyz="0 0 1" />
    <limit
      lower="-1.74"
      upper="0"
      effort="10"
      velocity="0.8" />
  </joint>
  <link
    name="L_thumb_proximal">
    <inertial>
      <origin
        xyz="0.0312833670370602 0.000740495699468297 -2.32089545953995E-05"
        rpy="0 0 0" />
      <mass
        value="0.033247" />
      <inertia
        ixx="1.214E-05"
        ixy="4.25E-06"
        ixz="-1E-07"
        iyy="3.292E-05"
        iyz="3E-08"
        izz="3.183E-05" />
    </inertial>
    <visual>
      <origin
        xyz="0 0 0"
        rpy="0 0 0" />
      <geometry>
        <mesh
          filename="../meshes/L_thumb_proximal.STL" />
      </geometry>
      <material
        name="">
        <color
          rgba="0.866666666666667 0.866666666666667 0.890196078431372 1" />
      </material>
    </visual>
    <collision>
      <origin
        xyz="0 0 0"
        rpy="0 0 0" />
      <geometry>
        <mesh
          filename="../meshes/L_thumb_proximal.STL" />
      </geometry>
    </collision>
  </link>
  <joint
    name="L_thumb_proximal_pitch_joint"
    type="revolute">
    <origin
      xyz="0.02175 0 0"
      rpy="-1.57072797771317 0 0" />
    <parent
      link="L_thumb_proximal_base" />
    <child
      link="L_thumb_proximal" />
    <axis
      xyz="0 0 1" />
    <limit
      lower="0"
      upper="1.22"
      effort="10"
      velocity="0.8" />
  </joint>
  <link
    name="L_thumb_distal">
    <inertial>
      <origin
        xyz="0.0132168665788391 -0.00326175003895993 -5.06101471370313E-07"
        rpy="0 0 0" />
      <mass
        value="0.020321" />
      <inertia
        ixx="9.7E-07"
        ixy="2.7E-07"
        ixz="9E-08"
        iyy="2.29E-06"
        iyz="-2E-08"
        izz="2.48E-06" />
    </inertial>
    <visual>
      <origin
        xyz="0 0 0"
        rpy="0 0 0" />
      <geometry>
        <mesh
          filename="../meshes/L_thumb_distal.STL" />
      </geometry>
      <material
        name="">
        <color
          rgba="0.792156862745098 0.819607843137255 0.933333333333333 1" />
      </material>
    </visual>
    <collision>
      <origin
        xyz="0 0 0"
        rpy="0 0 0" />
      <geometry>
        <mesh
          filename="../meshes/L_thumb_distal.STL" />
      </geometry>
    </collision>
  </link>
  <joint
    name="L_thumb_distal_joint"
    type="revolute">
    <origin
      xyz="0.0615493701717829 0.00746157030770586 0"
      rpy="0 0 1.22106056547031E-05" />
    <parent
      link="L_thumb_proximal" />
    <child
      link="L_thumb_distal" />
    <axis
      xyz="0 0 1" />
    <limit
      lower="0"
      upper="1.04"
      effort="10"
      velocity="0.8" />
    <mimic
      joint="L_thumb_proximal_pitch_joint"
      multiplier="0.974"
      offset="0" />
  </joint>

  <link name="L_thumb_tip">
    <visual>
      <origin
        xyz="0 0 0"
        rpy="0 0 0" />
      <geometry>
        <sphere radius="0.005" />
      </geometry>
      <material name="yellow">
        <color rgba="0.9 1 0 1" />
      </material>
    </visual>
  </link>
  <joint name="L_thumb_tip_joint" type="fixed">
    <parent link="L_thumb_distal" />
    <child link="L_thumb_tip" />
    <origin rpy="0 0 0" xyz="0.031 0 0" />
  </joint>

  <link
    name="L_index_proximal">
    <inertial>
      <origin
        xyz="0.00960018118915809 0.00044353185078605 2.958628109756E-06"
        rpy="0 0 0" />
      <mass
        value="0.019118" />
      <inertia
        ixx="3.83E-06"
        ixy="3E-08"
        ixz="1.8E-07"
        iyy="3.72E-06"
        iyz="-8E-08"
        izz="8.7E-07" />
    </inertial>
    <visual>
      <origin
        xyz="0 0 0"
        rpy="0 0 0" />
      <geometry>
        <mesh
          filename="../meshes/L_index_proximal.STL" />
      </geometry>
      <material
        name="">
        <color
          rgba="0.866666666666667 0.866666666666667 0.890196078431372 1" />
      </material>
    </visual>
    <collision>
      <origin
        xyz="0 0 0"
        rpy="0 0 0" />
      <geometry>
        <mesh
          filename="../meshes/L_index_proximal.STL" />
      </geometry>
    </collision>
  </link>
  <joint
    name="L_index_proximal_joint"
    type="revolute">
    <origin
      xyz="0.026869067504082 -0.0122934392405636 -0.0959894118552304"
      rpy="0.00130566300740641 1.51842419415245 0.00130387280614764" />
    <parent
      link="l_hand_base_link" />
    <child
      link="L_index_proximal" />
    <axis
      xyz="0 0 1" />
    <limit
      lower="-1.57"
      upper="0"
      effort="10"
      velocity="0.8" />
  </joint>
  <link
    name="L_index_intermediate">
    <inertial>
      <origin
        xyz="0.0180093666798108 0.00300055705134525 -8.82089827167198E-06"
        rpy="0 0 0" />
      <mass
        value="0.012927" />
      <inertia
        ixx="2.03E-06"
        ixy="2E-08"
        ixz="1.4E-07"
        iyy="2.01E-06"
        iyz="-2.3E-07"
        izz="3.8E-07" />
    </inertial>
    <visual>
      <origin
        xyz="0 0 0"
        rpy="0 0 0" />
      <geometry>
        <mesh
          filename="../meshes/L_index_intermediate.STL" />
      </geometry>
      <material
        name="">
        <color
          rgba="0.792156862745098 0.819607843137255 0.933333333333333 1" />
      </material>
    </visual>
    <collision>
      <origin
        xyz="0 0 0"
        rpy="0 0 0" />
      <geometry>
        <mesh
          filename="../meshes/L_index_intermediate.STL" />
      </geometry>
    </collision>
  </link>
  <joint
    name="L_index_intermediate_joint"
    type="revolute">
    <origin
      xyz="0.0315316061985493 -0.00545507200132231 0"
      rpy="0 0 -6.82553680074393E-05" />
    <parent
      link="L_index_proximal" />
    <child
      link="L_index_intermediate" />
    <axis
      xyz="0 0 1" />
    <limit
      lower="-1.74"
      upper="0"
      effort="10"
      velocity="0.8" />
    <mimic
      joint="L_index_proximal_joint"
      multiplier="1.128"
      offset="0" />
  </joint>


  <link name="L_index_tip">
    <visual>
      <origin
        xyz="0 0 0"
        rpy="0 0 0" />
      <geometry>
        <sphere radius="0.005" />
      </geometry>
      <material name="yellow">
        <color rgba="0.9 1 0 1" />
      </material>
    </visual>
  </link>
  <joint name="L_index_tip_joint" type="fixed">
    <parent link="L_index_intermediate" />
    <child link="L_index_tip" />
    <origin rpy="0 0 0" xyz="0.038 -0.0038 0" />
  </joint>


  
  <link
    name="L_middle_proximal">
    <inertial>
      <origin
        xyz="0.00955705245388191 0.00071918425895251 3.00382438536695E-06"
        rpy="0 0 0" />
      <mass
        value="0.019118" />
      <inertia
        ixx="3.84E-06"
        ixy="3E-08"
        ixz="1E-08"
        iyy="3.73E-06"
        iyz="-6E-08"
        izz="8.6E-07" />
    </inertial>
    <visual>
      <origin
        xyz="0 0 0"
        rpy="0 0 0" />
      <geometry>
        <mesh
          filename="../meshes/L_middle_proximal.STL" />
      </geometry>
      <material
        name="">
        <color
          rgba="0.890196078431372 0.890196078431372 0.913725490196078 1" />
      </material>
    </visual>
    <collision>
      <origin
        xyz="0 0 0"
        rpy="0 0 0" />
      <geometry>
        <mesh
          filename="../meshes/L_middle_proximal.STL" />
      </geometry>
    </collision>
  </link>
  <joint
    name="L_middle_proximal_joint"
    type="revolute">
    <origin
      xyz="0.00850119653118567 -0.0122933023251572 -0.0979925903933238"
      rpy="1.39401189702948 1.57072689557984 1.3940118966122" />
    <parent
      link="l_hand_base_link" />
    <child
      link="L_middle_proximal" />
    <axis
      xyz="0 0 1" />
    <limit
      lower="-1.57"
      upper="0"
      effort="10"
      velocity="0.8" />
  </joint>
  <link
    name="L_middle_intermediate">
    <inertial>
      <origin
        xyz="0.0212893549719316 0.00408289770373668 -9.13198765574441E-06"
        rpy="0 0 0" />
      <mass
        value="0.015352" />
      <inertia
        ixx="3.29E-06"
        ixy="0"
        ixz="5E-08"
        iyy="3.28E-06"
        iyz="-2.2E-07"
        izz="4.1E-07" />
    </inertial>
    <visual>
      <origin
        xyz="0 0 0"
        rpy="0 0 0" />
      <geometry>
        <mesh
          filename="../meshes/L_middle_intermediate.STL" />
      </geometry>
      <material
        name="">
        <color
          rgba="0.792156862745098 0.819607843137255 0.933333333333333 1" />
      </material>
    </visual>
    <collision>
      <origin
        xyz="0 0 0"
        rpy="0 0 0" />
      <geometry>
        <mesh
          filename="../meshes/L_middle_intermediate.STL" />
      </geometry>
    </collision>
  </link>
  <joint
    name="L_middle_intermediate_joint"
    type="revolute">
    <origin
      xyz="0.0316616941629316 -0.00464081056852417 0"
      rpy="0 0 -6.83490817261459E-05" />
    <parent
      link="L_middle_proximal" />
    <child
      link="L_middle_intermediate" />
    <axis
      xyz="0 0 1" />
    <limit
      lower="-1.74"
      upper="0"
      effort="10"
      velocity="0.8" />
    <mimic
      joint="L_middle_proximal_joint"
      multiplier="1.131"
      offset="0" />
  </joint>


  <link name="L_middle_tip">
    <visual>
      <origin
        xyz="0 0 0"
        rpy="0 0 0" />
      <geometry>
        <sphere radius="0.005" />
      </geometry>
      <material name="yellow">
        <color rgba="0.9 1 0 1" />
      </material>
    </visual>
  </link>
  <joint name="L_middle_tip_joint" type="fixed">
    <parent link="L_middle_intermediate" />
    <child link="L_middle_tip" />
    <origin rpy="0 0 0" xyz="0.045 -0.0032 0" />
  </joint>


  <link
    name="L_ring_proximal">
    <inertial>
      <origin
        xyz="0.00960002708086655 0.000443602585259689 3.01251546439701E-06"
        rpy="0 0 0" />
      <mass
        value="0.019117" />
      <inertia
        ixx="3.84E-06"
        ixy="2E-08"
        ixz="-1.2E-07"
        iyy="3.72E-06"
        iyz="-1.5E-07"
        izz="8.7E-07" />
    </inertial>
    <visual>
      <origin
        xyz="0 0 0"
        rpy="0 0 0" />
      <geometry>
        <mesh
          filename="../meshes/L_ring_proximal.STL" />
      </geometry>
      <material
        name="">
        <color
          rgba="0.890196078431372 0.890196078431372 0.913725490196078 1" />
      </material>
    </visual>
    <collision>
      <origin
        xyz="0 0 0"
        rpy="0 0 0" />
      <geometry>
        <mesh
          filename="../meshes/L_ring_proximal.STL" />
      </geometry>
    </collision>
  </link>
  <joint
    name="L_ring_proximal_joint"
    type="revolute">
    <origin
      xyz="-0.0099599699075906 -0.012293306060256 -0.0979379429013024"
      rpy="3.14028638202668 1.51844861517835 3.14028817139281" />
    <parent
      link="l_hand_base_link" />
    <child
      link="L_ring_proximal" />
    <axis
      xyz="0 0 1" />
    <limit
      lower="-1.57"
      upper="0"
      effort="10"
      velocity="0.8" />
  </joint>
  <link
    name="L_ring_intermediate">
    <inertial>
      <origin
        xyz="0.0180097013870772 0.00300008137097776 -8.39742864479354E-06"
        rpy="0 0 0" />
      <mass
        value="0.012926" />
      <inertia
        ixx="2.04E-06"
        ixy="0"
        ixz="-3E-08"
        iyy="2E-06"
        iyz="-2.6E-07"
        izz="3.8E-07" />
    </inertial>
    <visual>
      <origin
        xyz="0 0 0"
        rpy="0 0 0" />
      <geometry>
        <mesh
          filename="../meshes/L_ring_intermediate.STL" />
      </geometry>
      <material
        name="">
        <color
          rgba="0.792156862745098 0.819607843137255 0.933333333333333 1" />
      </material>
    </visual>
    <collision>
      <origin
        xyz="0 0 0"
        rpy="0 0 0" />
      <geometry>
        <mesh
          filename="../meshes/L_ring_intermediate.STL" />
      </geometry>
    </collision>
  </link>
  <joint
    name="L_ring_intermediate_joint"
    type="revolute">
    <origin
      xyz="0.0315316061985493 -0.00545507200132236 0"
      rpy="0 0 -6.82554553643455E-05" />
    <parent
      link="L_ring_proximal" />
    <child
      link="L_ring_intermediate" />
    <axis
      xyz="0 0 1" />
    <limit
      lower="-1.74"
      upper="0"
      effort="10"
      velocity="0.8" />
    <mimic
      joint="L_ring_proximal_joint"
      multiplier="1.143"
      offset="0" />
  </joint>


  <link name="L_ring_tip">
    <visual>
      <origin
        xyz="0 0 0"
        rpy="0 0 0" />
      <geometry>
        <sphere radius="0.005" />
      </geometry>
      <material name="green">
        <color rgba="0.9 1 0 1" />
      </material>
    </visual>
  </link>
  <joint name="L_ring_tip_joint" type="fixed">
    <parent link="L_ring_intermediate" />
    <child link="L_ring_tip" />
    <origin rpy="0 0 0" xyz="0.038 -0.0038 0" />
  </joint>


  <link
    name="L_pinky_proximal">
    <inertial>
      <origin
        xyz="0.00964509278679124 9.44866526330912E-05 3.06424748800632E-06"
        rpy="0 0 0" />
      <mass
        value="0.019118" />
      <inertia
        ixx="3.82E-06"
        ixy="0"
        ixz="-2.6E-07"
        iyy="3.7E-06"
        iyz="-2.6E-07"
        izz="9.1E-07" />
    </inertial>
    <visual>
      <origin
        xyz="0 0 0"
        rpy="0 0 0" />
      <geometry>
        <mesh
          filename="../meshes/L_pinky_proximal.STL" />
      </geometry>
      <material
        name="">
        <color
          rgba="0.890196078431372 0.890196078431372 0.913725490196078 1" />
      </material>
    </visual>
    <collision>
      <origin
        xyz="0 0 0"
        rpy="0 0 0" />
      <geometry>
        <mesh
          filename="../meshes/L_pinky_proximal.STL" />
      </geometry>
    </collision>
  </link>
  <joint
    name="L_pinky_proximal_joint"
    type="revolute">
    <origin
      xyz="-0.0282266675554703 -0.012293437629494 -0.0960129830601813"
      rpy="3.14093869761107 1.46608875997235 3.14094227921624" />
    <parent
      link="l_hand_base_link" />
    <child
      link="L_pinky_proximal" />
    <axis
      xyz="0 0 1" />
    <limit
      lower="-1.57"
      upper="0"
      effort="10"
      velocity="0.8" />
  </joint>
  <link
    name="L_pinky_intermediate">
    <inertial>
      <origin
        xyz="0.0160981065679005 0.00118818281307698 -9.37496349673328E-06"
        rpy="0 0 0" />
      <mass
        value="0.0056868" />
      <inertia
        ixx="6.6E-07"
        ixy="0"
        ixz="-2E-08"
        iyy="6.2E-07"
        iyz="-1.4E-07"
        izz="1.8E-07" />
    </inertial>
    <visual>
      <origin
        xyz="0 0 0"
        rpy="0 0 0" />
      <geometry>
        <mesh
          filename="../meshes/L_pinky_intermediate.STL" />
      </geometry>
      <material
        name="">
        <color
          rgba="0.792156862745098 0.819607843137255 0.933333333333333 1" />
      </material>
    </visual>
    <collision>
      <origin
        xyz="0 0 0"
        rpy="0 0 0" />
      <geometry>
        <mesh
          filename="../meshes/L_pinky_intermediate.STL" />
      </geometry>
    </collision>
  </link>
  <joint
    name="L_pinky_intermediate_joint"
    type="revolute">
    <origin
      xyz="0.0313378020543266 -0.00647627689369765 0"
      rpy="0 0 -6.79747455421694E-05" />
    <parent
      link="L_pinky_proximal" />
    <child
      link="L_pinky_intermediate" />
    <axis
      xyz="0 0 1" />
    <limit
      lower="-1.74"
      upper="0"
      effort="10"
      velocity="0.8" />
    <mimic
      joint="L_pinky_proximal_joint"
      multiplier="1.129"
      offset="0" />
  </joint>


  <link name="L_pinky_tip">
    <visual>
      <origin
        xyz="0 0 0"
        rpy="0 0 0" />
      <geometry>
        <sphere radius="0.005" />
      </geometry>
      <material name="yellow">
        <color rgba="0.9 1 0 1" />
      </material>
    </visual>
  </link>
  <joint name="L_pinky_tip_joint" type="fixed">
    <parent link="L_pinky_intermediate" />
    <child link="L_pinky_tip" />
    <origin rpy="0 0 0" xyz="0.031 -0.007 0" />
  </joint>





  <link
    name="right_upper_arm_pitch_link">
    <inertial>
      <origin
        xyz="0.00324 -0.0533 0.000185"
        rpy="0 0 0" />
      <mass
        value="0.81" />
      <inertia
        ixx="0.00203"
        ixy="0.000104"
        ixz="2.96E-6"
        iyy="0.000499"
        iyz="-1.1E-6"
        izz="0.001960" />
    </inertial>
    <visual>
      <origin
        xyz="0 0 0"
        rpy="0 0 0" />
      <geometry>
        <mesh
          filename="../meshes/right_upper_arm_pitch_link.STL" />
      </geometry>
      <material
        name="">
        <color
          rgba="0.752941176470588 0.752941176470588 0.752941176470588 1" />
      </material>
    </visual>
    <collision>
      <origin
        xyz="0 0 0"
        rpy="0 0 0" />
      <geometry>
        <mesh
          filename="../meshes/right_upper_arm_pitch_link.STL" />
      </geometry>
    </collision>
  </link>
  <joint
    name="right_shoulder_pitch_joint"
    type="revolute">
    <origin
      xyz="0 -0.10111 0.047149"
      rpy="-0.43633 0 0" />
    <parent
      link="torso_link" />
    <child
      link="right_upper_arm_pitch_link" />
    <axis
      xyz="0 1 0" />
    <limit
      lower="-2.79"
      upper="1.92"
      effort="38"
      velocity="9.11" />
  </joint>
  <link
    name="right_upper_arm_roll_link">
    <inertial>
      <origin
        xyz="0.00258 -0.0147 -0.0232"
        rpy="0 0 0" />
      <mass
        value="0.5" />
      <inertia
        ixx="0.000875"
        ixy="1.6E-5"
        ixz="2.96E-6"
        iyy="0.000696"
        iyz="-0.0002866"
        izz="0.0004121" />
    </inertial>
    <visual>
      <origin
        xyz="0 0 0"
        rpy="0 0 0" />
      <geometry>
        <mesh
          filename="../meshes/right_upper_arm_roll_link.STL" />
      </geometry>
      <material
        name="">
        <color
          rgba="0.752941176470588 0.752941176470588 0.752941176470588 1" />
      </material>
    </visual>
    <collision>
      <origin
        xyz="0 0 0"
        rpy="0 0 0" />
      <geometry>
        <mesh
          filename="../meshes/right_upper_arm_roll_link.STL" />
      </geometry>
    </collision>
  </link>
  <joint
    name="right_shoulder_roll_joint"
    type="revolute">
    <origin
      xyz="0.00085 -0.09515 0"
      rpy="0.43633 0 0" />
    <parent
      link="right_upper_arm_pitch_link" />
    <child
      link="right_upper_arm_roll_link" />
    <axis
      xyz="1 0 0" />
    <limit
      lower="-3.27"
      upper="0.57"
      effort="38"
      velocity="9.11" />
  </joint>
  <link
    name="right_upper_arm_yaw_link">
    <inertial>
      <origin
        xyz="7.6E-5 -0.002032 -0.08519"
        rpy="0 0 0" />
      <mass
        value="0.55" />
      <inertia
        ixx="0.003543"
        ixy="-1.9E-7"
        ixz="-1.49E-6"
        iyy="0.003536"
        iyz="-9.89E-5"
        izz="0.0002512" />
    </inertial>
    <visual>
      <origin
        xyz="0 0 0"
        rpy="0 0 0" />
      <geometry>
        <mesh
          filename="../meshes/right_upper_arm_yaw_link.STL" />
      </geometry>
      <material
        name="">
        <color
          rgba="0.752941176470588 0.752941176470588 0.752941176470588 1" />
      </material>
    </visual>
    <collision>
      <origin
        xyz="0 0 0"
        rpy="0 0 0" />
      <geometry>
        <mesh
          filename="../meshes/right_upper_arm_yaw_link.STL" />
      </geometry>
    </collision>
  </link>
  <joint
    name="right_shoulder_yaw_joint"
    type="revolute">
    <origin
      xyz="-0.00085 -0.04 -0.07645"
      rpy="0 0 0" />
    <parent
      link="right_upper_arm_roll_link" />
    <child
      link="right_upper_arm_yaw_link" />
    <axis
      xyz="0 0 1" />
    <limit
      lower="-2.97"
      upper="2.97"
      effort="30"
      velocity="7.33" />
  </joint>
  <link
    name="right_lower_arm_pitch_link">
    <inertial>
      <origin
        xyz="-1.69E-6 -0.003754 -0.02549"
        rpy="0 0 0" />
      <mass
        value="0.32" />
      <inertia
        ixx="0.0002914"
        ixy="2E-8"
        ixz="1E-8"
        iyy="0.0002847"
        iyz="4.85E-5"
        izz="0.000109" />
    </inertial>
    <visual>
      <origin
        xyz="0 0 0"
        rpy="0 0 0" />
      <geometry>
        <mesh
          filename="../meshes/right_lower_arm_pitch_link.STL" />
      </geometry>
      <material
        name="">
        <color
          rgba="0.752941176470588 0.752941176470588 0.752941176470588 1" />
      </material>
    </visual>
    <collision>
      <origin
        xyz="0 0 0"
        rpy="0 0 0" />
      <geometry>
        <mesh
          filename="../meshes/right_lower_arm_pitch_link.STL" />
      </geometry>
    </collision>
  </link>
  <joint
    name="right_elbow_pitch_joint"
    type="revolute">
    <origin
      xyz="0 -0.0096 -0.1751"
      rpy="0 0 0" />
    <parent
      link="right_upper_arm_yaw_link" />
    <child
      link="right_lower_arm_pitch_link" />
    <axis
      xyz="0 1 0" />
    <limit
      lower="-2.27"
      upper="2.27"
      effort="30"
      velocity="7.33" />
  </joint>
  <link
    name="right_hand_yaw_link">
    <inertial>
      <origin
        xyz="3.90E-5 -0.0212 -0.06117"
        rpy="0 0 0" />
      <mass
        value="0.73" />
      <inertia
        ixx="0.001866"
        ixy="3E-7"
        ixz="-1.091E-5"
        iyy="0.001862"
        iyz="-1.679E-5"
        izz="0.0003211" />
    </inertial>
    <visual>
      <origin
        xyz="0 0 0"
        rpy="0 0 0" />
      <geometry>
        <mesh
          filename="../meshes/right_hand_yaw_link.STL" />
      </geometry>
      <material
        name="">
        <color
          rgba="0.752941176470588 0.752941176470588 0.752941176470588 1" />
      </material>
    </visual>
    <collision>
      <origin
        xyz="0 0 0"
        rpy="0 0 0" />
      <geometry>
        <mesh
          filename="../meshes/right_hand_yaw_link.STL" />
      </geometry>
    </collision>
  </link>
  <joint
    name="right_wrist_yaw_joint"
    type="revolute">
    <origin
      xyz="0 0.0040497 -0.05945"
      rpy="0 0 0" />
    <parent
      link="right_lower_arm_pitch_link" />
    <child
      link="right_hand_yaw_link" />
    <axis
      xyz="0 0 1" />
    <limit
      lower="-2.97"
      upper="2.97"
      effort="10.2"
      velocity="24.4" />
  </joint>
  <link
    name="right_hand_roll_link">
    <inertial>
      <origin
        xyz="0 -0.00129 -0.0117"
        rpy="0 0 0" />
      <mass
        value="0.0295" />
      <inertia
        ixx="5.38E-6"
        ixy="0"
        ixz="0"
        iyy="1E-5"
        iyz="4.6E-7"
        izz="8.92E-6" />
    </inertial>
    <visual>
      <origin
        xyz="0 0 0"
        rpy="0 0 0" />
      <geometry>
        <mesh
          filename="../meshes/right_hand_roll_link.STL" />
      </geometry>
      <material
        name="">
        <color
          rgba="0.752941176470588 0.752941176470588 0.752941176470588 1" />
      </material>
    </visual>
    <collision>
      <origin
        xyz="0 0 0"
        rpy="0 0 0" />
      <geometry>
        <mesh
          filename="../meshes/right_hand_roll_link.STL" />
      </geometry>
    </collision>
  </link>
  <joint
    name="right_wrist_roll_joint"
    type="revolute">
    <origin
      xyz="0 0 -0.18765"
      rpy="0 0 0" />
    <parent
      link="right_hand_yaw_link" />
    <child
      link="right_hand_roll_link" />
    <axis
      xyz="0 1 0" />
    <limit
      lower="-0.61"
      upper="0.61"
      effort="3.95"
      velocity="27.96" />
  </joint>
  <link
    name="right_hand_pitch_link">
    <inertial>
      <origin
        xyz="0 -0.00129 -0.0117"
        rpy="0 0 0" />
      <mass
        value="0.0295" />
      <inertia
        ixx="5.38E-6"
        ixy="0"
        ixz="0"
        iyy="1E-5"
        iyz="4.6E-7"
        izz="8.92E-6" />
    </inertial>
    <visual>
      <origin
        xyz="0 0 0"
        rpy="0 0 0" />
      <geometry>
        <mesh
          filename="../meshes/right_hand_pitch_link.STL" />
      </geometry>
      <material
        name="">
        <color
          rgba="0.752941176470588 0.752941176470588 0.752941176470588 1" />
      </material>
    </visual>
    <collision>
      <origin
        xyz="0 0 0"
        rpy="0 0 0" />
      <geometry>
        <mesh
          filename="../meshes/right_hand_pitch_link.STL" />
      </geometry>
    </collision>
  </link>
  <joint
    name="right_wrist_pitch_joint"
    type="revolute">
    <origin
      xyz="0 0 0"
      rpy="0 0 0" />
    <parent
      link="right_hand_roll_link" />
    <child
      link="right_hand_pitch_link" />
    <axis
      xyz="1 0 0" />
    <limit
      lower="-0.96"
      upper="0.87"
      effort="3.95"
      velocity="27.96" />
  </joint>

  <link
    name="right_end_effector_link">
  </link>
  <joint
    name="right_end_effector_joint"
    type="fixed">
    <origin
      xyz="0 0 0"
      rpy="0 0 0" />
    <parent
      link="right_hand_pitch_link" />
    <child
      link="right_end_effector_link" />
  </joint>


    <link
    name="r_hand_base_link">
    <inertial>
      <origin
        xyz="-0.000386127877570155 0.00503962174027214 -0.0449101271034299"
        rpy="0 0 0" />
      <mass
        value="0.09995" />
      <inertia
        ixx="0.00030106"
        ixy="6E-08"
        ixz="-3.7E-07"
        iyy="0.0004068"
        iyz="-3.2E-07"
        izz="0.00019218" />
    </inertial>
    <visual>
      <origin
        xyz="0 0 0"
        rpy="0 0 0" />
      <geometry>
        <mesh
          filename="../meshes/r_hand_base_link.STL" />
      </geometry>
      <material
        name="">
        <color
          rgba="0.866666666666667 0.866666666666667 0.890196078431372 1" />
      </material>
    </visual>
    <collision>
      <origin
        xyz="0 0 0"
        rpy="0 0 0" />
      <geometry>
        <mesh
          filename="../meshes/r_hand_base_link.STL" />
      </geometry>
    </collision>
  </link>
  <joint
    name="r_hand_base_joint"
    type="fixed">
    <origin
      xyz="-0.00141711624232485 0 -0.0210000172555634"
      rpy="0 0 0" />
    <parent
      link="right_end_effector_link" />
    <child
      link="r_hand_base_link" />
    <axis
      xyz="0 0 0" />
  </joint>
  <link
    name="R_thumb_proximal_base">
    <inertial>
      <origin
        xyz="0.0110212287050384 -3.32698098642614E-05 -0.000776780774953884"
        rpy="0 0 0" />
      <mass
        value="0.0094822" />
      <inertia
        ixx="3E-07"
        ixy="0"
        ixz="-4E-08"
        iyy="9.5E-07"
        iyz="0"
        izz="9.7E-07" />
    </inertial>
    <visual>
      <origin
        xyz="0 0 0"
        rpy="0 0 0" />
      <geometry>
        <mesh
          filename="../meshes/R_thumb_proximal_base.STL" />
      </geometry>
      <material
        name="">
        <color
          rgba="0.890196078431372 0.890196078431372 0.913725490196078 1" />
      </material>
    </visual>
    <collision>
      <origin
        xyz="0 0 0"
        rpy="0 0 0" />
      <geometry>
        <mesh
          filename="../meshes/R_thumb_proximal_base.STL" />
      </geometry>
    </collision>
  </link>
  <joint
    name="R_thumb_proximal_yaw_joint"
    type="revolute">
    <origin
      xyz="0.0219570995851234 0.0155628599102215 -0.0250905219673082"
      rpy="3.14159265358979 0 0" />
    <parent
      link="r_hand_base_link" />
    <child
      link="R_thumb_proximal_base" />
    <axis
      xyz="-1.22100045962969E-05 6.83500415353481E-05 0.999999997589594" />
    <limit
      lower="-1.74"
      upper="0"
      effort="10"
      velocity="0.8" />
  </joint>
  <link
    name="R_thumb_proximal">
    <inertial>
      <origin
        xyz="0.0317791766093077 0.00114667119068899 -2.28155954604681E-05"
        rpy="0 0 0" />
      <mass
        value="0.033824" />
      <inertia
        ixx="1.132E-05"
        ixy="3E-08"
        ixz="1.7E-07"
        iyy="3.419E-05"
        iyz="1E-08"
        izz="3.228E-05" />
    </inertial>
    <visual>
      <origin
        xyz="0 0 0"
        rpy="0 0 0" />
      <geometry>
        <mesh
          filename="../meshes/R_thumb_proximal.STL" />
      </geometry>
      <material
        name="">
        <color
          rgba="0.866666666666667 0.866666666666667 0.890196078431372 1" />
      </material>
    </visual>
    <collision>
      <origin
        xyz="0 0 0"
        rpy="0 0 0" />
      <geometry>
        <mesh
          filename="../meshes/R_thumb_proximal.STL" />
      </geometry>
    </collision>
  </link>
  <joint
    name="R_thumb_proximal_pitch_joint"
    type="revolute">
    <origin
      xyz="0.0217499931849152 -1.72158354079244E-05 0"
      rpy="1.57086466715046 1.22641020904056E-05 -0.000791532745143911" />
    <parent
      link="R_thumb_proximal_base" />
    <child
      link="R_thumb_proximal" />
    <axis
      xyz="0 0 1" />
    <limit
      lower="0"
      upper="1.22"
      effort="10"
      velocity="0.8" />
  </joint>
  <link
    name="R_thumb_distal">
    <inertial>
      <origin
        xyz="0.0137334892415782 -0.00277453154609453 -4.9718691799705E-07"
        rpy="0 0 0" />
      <mass
        value="0.019744" />
      <inertia
        ixx="9E-07"
        ixy="0"
        ixz="9E-08"
        iyy="2.19E-06"
        iyz="0"
        izz="2.33E-06" />
    </inertial>
    <visual>
      <origin
        xyz="0 0 0"
        rpy="0 0 0" />
      <geometry>
        <mesh
          filename="../meshes/R_thumb_distal.STL" />
      </geometry>
      <material
        name="">
        <color
          rgba="0.866666666666667 0.866666666666667 0.890196078431372 1" />
      </material>
    </visual>
    <collision>
      <origin
        xyz="0 0 0"
        rpy="0 0 0" />
      <geometry>
        <mesh
          filename="../meshes/R_thumb_distal.STL" />
      </geometry>
    </collision>
  </link>
  <joint
    name="R_thumb_distal_joint"
    type="revolute">
    <origin
      xyz="0.0614443264755605 0.00828219439307844 0"
      rpy="0 0 1.22100084212751E-05" />
    <parent
      link="R_thumb_proximal" />
    <child
      link="R_thumb_distal" />
    <axis
      xyz="0 0 1" />
    <limit
      lower="0"
      upper="1.04"
      effort="10"
      velocity="0.8" />
    <mimic
      joint="R_thumb_proximal_pitch_joint"
      multiplier="0.974"
      offset="0" />
  </joint>


  <link name="R_thumb_tip">
    <visual>
      <origin
        xyz="0 0 0"
        rpy="0 0 0" />
      <geometry>
        <sphere radius="0.005" />
      </geometry>
      <material name="yellow">
        <color rgba="0.9 1 0 1" />
      </material>
    </visual>
  </link>
  <joint name="R_thumb_tip_joint" type="fixed">
    <parent link="R_thumb_distal" />
    <child link="R_thumb_tip" />
    <origin rpy="0 0 0" xyz="0.031 0 0" />
  </joint>


  <link
    name="R_index_proximal">
    <inertial>
      <origin
        xyz="0.00960002721978334 0.000443602715936658 3.01276850581123E-06"
        rpy="0 0 0" />
      <mass
        value="0.019118" />
      <inertia
        ixx="3.84E-06"
        ixy="0"
        ixz="1.5E-07"
        iyy="3.71E-06"
        iyz="1.2E-07"
        izz="8.7E-07" />
    </inertial>
    <visual>
      <origin
        xyz="0 0 0"
        rpy="0 0 0" />
      <geometry>
        <mesh
          filename="../meshes/R_index_proximal.STL" />
      </geometry>
      <material
        name="">
        <color
          rgba="0.890196078431372 0.890196078431372 0.913725490196078 1" />
      </material>
    </visual>
    <collision>
      <origin
        xyz="0 0 0"
        rpy="0 0 0" />
      <geometry>
        <mesh
          filename="../meshes/R_index_proximal.STL" />
      </geometry>
    </collision>
  </link>
  <joint
    name="R_index_proximal_joint"
    type="revolute">
    <origin
      xyz="0.0268347443648602 0.01238126080166 -0.0959877257832576"
      rpy="-3.14028763091841 1.5184240046093 0.00408527869771669" />
    <parent
      link="r_hand_base_link" />
    <child
      link="R_index_proximal" />
    <axis
      xyz="0.0012744819545806 0.219189646097979 0.975681441219003" />
    <limit
      lower="-1.57"
      upper="0"
      effort="10"
      velocity="0.8" />
  </joint>
  <link
    name="R_index_intermediate">
    <inertial>
      <origin
        xyz="0.0180099074306208 0.00299885189981389 -8.39749152652114E-06"
        rpy="0 0 0" />
      <mass
        value="0.012927" />
      <inertia
        ixx="2.03E-06"
        ixy="-1E-08"
        ixz="9E-08"
        iyy="2.01E-06"
        iyz="2.5E-07"
        izz="3.8E-07" />
    </inertial>
    <visual>
      <origin
        xyz="0 0 0"
        rpy="0 0 0" />
      <geometry>
        <mesh
          filename="../meshes/R_index_intermediate.STL" />
      </geometry>
      <material
        name="">
        <color
          rgba="0.792156862745098 0.819607843137255 0.933333333333333 1" />
      </material>
    </visual>
    <collision>
      <origin
        xyz="0 0 0"
        rpy="0 0 0" />
      <geometry>
        <mesh
          filename="../meshes/R_index_intermediate.STL" />
      </geometry>
    </collision>
  </link>
  <joint
    name="R_index_intermediate_joint"
    type="revolute">
    <origin
      xyz="0.0315316061985493 -0.00545507200132231 0"
      rpy="0 0 0" />
    <parent
      link="R_index_proximal" />
    <child
      link="R_index_intermediate" />
    <axis
      xyz="0 0 1" />
    <limit
      lower="-1.74"
      upper="0"
      effort="10"
      velocity="0.8" />
    <mimic
      joint="R_index_proximal_joint"
      multiplier="1.128"
      offset="0" />
  </joint>


  <link name="R_index_tip">
    <visual>
      <origin
        xyz="0 0 0"
        rpy="0 0 0" />
      <geometry>
        <sphere radius="0.005" />
      </geometry>
      <material name="yellow">
        <color rgba="0.9 1 0 1" />
      </material>
    </visual>
  </link>
  <joint name="R_index_tip_joint" type="fixed">
    <parent link="R_index_intermediate" />
    <child link="R_index_tip" />
    <origin rpy="0 0 0" xyz="0.038 -0.0038 0" />
  </joint>


  <link
    name="R_middle_proximal">
    <inertial>
      <origin
        xyz="0.00955705255659736 0.000719184503009201 3.00388766753812E-06"
        rpy="0 0 0" />
      <mass
        value="0.019118" />
      <inertia
        ixx="3.85E-06"
        ixy="0"
        ixz="0"
        iyy="3.72E-06"
        iyz="6E-08"
        izz="8.6E-07" />
    </inertial>
    <visual>
      <origin
        xyz="0 0 0"
        rpy="0 0 0" />
      <geometry>
        <mesh
          filename="../meshes/R_middle_proximal.STL" />
      </geometry>
      <material
        name="">
        <color
          rgba="0.890196078431372 0.890196078431372 0.913725490196078 1" />
      </material>
    </visual>
    <collision>
      <origin
        xyz="0 0 0"
        rpy="0 0 0" />
      <geometry>
        <mesh
          filename="../meshes/R_middle_proximal.STL" />
      </geometry>
    </collision>
  </link>
  <joint
    name="R_middle_proximal_joint"
    type="revolute">
    <origin
      xyz="0.00846694447258024 0.0123302974668429 -0.0979909078036594"
      rpy="-1.75035301585144 1.57072689472437 1.39402168267738" />
    <parent
      link="r_hand_base_link" />
    <child
      link="R_middle_proximal" />
    <axis
      xyz="0 0 1" />
    <limit
      lower="-1.57"
      upper="0"
      effort="10"
      velocity="0.8" />
  </joint>
  <link
    name="R_middle_intermediate">
    <inertial>
      <origin
        xyz="0.0212896407543054 0.00408143996126112 -9.13148789218055E-06"
        rpy="0 0 0" />
      <mass
        value="0.015352" />
      <inertia
        ixx="3.29E-06"
        ixy="0"
        ixz="0"
        iyy="3.28E-06"
        iyz="2.2E-07"
        izz="4.1E-07" />
    </inertial>
    <visual>
      <origin
        xyz="0 0 0"
        rpy="0 0 0" />
      <geometry>
        <mesh
          filename="../meshes/R_middle_intermediate.STL" />
      </geometry>
      <material
        name="">
        <color
          rgba="0.866666666666667 0.866666666666667 0.890196078431372 1" />
      </material>
    </visual>
    <collision>
      <origin
        xyz="0 0 0"
        rpy="0 0 0" />
      <geometry>
        <mesh
          filename="../meshes/R_middle_intermediate.STL" />
      </geometry>
    </collision>
  </link>
  <joint
    name="R_middle_intermediate_joint"
    type="revolute">
    <origin
      xyz="0.0316616941629307 -0.00464081056853635 0"
      rpy="0 0 0" />
    <parent
      link="R_middle_proximal" />
    <child
      link="R_middle_intermediate" />
    <axis
      xyz="0 0 1" />
    <limit
      lower="-1.74"
      upper="0"
      effort="10"
      velocity="0.8" />
      <mimic
      joint="R_middle_proximal_joint"
      multiplier="1.131"
      offset="0" />
  </joint>


  <link name="R_middle_tip">
    <visual>
      <origin
        xyz="0 0 0"
        rpy="0 0 0" />
      <geometry>
        <sphere radius="0.005" />
      </geometry>
      <material name="yellow">
        <color rgba="0.9 1 0 1" />
      </material>
    </visual>
  </link>
  <joint name="R_middle_tip_joint" type="fixed">
    <parent link="R_middle_intermediate" />
    <child link="R_middle_tip" />
    <origin rpy="0 0 0" xyz="0.045 -0.0032 0" />
  </joint>


  <link
    name="R_ring_proximal">
    <inertial>
      <origin
        xyz="0.0096001470731025 0.00044427472300787 2.95897501418479E-06"
        rpy="0 0 0" />
      <mass
        value="0.019117" />
      <inertia
        ixx="3.84E-06"
        ixy="0"
        ixz="-1.6E-07"
        iyy="3.71E-06"
        iyz="1.2E-07"
        izz="8.7E-07" />
    </inertial>
    <visual>
      <origin
        xyz="0 0 0"
        rpy="0 0 0" />
      <geometry>
        <mesh
          filename="../meshes/R_ring_proximal.STL" />
      </geometry>
      <material
        name="">
        <color
          rgba="0.890196078431372 0.890196078431372 0.913725490196078 1" />
      </material>
    </visual>
    <collision>
      <origin
        xyz="0 0 0"
        rpy="0 0 0" />
      <geometry>
        <mesh
          filename="../meshes/R_ring_proximal.STL" />
      </geometry>
    </collision>
  </link>
  <joint
    name="R_ring_proximal_joint"
    type="revolute">
    <origin
      xyz="-0.00999415052356634 0.0122789339975533 -0.0979362638116289"
      rpy="-0.00278180898871791 1.51844864673705 3.14159265358979" />
    <parent
      link="r_hand_base_link" />
    <child
      link="R_ring_proximal" />
    <axis
      xyz="0 0 1" />
    <limit
      lower="-1.57"
      upper="0"
      effort="10"
      velocity="0.8" />
  </joint>
  <link
    name="R_ring_intermediate">
    <inertial>
      <origin
        xyz="0.0180093387957889 0.00300072092575132 -8.8209720389143E-06"
        rpy="0 0 0" />
      <mass
        value="0.012925" />
      <inertia
        ixx="2.03E-06"
        ixy="1E-08"
        ixz="-9E-08"
        iyy="2.01E-06"
        iyz="2.5E-07"
        izz="3.8E-07" />
    </inertial>
    <visual>
      <origin
        xyz="0 0 0"
        rpy="0 0 0" />
      <geometry>
        <mesh
          filename="../meshes/R_ring_intermediate.STL" />
      </geometry>
      <material
        name="">
        <color
          rgba="0.298039215686275 0.298039215686275 0.298039215686275 1" />
      </material>
    </visual>
    <collision>
      <origin
        xyz="0 0 0"
        rpy="0 0 0" />
      <geometry>
        <mesh
          filename="../meshes/R_ring_intermediate.STL" />
      </geometry>
    </collision>
  </link>
  <joint
    name="R_ring_intermediate_joint"
    type="revolute">
    <origin
      xyz="0.0315320280251494 -0.00545263318234326 0"
      rpy="0 0 0" />
    <parent
      link="R_ring_proximal" />
    <child
      link="R_ring_intermediate" />
    <axis
      xyz="0 0 1" />
    <limit
      lower="-1.74"
      upper="0"
      effort="10"
      velocity="0.8" />
    <mimic
      joint="R_ring_proximal_joint"
      multiplier="1.143"
      offset="0" />
  </joint>


  <link name="R_ring_tip">
    <visual>
      <origin
        xyz="0 0 0"
        rpy="0 0 0" />
      <geometry>
        <sphere radius="0.005" />
      </geometry>
      <material name="green">
        <color rgba="0.9 1 0 1" />
      </material>
    </visual>
  </link>
  <joint name="R_ring_tip_joint" type="fixed">
    <parent link="R_ring_intermediate" />
    <child link="R_ring_tip" />
    <origin rpy="0 0 0" xyz="0.038 -0.0038 0" />
  </joint>



  <link
    name="R_pinky_proximal">
    <inertial>
      <origin
        xyz="0.0096385794510781 0.000350820790422174 2.97431465753201E-06"
        rpy="0 0 0" />
      <mass
        value="0.019117" />
      <inertia
        ixx="3.82E-06"
        ixy="2E-08"
        ixz="-3.1E-07"
        iyy="3.7E-06"
        iyz="2E-07"
        izz="9.1E-07" />
    </inertial>
    <visual>
      <origin
        xyz="0 0 0"
        rpy="0 0 0" />
      <geometry>
        <mesh
          filename="../meshes/R_pinky_proximal.STL" />
      </geometry>
      <material
        name="">
        <color
          rgba="0.890196078431372 0.890196078431372 0.913725490196078 1" />
      </material>
    </visual>
    <collision>
      <origin
        xyz="0 0 0"
        rpy="0 0 0" />
      <geometry>
        <mesh
          filename="../meshes/R_pinky_proximal.STL" />
      </geometry>
    </collision>
  </link>
  <joint
    name="R_pinky_proximal_joint"
    type="revolute">
    <origin
      xyz="-0.0282607774805067 0.012227983776169 -0.0960113074336258"
      rpy="-0.248599525552003 1.46275517858851 2.89438415643823" />
    <parent
      link="r_hand_base_link" />
    <child
      link="R_pinky_proximal" />
    <axis
      xyz="0 0 1" />
    <limit
      lower="-1.57"
      upper="0"
      effort="10"
      velocity="0.8" />
  </joint>
  <link
    name="R_pinky_intermediate">
    <inertial>
      <origin
        xyz="0.0160982593015231 0.00119063979850093 -9.07695338753234E-06"
        rpy="0 0 0" />
      <mass
        value="0.0056869" />
      <inertia
        ixx="6.6E-07"
        ixy="1E-08"
        ixz="-5E-08"
        iyy="6.2E-07"
        iyz="1.3E-07"
        izz="1.8E-07" />
    </inertial>
    <visual>
      <origin
        xyz="0 0 0"
        rpy="0 0 0" />
      <geometry>
        <mesh
          filename="../meshes/R_pinky_intermediate.STL" />
      </geometry>
      <material
        name="">
        <color
          rgba="0.792156862745098 0.819607843137255 0.933333333333333 1" />
      </material>
    </visual>
    <collision>
      <origin
        xyz="0 0 0"
        rpy="0 0 0" />
      <geometry>
        <mesh
          filename="../meshes/R_pinky_intermediate.STL" />
      </geometry>
    </collision>
  </link>
  <joint
    name="R_pinky_intermediate_joint"
    type="revolute">
    <origin
      xyz="0.0314990327566104 -0.00564011838510353 0"
      rpy="0 0 0.0263892434774018" />
    <parent
      link="R_pinky_proximal" />
    <child
      link="R_pinky_intermediate" />
    <axis
      xyz="0 0 1" />
    <limit
      lower="-1.74"
      upper="0"
      effort="10"
      velocity="0.8" />
    <mimic
      joint="R_pinky_proximal_joint"
      multiplier="1.129"
      offset="0" />
  </joint>


  <link name="R_pinky_tip">
    <visual>
      <origin
        xyz="0 0 0"
        rpy="0 0 0" />
      <geometry>
        <sphere radius="0.005" />
      </geometry>
      <material name="yellow">
        <color rgba="0.9 1 0 1" />
      </material>
    </visual>
  </link>
  <joint name="R_pinky_tip_joint" type="fixed">
    <parent link="R_pinky_intermediate" />
    <child link="R_pinky_tip" />
    <origin rpy="0 0 0" xyz="0.031 -0.007 0" />
  </joint>



  <link
    name="head_yaw_link">
    <inertial>
      <origin
        xyz="-0.0001367 -0.0001340 0.05313"
        rpy="0 0 0" />
      <mass
        value="0.45" />
      <inertia
        ixx="0.0007357"
        ixy="-8.7E-7"
        ixz="1.075E-5"
        iyy="0.0007692"
        iyz="1.54E-6"
        izz="0.0001691" />
    </inertial>
    <visual>
      <origin
        xyz="0 0 0"
        rpy="0 0 0" />
      <geometry>
        <mesh
          filename="../meshes/head_yaw_link.STL" />
      </geometry>
      <material
        name="">
        <color
          rgba="0.752941176470588 0.752941176470588 0.752941176470588 1" />
      </material>
    </visual>
    <collision>
      <origin
        xyz="0 0 0"
        rpy="0 0 0" />
      <geometry>
        <mesh
          filename="../meshes/head_yaw_link.STL" />
      </geometry>
    </collision>
  </link>
  <joint
    name="head_yaw_joint"
    type="revolute">
    <origin
      xyz="0 0 0.17339"
      rpy="0 0 0" />
    <parent
      link="torso_link" />
    <child
      link="head_yaw_link" />
    <axis
      xyz="0 0 1" />
    <limit
      lower="-2.71"
      upper="2.71"
      effort="3.95"
      velocity="27.96" />
  </joint>
  <link
    name="head_roll_link">
    <inertial>
      <origin
        xyz="-3E-5 0.01418 -0.00267"
        rpy="0 0 0" />
      <mass
        value="0.0328" />
      <inertia
        ixx="2.576E-5"
        ixy="-2.08E-6"
        ixz="-1.76E-6"
        iyy="2.306E-5"
        iyz="-1.9E-6"
        izz="2.592E-5" />
    </inertial>
    <visual>
      <origin
        xyz="0 0 0"
        rpy="0 0 0" />
      <geometry>
        <mesh
          filename="../meshes/head_roll_link.STL" />
      </geometry>
      <material
        name="">
        <color
          rgba="0.752941176470588 0.752941176470588 0.752941176470588 1" />
      </material>
    </visual>
    <collision>
      <origin
        xyz="0 0 0"
        rpy="0 0 0" />
      <geometry>
        <mesh
          filename="../meshes/head_roll_link.STL" />
      </geometry>
    </collision>
  </link>
  <joint
    name="head_roll_joint"
    type="revolute">
    <origin
      xyz="0 -0.00105 0.14195"
      rpy="0 0 0" />
    <parent
      link="head_yaw_link" />
    <child
      link="head_roll_link" />
    <axis
      xyz="1 0 0" />
    <limit
      lower="-0.35"
      upper="0.35"
      effort="3.95"
      velocity="27.96" />
  </joint>
  <link
    name="head_pitch_link">
    <inertial>
      <origin
        xyz="0.02654 0.002225 -0.01063"
        rpy="0 0 0" />
      <mass
        value="0.45" />
      <inertia
        ixx="0.001107"
        ixy="1.689E-5"
        ixz="0.0002775"
        iyy="0.001414"
        iyz="-8.33E-6"
        izz="0.001518" />
    </inertial>
    <visual>
      <origin
        xyz="0 0 0"
        rpy="0 0 0" />
      <geometry>
        <mesh
          filename="../meshes/head_pitch_link.STL" />
      </geometry>
      <material
        name="">
        <color
          rgba="0.752941176470588 0.752941176470588 0.752941176470588 1" />
      </material>
    </visual>
    <collision>
      <origin
        xyz="0 0 0"
        rpy="0 0 0" />
      <geometry>
        <mesh
          filename="../meshes/head_pitch_link.STL" />
      </geometry>
    </collision>
  </link>
  <joint
    name="head_pitch_joint"
    type="revolute">
    <origin
      xyz="0 0 0"
      rpy="0 0 0" />
    <parent
      link="head_roll_link" />
    <child
      link="head_pitch_link" />
    <axis
      xyz="0 1 0" />
    <limit
      lower="-0.87"
      upper="0.87"
      effort="3.95"
      velocity="27.96" />
  </joint>
  <link
    name="IMU_link">
    <inertial>
      <origin
        xyz="-0.0003275 0 -0.005737"
        rpy="0 0 0" />
      <mass
        value="0.064" />
      <inertia
        ixx="1.427E-5"
        ixy="0"
        ixz="-2.3E-7"
        iyy="1.525E-5"
        iyz="0"
        izz="1.836E-5" />
    </inertial>
    <visual>
      <origin
        xyz="0 0 0"
        rpy="0 0 0" />
      <geometry>
        <mesh
          filename="../meshes/IMU_link.STL" />
      </geometry>
      <material
        name="">
        <color
          rgba="0.752941176470588 0.752941176470588 0.752941176470588 1" />
      </material>
    </visual>
    <collision>
      <origin
        xyz="0 0 0"
        rpy="0 0 0" />
      <geometry>
        <mesh
          filename="../meshes/IMU_link.STL" />
      </geometry>
    </collision>
  </link>
  <joint
    name="IMU_joint"
    type="fixed">
    <origin
      xyz="-0.064772 0 -0.0596"
      rpy="0 0 0" />
    <parent
      link="base_link" />
    <child
      link="IMU_link" />
    <axis
      xyz="0 0 0" />
  </joint>
</robot>