<?xml version="1.0" encoding="utf-8"?>
<!-- 09222025-alpha-1 -->
<robot name="fourier_left_hand_6dof">
  <link name="L_hand_base_link">
    <inertial>
      <origin xyz="-0.0010133 -0.001628 -0.049512" rpy="0 0 0" />
      <mass value="0.29928" />
      <inertia ixx="0.00020599" ixy="-1.22E-06" ixz="8.34E-06" iyy="0.00028701" iyz="7.34E-06" izz="0.0001476" />
    </inertial>
    <visual>
      <origin xyz="0 0 0" rpy="0 0 0" />
      <geometry>
        <mesh filename="../meshes/fourier_hand_6dof/L_hand_base_link.STL" />
      </geometry>
      <material name="">
        <color rgba="1 1 1 1" />
      </material>
    </visual>
    <collision>
      <origin xyz="0 0 0" rpy="0 0 0" />
      <geometry>
        <mesh filename="../meshes/fourier_hand_6dof/L_hand_base_link.STL" />
      </geometry>
    </collision>
  </link>
  <link name="L_thumb_proximal_yaw_link">
    <inertial>
      <origin xyz="0.011674 -0.00039205 0.00044569" rpy="0 0 0" />
      <mass value="0.0084328" />
      <inertia ixx="3E-07" ixy="1E-08" ixz="-5E-08" iyy="8.8E-07" iyz="0" izz="8.5E-07" />
    </inertial>
    <visual>
      <origin xyz="0 0 0" rpy="0 0 0" />
      <geometry>
        <mesh filename="../meshes/fourier_hand_6dof/L_thumb_proximal_yaw_link.STL" />
      </geometry>
      <material name="">
        <color rgba="1 1 1 1" />
      </material>
    </visual>
    <collision>
      <origin xyz="0 0 0" rpy="0 0 0" />
      <geometry>
        <mesh filename="../meshes/fourier_hand_6dof/L_thumb_proximal_yaw_link.STL" />
      </geometry>
    </collision>
  </link>
  <joint name="L_thumb_proximal_yaw_joint" type="revolute">
    <origin xyz="0.022 -0.0155 -0.022992" rpy="0 0 0" />
    <parent link="L_hand_base_link" />
    <child link="L_thumb_proximal_yaw_link" />
    <axis xyz="0 0 1" />
    <limit lower="-1.676" upper="0" effort="0" velocity="0" />
  </joint>
  <link name="L_thumb_proximal_pitch_link">
    <inertial>
      <origin xyz="0.034496 0.00048877 1.942E-05" rpy="0 0 0" />
      <mass value="0.060766" />
      <inertia ixx="5.08E-06" ixy="8.1E-07" ixz="2E-08" iyy="1.71E-05" iyz="0" izz="1.85E-05" />
    </inertial>
    <visual>
      <origin xyz="0 0 0" rpy="0 0 0" />
      <geometry>
        <mesh filename="../meshes/fourier_hand_6dof/L_thumb_proximal_pitch_link.STL" />
      </geometry>
      <material name="">
        <color rgba="1 1 1 1" />
      </material>
    </visual>
    <collision>
      <origin xyz="0 0 0" rpy="0 0 0" />
      <geometry>
        <mesh filename="../meshes/fourier_hand_6dof/L_thumb_proximal_pitch_link.STL" />
      </geometry>
    </collision>
  </link>
  <joint name="L_thumb_proximal_pitch_joint" type="revolute">
    <origin xyz="0.021749 -0.00016321 0" rpy="-1.5708 0 -0.0052052" />
    <parent link="L_thumb_proximal_yaw_link" />
    <child link="L_thumb_proximal_pitch_link" />
    <axis xyz="0 0 1" />
    <limit lower="0" upper="1.159" effort="0" velocity="0" />
  </joint>
  <link name="L_thumb_distal_link">
    <inertial>
      <origin xyz="0.012862 -0.0029035 0" rpy="0 0 0" />
      <mass value="0.018024" />
      <inertia ixx="8.6E-07" ixy="-1.4E-07" ixz="0" iyy="2E-06" iyz="0" izz="1.87E-06" />
    </inertial>
    <visual>
      <origin xyz="0 0 0" rpy="0 0 0" />
      <geometry>
        <mesh filename="../meshes/fourier_hand_6dof/L_thumb_distal_link.STL" />
      </geometry>
      <material name="">
        <color rgba="1 1 1 1" />
      </material>
    </visual>
    <collision>
      <origin xyz="0 0 0" rpy="0 0 0" />
      <geometry>
        <mesh filename="../meshes/fourier_hand_6dof/L_thumb_distal_link.STL" />
      </geometry>
    </collision>
  </link>
  <joint name="L_thumb_distal_joint" type="revolute">
    <origin xyz="0.061549 0.007464 0" rpy="0 1.7448E-05 -0.055652" />
    <parent link="L_thumb_proximal_pitch_link" />
    <child link="L_thumb_distal_link" />
    <axis xyz="0 0 1" />
    <limit lower="0" upper="1.267" effort="0" velocity="0" />
    <mimic joint="L_thumb_proximal_pitch_joint" multiplier="1.06" offset="0" />
  </joint>
  <link name="L_thumb_tip_link">
    <visual>
      <origin xyz="0 0 0" rpy="0 0 0" />
      <geometry>
        <sphere radius="0.005" />
      </geometry>
      <material name="yellow">
        <color rgba="0.9 1 0 1" />
      </material>
    </visual>
  </link>
  <joint name="L_thumb_tip_joint" type="fixed">
    <parent link="L_thumb_distal_link" />
    <child link="L_thumb_tip_link" />
    <origin rpy="0 0 0" xyz="0.0305 -0.001 0" />
  </joint>
  <link name="L_index_proximal_link">
    <inertial>
      <origin xyz="0.013885 0.0013346 9.91E-06" rpy="0 0 0" />
      <mass value="0.011244" />
      <inertia ixx="7E-07" ixy="2.1E-07" ixz="0" iyy="1.81E-06" iyz="0" izz="1.87E-06" />
    </inertial>
    <visual>
      <origin xyz="0 0 0" rpy="0 0 0" />
      <geometry>
        <mesh filename="../meshes/fourier_hand_6dof/L_index_proximal_link.STL" />
      </geometry>
      <material name="">
        <color rgba="1 1 1 1" />
      </material>
    </visual>
    <collision>
      <origin xyz="0 0 0" rpy="0 0 0" />
      <geometry>
        <mesh filename="../meshes/fourier_hand_6dof/L_index_proximal_link.STL" />
      </geometry>
    </collision>
  </link>
  <joint name="L_index_proximal_joint" type="revolute">
    <origin xyz="0.026868 -0.0123 -0.093989" rpy="0 1.5184 0" />
    <parent link="L_hand_base_link" />
    <child link="L_index_proximal_link" />
    <axis xyz="0 0 1" />
    <limit lower="-1.602" upper="0" effort="0" velocity="0" />
  </joint>
  <link name="L_index_intermediate_link">
    <inertial>
      <origin xyz="0.014739 0.0047926 6.8E-06" rpy="0 0 0" />
      <mass value="0.0027085" />
      <inertia ixx="8E-08" ixy="3E-08" ixz="0" iyy="4.9E-07" iyz="0" izz="4.9E-07" />
    </inertial>
    <visual>
      <origin xyz="0 0 0" rpy="0 0 0" />
      <geometry>
        <mesh filename="../meshes/fourier_hand_6dof/L_index_intermediate_link.STL" />
      </geometry>
      <material name="">
        <color rgba="1 1 1 1" />
      </material>
    </visual>
    <collision>
      <origin xyz="0 0 0" rpy="0 0 0" />
      <geometry>
        <mesh filename="../meshes/fourier_hand_6dof/L_index_intermediate_link.STL" />
      </geometry>
    </collision>
  </link>
  <joint name="L_index_intermediate_joint" type="revolute">
    <origin xyz="0.031533 -0.0054444 0" rpy="0 0.00014037 -0.0018338" />
    <parent link="L_index_proximal_link" />
    <child link="L_index_intermediate_link" />
    <axis xyz="0 0 1" />
    <limit lower="-1.791" upper="0" effort="0" velocity="0" />
    <mimic joint="L_index_proximal_joint" multiplier="0.975" offset="0" />
  </joint>
  <link name="L_index_tip_link">
    <visual>
      <origin xyz="0 0 0" rpy="0 0 0" />
      <geometry>
        <sphere radius="0.005" />
      </geometry>
      <material name="yellow">
        <color rgba="0.9 1 0 1" />
      </material>
    </visual>
  </link>
  <joint name="L_index_tip_joint" type="fixed">
    <parent link="L_index_intermediate_link" />
    <child link="L_index_tip_link" />
    <origin rpy="0 0 0" xyz="0.0390 -0.0020 0" />
  </joint>
  <link name="L_middle_proximal_link">
    <inertial>
      <origin xyz="0.013888 0.001304 9.91E-06" rpy="0 0 0" />
      <mass value="0.011244" />
      <inertia ixx="7E-07" ixy="2.2E-07" ixz="0" iyy="1.81E-06" iyz="0" izz="1.87E-06" />
    </inertial>
    <visual>
      <origin xyz="0 0 0" rpy="0 0 0" />
      <geometry>
        <mesh filename="../meshes/fourier_hand_6dof/L_middle_proximal_link.STL" />
      </geometry>
      <material name="">
        <color rgba="1 1 1 1" />
      </material>
    </visual>
    <collision>
      <origin xyz="0 0 0" rpy="0 0 0" />
      <geometry>
        <mesh filename="../meshes/fourier_hand_6dof/L_middle_proximal_link.STL" />
      </geometry>
    </collision>
  </link>
  <joint name="L_middle_proximal_joint" type="revolute">
    <origin xyz="0.0085 -0.0123 -0.095992" rpy="0 1.5708 0" />
    <parent link="L_hand_base_link" />
    <child link="L_middle_proximal_link" />
    <axis xyz="0 0 1" />
    <limit lower="-1.603" upper="0" effort="0" velocity="0" />
  </joint>
  <link name="L_middle_intermediate_link">
    <inertial>
      <origin xyz="0.01836 0.0048894 0" rpy="0 0 0" />
      <mass value="0.0032739" />
      <inertia ixx="9E-08" ixy="5E-08" ixz="0" iyy="7.9E-07" iyz="0" izz="7.8E-07" />
    </inertial>
    <visual>
      <origin xyz="0 0 0" rpy="0 0 0" />
      <geometry>
        <mesh filename="../meshes/fourier_hand_6dof/L_middle_intermediate_link.STL" />
      </geometry>
      <material name="">
        <color rgba="1 1 1 1" />
      </material>
    </visual>
    <collision>
      <origin xyz="0 0 0" rpy="0 0 0" />
      <geometry>
        <mesh filename="../meshes/fourier_hand_6dof/L_middle_intermediate_link.STL" />
      </geometry>
    </collision>
  </link>
  <joint name="L_middle_intermediate_joint" type="revolute">
    <origin xyz="0.031521 -0.0055139 0" rpy="0 0.00015517 0.0048744" />
    <parent link="L_middle_proximal_link" />
    <child link="L_middle_intermediate_link" />
    <axis xyz="0 0 1" />
    <limit lower="-1.791" upper="0" effort="0" velocity="0" />
    <mimic joint="L_middle_proximal_joint" multiplier="0.975" offset="0" />
  </joint>
  <link name="L_middle_tip_link">
    <visual>
      <origin xyz="0 0 0" rpy="0 0 0" />
      <geometry>
        <sphere radius="0.005" />
      </geometry>
      <material name="yellow">
        <color rgba="0.9 1 0 1" />
      </material>
    </visual>
  </link>
  <joint name="L_middle_tip_joint" type="fixed">
    <parent link="L_middle_intermediate_link" />
    <child link="L_middle_tip_link" />
    <origin rpy="0 0 0" xyz="0.047 -0.0025 0" />
  </joint>
  <link name="L_ring_proximal_link">
    <inertial>
      <origin xyz="0.013886 0.0013292 0.00025991" rpy="0 0 0" />
      <mass value="0.011244" />
      <inertia ixx="7E-07" ixy="2.1E-07" ixz="0" iyy="1.81E-06" iyz="0" izz="1.87E-06" />
    </inertial>
    <visual>
      <origin xyz="0 0 0" rpy="0 0 0" />
      <geometry>
        <mesh filename="../meshes/fourier_hand_6dof/L_ring_proximal_link.STL" />
      </geometry>
      <material name="">
        <color rgba="1 1 1 1" />
      </material>
    </visual>
    <collision>
      <origin xyz="0 0 0" rpy="0 0 0" />
      <geometry>
        <mesh filename="../meshes/fourier_hand_6dof/L_ring_proximal_link.STL" />
      </geometry>
    </collision>
  </link>
  <joint name="L_ring_proximal_joint" type="revolute">
    <origin xyz="-0.010211 -0.0123 -0.095924" rpy="3.1416 1.5184 3.1416" />
    <parent link="L_hand_base_link" />
    <child link="L_ring_proximal_link" />
    <axis xyz="0 0 1" />
    <limit lower="-1.602" upper="0" effort="0" velocity="0" />
  </joint>
  <link name="L_ring_intermediate_link">
    <inertial>
      <origin xyz="0.014739 0.0047926 6.8E-06" rpy="0 0 0" />
      <mass value="0.0027085" />
      <inertia ixx="8E-08" ixy="3E-08" ixz="0" iyy="4.9E-07" iyz="0" izz="4.9E-07" />
    </inertial>
    <visual>
      <origin xyz="0 0 0" rpy="0 0 0" />
      <geometry>
        <mesh filename="../meshes/fourier_hand_6dof/L_ring_intermediate_link.STL" />
      </geometry>
      <material name="">
        <color rgba="1 1 1 1" />
      </material>
    </visual>
    <collision>
      <origin xyz="0 0 0" rpy="0 0 0" />
      <geometry>
        <mesh filename="../meshes/fourier_hand_6dof/L_ring_intermediate_link.STL" />
      </geometry>
    </collision>
  </link>
  <joint name="L_ring_intermediate_joint" type="revolute">
    <origin xyz="0.031531 -0.0054567 0.00025" rpy="0 0.00014037 -0.0025338" />
    <parent link="L_ring_proximal_link" />
    <child link="L_ring_intermediate_link" />
    <axis xyz="0 0 1" />
    <limit lower="-1.798" upper="0" effort="0" velocity="0" />
    <mimic joint="L_ring_proximal_joint" multiplier="0.975" offset="0" />
  </joint>
  <link name="L_ring_tip_link">
    <visual>
      <origin xyz="0 0 0" rpy="0 0 0" />
      <geometry>
        <sphere radius="0.005" />
      </geometry>
      <material name="green">
        <color rgba="0.9 1 0 1" />
      </material>
    </visual>
  </link>
  <joint name="L_ring_tip_joint" type="fixed">
    <parent link="L_ring_intermediate_link" />
    <child link="L_ring_tip_link" />
    <origin rpy="0 0 0" xyz="0.0385 -0.0015 0" />
  </joint>
  <link name="L_pinky_proximal_link">
    <inertial>
      <origin xyz="0.013886 0.0013317 9.91E-06" rpy="0 0 0" />
      <mass value="0.011244" />
      <inertia ixx="7E-07" ixy="2.1E-07" ixz="0" iyy="1.81E-06" iyz="0" izz="1.87E-06" />
    </inertial>
    <visual>
      <origin xyz="0 0 0" rpy="0 0 0" />
      <geometry>
        <mesh filename="../meshes/fourier_hand_6dof/L_pinky_proximal_link.STL" />
      </geometry>
      <material name="">
        <color rgba="1 1 1 1" />
      </material>
    </visual>
    <collision>
      <origin xyz="0 0 0" rpy="0 0 0" />
      <geometry>
        <mesh filename="../meshes/fourier_hand_6dof/L_pinky_proximal_link.STL" />
      </geometry>
    </collision>
  </link>
  <joint name="L_pinky_proximal_joint" type="revolute">
    <origin xyz="-0.028228 -0.0123 -0.094012" rpy="3.1416 1.4661 3.1416" />
    <parent link="L_hand_base_link" />
    <child link="L_pinky_proximal_link" />
    <axis xyz="0 0 1" />
    <limit lower="-1.602" upper="0" effort="0" velocity="0" />
  </joint>
  <link name="L_pinky_intermediate_link">
    <inertial>
      <origin xyz="0.012117 0.0047104 1.872E-05" rpy="0 0 0" />
      <mass value="0.0024076" />
      <inertia ixx="7E-08" ixy="1E-08" ixz="0" iyy="3.2E-07" iyz="0" izz="3.2E-07" />
    </inertial>
    <visual>
      <origin xyz="0 0 0" rpy="0 0 0" />
      <geometry>
        <mesh filename="../meshes/fourier_hand_6dof/L_pinky_intermediate_link.STL" />
      </geometry>
      <material name="">
        <color rgba="1 1 1 1" />
      </material>
    </visual>
    <collision>
      <origin xyz="0 0 0" rpy="0 0 0" />
      <geometry>
        <mesh filename="../meshes/fourier_hand_6dof/L_pinky_intermediate_link.STL" />
      </geometry>
    </collision>
  </link>
  <joint name="L_pinky_intermediate_joint" type="revolute">
    <origin xyz="0.031532 -0.005451 0" rpy="0 0.00032164 -0.011403" />
    <parent link="L_pinky_proximal_link" />
    <child link="L_pinky_intermediate_link" />
    <axis xyz="0 0 1" />
    <limit lower="-1.796" upper="0" effort="0" velocity="0" />
    <mimic joint="L_pinky_proximal_joint" multiplier="0.975" offset="0" />
  </joint>
  <link name="L_pinky_tip_link">
    <visual>
      <origin xyz="0 0 0" rpy="0 0 0" />
      <geometry>
        <sphere radius="0.005" />
      </geometry>
      <material name="yellow">
        <color rgba="0.9 1 0 1" />
      </material>
    </visual>
  </link>
  <joint name="L_pinky_tip_joint" type="fixed">
    <parent link="L_pinky_intermediate_link" />
    <child link="L_pinky_tip_link" />
    <origin rpy="0 0 0" xyz="0.033 -0.0015 0" />
  </joint>
</robot>
